Workbook
Name _1_ILS2_OBJ_FUNCTION_new50jobs: Planilha1!$A$1:$Y$60
Name _10_ILS2_OBJ_FUNCTION_new50jobs: Planilha10!$A$1:$Y$60
Name _2_ILS2_OBJ_FUNCTION_new50jobs: Planilha2!$A$1:$Y$60
Name _3_ILS2_OBJ_FUNCTION_new50jobs: Planilha3!$A$1:$Y$60
Name _4_ILS2_OBJ_FUNCTION_new50jobs: Planilha4!$A$1:$Y$60
Name _5_ILS2_OBJ_FUNCTION_new50jobs: Planilha5!$A$1:$Y$60
Name _6_ILS2_OBJ_FUNCTION_new50jobs: Planilha6!$A$1:$Y$60
Name _7_ILS2_OBJ_FUNCTION_new50jobs: Planilha7!$A$1:$Y$60
Name _8_ILS2_OBJ_FUNCTION_new50jobs_1: Planilha8!$A$1:$Y$60
Name _9_ILS2_OBJ_FUNCTION_new50jobs: Planilha9!$A$1:$Y$60
Name out: Planilha12!$B$1:$Y$1

Sheet Planilha1
A1: 1 | B1: 293568 | C1: 323247 | D1: 321079 | E1: 316529 | F1: 285888 | G1: 321676 | H1: 318961 | I1: 312439 | J1: 295910 | K1: 310202 | L1: 308298 | M1: 322673 | N1: 291323 | O1: 306718 | P1: 313716 | Q1: 310764 | R1: 288736 | S1: 309629 | T1: 320504 | U1: 315820 | V1: 288270 | W1: 307525 | X1: 303110 | Y1: 308835
A2: 2 | B2: 310006 | C2: 317424 | D2: 325962 | E2: 317110 | F2: 301500 | G2: 321066 | H2: 313594 | I2: 325253 | J2: 292800 | K2: 304544 | L2: 321329 | M2: 322829 | N2: 287163 | O2: 314611 | P2: 310866 | Q2: 309542 | R2: 293361 | S2: 318543 | T2: 305848 | U2: 326089 | V2: 293802 | W2: 315556 | X2: 315132 | Y2: 319562
A3: 3 | B3: 302933 | C3: 349802 | D3: 355450 | E3: 359391 | F3: 315749 | G3: 341150 | H3: 340044 | I3: 349473 | J3: 328197 | K3: 339003 | L3: 343770 | M3: 348116 | N3: 314908 | O3: 335461 | P3: 345618 | Q3: 341115 | R3: 314983 | S3: 340197 | T3: 331820 | U3: 345145 | V3: 307043 | W3: 330583 | X3: 348777 | Y3: 353538
A4: 4 | B4: 325559 | C4: 349062 | D4: 342403 | E4: 350328 | F4: 331373 | G4: 353007 | H4: 355276 | I4: 347512 | J4: 320910 | K4: 341692 | L4: 351158 | M4: 356523 | N4: 326282 | O4: 341491 | P4: 341377 | Q4: 344523 | R4: 306589 | S4: 348525 | T4: 344276 | U4: 345885 | V4: 318125 | W4: 340493 | X4: 349722 | Y4: 343762
A5: 5 | B5: 292597 | C5: 323515 | D5: 311404 | E5: 323836 | F5: 294818 | G5: 309294 | H5: 313312 | I5: 313911 | J5: 289992 | K5: 308242 | L5: 320204 | M5: 311157 | N5: 290192 | O5: 310230 | P5: 305547 | Q5: 321688 | R5: 279704 | S5: 313367 | T5: 311052 | U5: 314560 | V5: 288936 | W5: 314154 | X5: 293184 | Y5: 317964
A6: 6 | B6: 357042 | C6: 368804 | D6: 369113 | E6: 361017 | F6: 347962 | G6: 356820 | H6: 367845 | I6: 373979 | J6: 345021 | K6: 377211 | L6: 367858 | M6: 371827 | N6: 339545 | O6: 359200 | P6: 370686 | Q6: 371042 | R6: 341554 | S6: 359435 | T6: 369270 | U6: 369034 | V6: 342293 | W6: 357506 | X6: 366760 | Y6: 367879
A7: 7 | B7: 356221 | C7: 379529 | D7: 381032 | E7: 377139 | F7: 352090 | G7: 366428 | H7: 383511 | I7: 369278 | J7: 351284 | K7: 377022 | L7: 385396 | M7: 375324 | N7: 346710 | O7: 369584 | P7: 371628 | Q7: 374719 | R7: 359845 | S7: 374871 | T7: 369283 | U7: 381969 | V7: 349423 | W7: 363641 | X7: 373902 | Y7: 373325
A8: 8 | B8: 305268 | C8: 312577 | D8: 324546 | E8: 323468 | F8: 288614 | G8: 305862 | H8: 319494 | I8: 315449 | J8: 297333 | K8: 310640 | L8: 319274 | M8: 318236 | N8: 283446 | O8: 315255 | P8: 317006 | Q8: 308888 | R8: 301300 | S8: 315982 | T8: 316579 | U8: 326804 | V8: 291476 | W8: 312905 | X8: 311616 | Y8: 304217
A9: 9 | B9: 338664 | C9: 333433 | D9: 356271 | E9: 371403 | F9: 329571 | G9: 353100 | H9: 360867 | I9: 363071 | J9: 329767 | K9: 357601 | L9: 360693 | M9: 356890 | N9: 323862 | O9: 345872 | P9: 358083 | Q9: 358595 | R9: 335493 | S9: 357894 | T9: 353060 | U9: 365034 | V9: 319825 | W9: 344291 | X9: 337097 | Y9: 352570
A10: 10 | B10: 336089 | C10: 355301 | D10: 346546 | E10: 359059 | F10: 329847 | G10: 348004 | H10: 344257 | I10: 350110 | J10: 323396 | K10: 344766 | L10: 354384 | M10: 350130 | N10: 333105 | O10: 340361 | P10: 346350 | Q10: 347902 | R10: 330142 | S10: 339917 | T10: 352965 | U10: 345378 | V10: 324356 | W10: 340489 | X10: 351498 | Y10: 344698
A11: 11 | B11: 363497 | C11: 401610 | D11: 404359 | E11: 399730 | F11: 363109 | G11: 391568 | H11: 401959 | I11: 394929 | J11: 365900 | K11: 395864 | L11: 389645 | M11: 383497 | N11: 366979 | O11: 388577 | P11: 392787 | Q11: 401724 | R11: 369130 | S11: 395353 | T11: 396241 | U11: 394332 | V11: 354837 | W11: 379020 | X11: 396501 | Y11: 389799
A12: 12 | B12: 332272 | C12: 352758 | D12: 357828 | E12: 357502 | F12: 335824 | G12: 347005 | H12: 353387 | I12: 351785 | J12: 339312 | K12: 352509 | L12: 365326 | M12: 352637 | N12: 322755 | O12: 342140 | P12: 351858 | Q12: 349651 | R12: 334458 | S12: 354019 | T12: 354494 | U12: 353070 | V12: 323158 | W12: 348035 | X12: 357594 | Y12: 353006
... A60: 60 | B60: 285929 | C60: 297521 | D60: 299044 | E60: 293201 | F60: 284472 | G60: 288713 | H60: 293201 | I60: 295048 | J60: 279424 | K60: 288426 | L60: 292254 | M60: 293201 | N60: 284268 | O60: 288915 | P60: 285742 | Q60: 289672 | R60: 278091 | S60: 290345 | T60: 290432 | U60: 289714 | V60: 267354 | W60: 284586 | X60: 293309 | Y60: 281763

Sheet Planilha2
A1: 1 | B1: 290501 | C1: 307497 | D1: 314473 | E1: 325358 | F1: 295302 | G1: 307180 | H1: 307338 | I1: 311990 | J1: 286423 | K1: 319695 | L1: 311416 | M1: 318248 | N1: 291695 | O1: 312646 | P1: 304598 | Q1: 296242 | R1: 288826 | S1: 314322 | T1: 316698 | U1: 322128 | V1: 283541 | W1: 311431 | X1: 312329 | Y1: 302624
A2: 2 | B2: 293432 | C2: 323455 | D2: 318573 | E2: 323594 | F2: 286248 | G2: 305144 | H2: 323899 | I2: 312943 | J2: 297999 | K2: 315842 | L2: 320325 | M2: 324740 | N2: 292085 | O2: 312973 | P2: 319228 | Q2: 302711 | R2: 305508 | S2: 318383 | T2: 322282 | U2: 316981 | V2: 297903 | W2: 311609 | X2: 308300 | Y2: 314458
A3: 3 | B3: 327999 | C3: 347570 | D3: 355714 | E3: 339257 | F3: 308978 | G3: 345558 | H3: 354354 | I3: 352016 | J3: 314949 | K3: 349152 | L3: 340235 | M3: 350394 | N3: 309317 | O3: 348295 | P3: 333356 | Q3: 339643 | R3: 317745 | S3: 348567 | T3: 345420 | U3: 346272 | V3: 318716 | W3: 337863 | X3: 345783 | Y3: 336286
A4: 4 | B4: 327651 | C4: 355046 | D4: 345412 | E4: 354693 | F4: 318890 | G4: 349573 | H4: 344082 | I4: 342536 | J4: 325513 | K4: 339409 | L4: 356646 | M4: 352047 | N4: 315067 | O4: 344489 | P4: 343900 | Q4: 345310 | R4: 327476 | S4: 342276 | T4: 347558 | U4: 356372 | V4: 326371 | W4: 339324 | X4: 348819 | Y4: 345870
A5: 5 | B5: 299415 | C5: 315649 | D5: 317279 | E5: 323260 | F5: 293113 | G5: 316170 | H5: 307027 | I5: 318590 | J5: 293916 | K5: 316200 | L5: 313278 | M5: 298109 | N5: 287580 | O5: 315485 | P5: 311348 | Q5: 315298 | R5: 292641 | S5: 304440 | T5: 307931 | U5: 325746 | V5: 282540 | W5: 307201 | X5: 314344 | Y5: 306998
A6: 6 | B6: 344861 | C6: 373496 | D6: 373677 | E6: 364736 | F6: 337688 | G6: 363169 | H6: 373757 | I6: 380316 | J6: 352148 | K6: 381033 | L6: 373971 | M6: 378583 | N6: 336708 | O6: 356900 | P6: 363507 | Q6: 369194 | R6: 345043 | S6: 358572 | T6: 372083 | U6: 366025 | V6: 347109 | W6: 365206 | X6: 368137 | Y6: 372425
A7: 7 | B7: 353945 | C7: 374500 | D7: 385331 | E7: 381358 | F7: 348788 | G7: 376547 | H7: 384567 | I7: 367576 | J7: 356699 | K7: 381805 | L7: 375452 | M7: 379160 | N7: 348284 | O7: 364312 | P7: 372104 | Q7: 362244 | R7: 348531 | S7: 377708 | T7: 378455 | U7: 382589 | V7: 356561 | W7: 367068 | X7: 373789 | Y7: 368310
A8: 8 | B8: 306740 | C8: 318196 | D8: 330372 | E8: 317878 | F8: 294348 | G8: 317096 | H8: 313606 | I8: 322492 | J8: 292190 | K8: 312682 | L8: 318910 | M8: 322271 | N8: 292767 | O8: 309019 | P8: 303993 | Q8: 315822 | R8: 290019 | S8: 303073 | T8: 319698 | U8: 315760 | V8: 281740 | W8: 301388 | X8: 316501 | Y8: 309264
A9: 9 | B9: 336090 | C9: 364398 | D9: 361972 | E9: 364915 | F9: 333915 | G9: 357314 | H9: 347917 | I9: 365083 | J9: 325743 | K9: 338761 | L9: 364133 | M9: 362984 | N9: 324744 | O9: 346018 | P9: 363309 | Q9: 344229 | R9: 338777 | S9: 357033 | T9: 363189 | U9: 364138 | V9: 322770 | W9: 349228 | X9: 353661 | Y9: 350482
A10: 10 | B10: 328566 | C10: 351397 | D10: 357161 | E10: 360758 | F10: 324418 | G10: 348514 | H10: 349164 | I10: 358318 | J10: 325316 | K10: 338526 | L10: 338962 | M10: 356213 | N10: 322723 | O10: 344049 | P10: 348976 | Q10: 350757 | R10: 332605 | S10: 353578 | T10: 341826 | U10: 352761 | V10: 311171 | W10: 335338 | X10: 346234 | Y10: 344284
A11: 11 | B11: 365802 | C11: 380759 | D11: 397795 | E11: 391712 | F11: 356888 | G11: 393488 | H11: 400947 | I11: 401321 | J11: 377675 | K11: 398588 | L11: 387635 | M11: 392462 | N11: 367896 | O11: 386232 | P11: 392935 | Q11: 395268 | R11: 364382 | S11: 379738 | T11: 398012 | U11: 401665 | V11: 359086 | W11: 387934 | X11: 389973 | Y11: 395129
A12: 12 | B12: 330025 | C12: 349220 | D12: 362189 | E12: 360036 | F12: 328432 | G12: 362467 | H12: 353674 | I12: 354610 | J12: 335172 | K12: 350578 | L12: 355136 | M12: 348645 | N12: 325972 | O12: 351730 | P12: 345366 | Q12: 351019 | R12: 338026 | S12: 358211 | T12: 353943 | U12: 357213 | V12: 329469 | W12: 347475 | X12: 348688 | Y12: 356234
... A60: 60 | B60: 281926 | C60: 276714 | D60: 287641 | E60: 288694 | F60: 265185 | G60: 285380 | H60: 291580 | I60: 293731 | J60: 269088 | K60: 291503 | L60: 295283 | M60: 288577 | N60: 282760 | O60: 280431 | P60: 286627 | Q60: 289123 | R60: 279906 | S60: 284149 | T60: 292738 | U60: 284257 | V60: 266584 | W60: 289689 | X60: 279950 | Y60: 284707

Sheet Planilha3
A1: 1 | B1: 295715 | C1: 320656 | D1: 316924 | E1: 327723 | F1: 278254 | G1: 313980 | H1: 314216 | I1: 303144 | J1: 293500 | K1: 315808 | L1: 315286 | M1: 314924 | N1: 292694 | O1: 311600 | P1: 316908 | Q1: 309535 | R1: 284910 | S1: 320770 | T1: 310426 | U1: 302725 | V1: 285309 | W1: 294674 | X1: 311226 | Y1: 306569
A2: 2 | B2: 295654 | C2: 314082 | D2: 311042 | E2: 325208 | F2: 287313 | G2: 307533 | H2: 316178 | I2: 321990 | J2: 300600 | K2: 320759 | L2: 323474 | M2: 324791 | N2: 297462 | O2: 315303 | P2: 314922 | Q2: 316953 | R2: 293594 | S2: 315280 | T2: 319825 | U2: 324101 | V2: 300290 | W2: 308010 | X2: 314229 | Y2: 314453
A3: 3 | B3: 319148 | C3: 342582 | D3: 358790 | E3: 357454 | F3: 322755 | G3: 347899 | H3: 346368 | I3: 344559 | J3: 325156 | K3: 348985 | L3: 350039 | M3: 353288 | N3: 304449 | O3: 333225 | P3: 338791 | Q3: 346820 | R3: 322107 | S3: 343432 | T3: 351362 | U3: 346784 | V3: 317483 | W3: 331868 | X3: 346261 | Y3: 336026
A4: 4 | B4: 326773 | C4: 353889 | D4: 360471 | E4: 348902 | F4: 329272 | G4: 345982 | H4: 333305 | I4: 344243 | J4: 326995 | K4: 352672 | L4: 350013 | M4: 354228 | N4: 328931 | O4: 341738 | P4: 353579 | Q4: 338655 | R4: 325973 | S4: 341086 | T4: 350381 | U4: 356476 | V4: 322074 | W4: 346088 | X4: 346449 | Y4: 338218
A5: 5 | B5: 304950 | C5: 317856 | D5: 315832 | E5: 315397 | F5: 293349 | G5: 309678 | H5: 312533 | I5: 305472 | J5: 287623 | K5: 300101 | L5: 315598 | M5: 316386 | N5: 284509 | O5: 313309 | P5: 311722 | Q5: 307939 | R5: 295265 | S5: 311307 | T5: 303198 | U5: 316746 | V5: 292527 | W5: 310453 | X5: 308749 | Y5: 314900
A6: 6 | B6: 354288 | C6: 374909 | D6: 368247 | E6: 366495 | F6: 334568 | G6: 372880 | H6: 365890 | I6: 364098 | J6: 348320 | K6: 376541 | L6: 366361 | M6: 373425 | N6: 337528 | O6: 365452 | P6: 363259 | Q6: 372220 | R6: 347129 | S6: 357716 | T6: 357458 | U6: 366164 | V6: 343358 | W6: 368929 | X6: 370852 | Y6: 375022
A7: 7 | B7: 345085 | C7: 388402 | D7: 392219 | E7: 384329 | F7: 350806 | G7: 379097 | H7: 371217 | I7: 374584 | J7: 349501 | K7: 378089 | L7: 378723 | M7: 371479 | N7: 354016 | O7: 373465 | P7: 372864 | Q7: 361416 | R7: 342300 | S7: 367708 | T7: 373700 | U7: 376480 | V7: 352187 | W7: 364213 | X7: 374338 | Y7: 367622
A8: 8 | B8: 297047 | C8: 322075 | D8: 321320 | E8: 321644 | F8: 294145 | G8: 315366 | H8: 319193 | I8: 323024 | J8: 292144 | K8: 315265 | L8: 312240 | M8: 316522 | N8: 290266 | O8: 314021 | P8: 306338 | Q8: 305715 | R8: 282713 | S8: 313418 | T8: 311136 | U8: 305921 | V8: 275038 | W8: 304666 | X8: 306458 | Y8: 307102
A9: 9 | B9: 331876 | C9: 360700 | D9: 365506 | E9: 367135 | F9: 330611 | G9: 352000 | H9: 351396 | I9: 342253 | J9: 336834 | K9: 360497 | L9: 351677 | M9: 350666 | N9: 327604 | O9: 347072 | P9: 359458 | Q9: 348562 | R9: 330474 | S9: 364460 | T9: 359897 | U9: 358887 | V9: 328719 | W9: 352179 | X9: 352872 | Y9: 353057
A10: 10 | B10: 331196 | C10: 350803 | D10: 355077 | E10: 357123 | F10: 322484 | G10: 328402 | H10: 353589 | I10: 343141 | J10: 318074 | K10: 354817 | L10: 353520 | M10: 346855 | N10: 327413 | O10: 349356 | P10: 348435 | Q10: 351801 | R10: 329230 | S10: 353664 | T10: 352979 | U10: 344009 | V10: 315589 | W10: 343511 | X10: 334823 | Y10: 348636
A11: 11 | B11: 354949 | C11: 396539 | D11: 398289 | E11: 404807 | F11: 371956 | G11: 399848 | H11: 373942 | I11: 387736 | J11: 355258 | K11: 397362 | L11: 397540 | M11: 393154 | N11: 365249 | O11: 376733 | P11: 393801 | Q11: 397866 | R11: 353885 | S11: 387016 | T11: 388788 | U11: 396192 | V11: 357363 | W11: 380642 | X11: 392450 | Y11: 395653
A12: 12 | B12: 340689 | C12: 359493 | D12: 365173 | E12: 354110 | F12: 326875 | G12: 357918 | H12: 357221 | I12: 354943 | J12: 327475 | K12: 362369 | L12: 350816 | M12: 358525 | N12: 327464 | O12: 360913 | P12: 342326 | Q12: 345199 | R12: 319507 | S12: 352430 | T12: 344984 | U12: 355629 | V12: 320380 | W12: 347364 | X12: 345314 | Y12: 339696
... A60: 60 | B60: 274039 | C60: 299823 | D60: 284791 | E60: 293201 | F60: 281226 | G60: 284104 | H60: 293895 | I60: 298804 | J60: 280540 | K60: 294422 | L60: 289774 | M60: 286096 | N60: 275093 | O60: 285221 | P60: 289440 | Q60: 294980 | R60: 285317 | S60: 284189 | T60: 281903 | U60: 294664 | V60: 273591 | W60: 278216 | X60: 280215 | Y60: 292204

Sheet Planilha4
A1: 1 | B1: 289191 | C1: 312688 | D1: 317152 | E1: 316418 | F1: 298058 | G1: 318418 | H1: 325476 | I1: 318514 | J1: 298687 | K1: 317061 | L1: 314780 | M1: 317995 | N1: 284947 | O1: 304732 | P1: 314559 | Q1: 316753 | R1: 292166 | S1: 311376 | T1: 312050 | U1: 315393 | V1: 284305 | W1: 309176 | X1: 316984 | Y1: 303277
A2: 2 | B2: 317354 | C2: 325576 | D2: 311557 | E2: 330140 | F2: 305925 | G2: 313400 | H2: 313745 | I2: 316575 | J2: 300024 | K2: 314642 | L2: 312902 | M2: 324248 | N2: 298679 | O2: 296018 | P2: 310535 | Q2: 318376 | R2: 298161 | S2: 305150 | T2: 319478 | U2: 321437 | V2: 296239 | W2: 306983 | X2: 321585 | Y2: 313174
A3: 3 | B3: 329605 | C3: 330535 | D3: 349791 | E3: 354570 | F3: 311382 | G3: 355404 | H3: 346790 | I3: 350694 | J3: 318777 | K3: 348977 | L3: 349339 | M3: 346439 | N3: 302660 | O3: 334171 | P3: 353009 | Q3: 339793 | R3: 319612 | S3: 348856 | T3: 346563 | U3: 340062 | V3: 316013 | W3: 343401 | X3: 341016 | Y3: 342235
A4: 4 | B4: 316679 | C4: 343614 | D4: 356252 | E4: 344208 | F4: 317918 | G4: 343336 | H4: 342752 | I4: 355740 | J4: 325439 | K4: 351501 | L4: 350593 | M4: 353759 | N4: 323423 | O4: 345226 | P4: 340668 | Q4: 346978 | R4: 324873 | S4: 335410 | T4: 352663 | U4: 355399 | V4: 319298 | W4: 345526 | X4: 343131 | Y4: 347474
A5: 5 | B5: 296156 | C5: 318464 | D5: 311652 | E5: 322776 | F5: 294578 | G5: 314399 | H5: 309498 | I5: 319702 | J5: 294445 | K5: 324952 | L5: 313812 | M5: 308865 | N5: 292925 | O5: 300102 | P5: 317295 | Q5: 311058 | R5: 279764 | S5: 312016 | T5: 308141 | U5: 317320 | V5: 281660 | W5: 308075 | X5: 316984 | Y5: 305957
A6: 6 | B6: 356797 | C6: 364900 | D6: 364281 | E6: 355873 | F6: 351115 | G6: 363831 | H6: 376661 | I6: 378913 | J6: 337692 | K6: 378067 | L6: 374466 | M6: 384626 | N6: 340092 | O6: 359362 | P6: 364270 | Q6: 366431 | R6: 344434 | S6: 361632 | T6: 367668 | U6: 372977 | V6: 346700 | W6: 367090 | X6: 362539 | Y6: 357297
A7: 7 | B7: 344833 | C7: 380746 | D7: 381479 | E7: 380325 | F7: 348009 | G7: 381083 | H7: 382869 | I7: 378459 | J7: 335807 | K7: 369001 | L7: 363622 | M7: 378662 | N7: 354712 | O7: 365368 | P7: 371177 | Q7: 375107 | R7: 352947 | S7: 384791 | T7: 366878 | U7: 367900 | V7: 344635 | W7: 370483 | X7: 364021 | Y7: 372051
A8: 8 | B8: 310300 | C8: 326479 | D8: 307983 | E8: 321611 | F8: 281646 | G8: 312603 | H8: 317879 | I8: 315349 | J8: 283651 | K8: 302710 | L8: 318430 | M8: 318363 | N8: 289508 | O8: 308911 | P8: 309686 | Q8: 315639 | R8: 289764 | S8: 310835 | T8: 318600 | U8: 316806 | V8: 290554 | W8: 306654 | X8: 317796 | Y8: 301050
A9: 9 | B9: 333813 | C9: 361821 | D9: 355890 | E9: 361652 | F9: 334001 | G9: 355538 | H9: 358639 | I9: 343915 | J9: 341520 | K9: 359111 | L9: 343802 | M9: 361188 | N9: 327801 | O9: 356297 | P9: 352146 | Q9: 352908 | R9: 323168 | S9: 355228 | T9: 354665 | U9: 368654 | V9: 324386 | W9: 355279 | X9: 343471 | Y9: 355997
A10: 10 | B10: 320474 | C10: 356087 | D10: 356528 | E10: 356329 | F10: 323210 | G10: 351710 | H10: 355528 | I10: 353995 | J10: 322831 | K10: 352390 | L10: 348359 | M10: 340321 | N10: 315786 | O10: 350574 | P10: 344633 | Q10: 349683 | R10: 327469 | S10: 343422 | T10: 349663 | U10: 354957 | V10: 318796 | W10: 347717 | X10: 353980 | Y10: 343167
A11: 11 | B11: 365827 | C11: 393086 | D11: 392419 | E11: 403788 | F11: 365520 | G11: 389539 | H11: 398667 | I11: 395362 | J11: 373269 | K11: 400922 | L11: 398518 | M11: 401721 | N11: 364784 | O11: 385935 | P11: 389483 | Q11: 397355 | R11: 364853 | S11: 385454 | T11: 400178 | U11: 399877 | V11: 369165 | W11: 375291 | X11: 389698 | Y11: 385649
A12: 12 | B12: 326427 | C12: 350969 | D12: 360082 | E12: 362892 | F12: 325501 | G12: 347755 | H12: 359847 | I12: 358290 | J12: 330923 | K12: 349716 | L12: 360082 | M12: 347095 | N12: 324294 | O12: 348698 | P12: 360082 | Q12: 356454 | R12: 336229 | S12: 353991 | T12: 359456 | U12: 361059 | V12: 327993 | W12: 346540 | X12: 353738 | Y12: 352523
... A60: 60 | B60: 277246 | C60: 291734 | D60: 296512 | E60: 293201 | F60: 284851 | G60: 290573 | H60: 295862 | I60: 293015 | J60: 283480 | K60: 286557 | L60: 289769 | M60: 280033 | N60: 279867 | O60: 277514 | P60: 286259 | Q60: 287812 | R60: 277790 | S60: 291161 | T60: 293201 | U60: 293201 | V60: 273693 | W60: 283353 | X60: 282118 | Y60: 292323

Sheet Planilha5
A1: 1 | B1: 303238 | C1: 312944 | D1: 321678 | E1: 298768 | F1: 305711 | G1: 304526 | H1: 319172 | I1: 315392 | J1: 300902 | K1: 315288 | L1: 328219 | M1: 312085 | N1: 285012 | O1: 308250 | P1: 314648 | Q1: 305116 | R1: 289540 | S1: 310634 | T1: 312617 | U1: 310636 | V1: 290557 | W1: 299352 | X1: 315488 | Y1: 316726
A2: 2 | B2: 294576 | C2: 320503 | D2: 326077 | E2: 326571 | F2: 292371 | G2: 317360 | H2: 316539 | I2: 322680 | J2: 299031 | K2: 316233 | L2: 313593 | M2: 330836 | N2: 295846 | O2: 306278 | P2: 316141 | Q2: 298019 | R2: 299408 | S2: 313583 | T2: 311530 | U2: 315875 | V2: 292326 | W2: 315130 | X2: 317399 | Y2: 310250
A3: 3 | B3: 321894 | C3: 349777 | D3: 352780 | E3: 354394 | F3: 319965 | G3: 334631 | H3: 345084 | I3: 347170 | J3: 313100 | K3: 345669 | L3: 337416 | M3: 349527 | N3: 315478 | O3: 343643 | P3: 352743 | Q3: 341713 | R3: 311642 | S3: 339763 | T3: 349463 | U3: 332798 | V3: 304659 | W3: 336133 | X3: 347998 | Y3: 339801
A4: 4 | B4: 335122 | C4: 343382 | D4: 351780 | E4: 348392 | F4: 332475 | G4: 353166 | H4: 347290 | I4: 334589 | J4: 325538 | K4: 346141 | L4: 344439 | M4: 349361 | N4: 328617 | O4: 345810 | P4: 350345 | Q4: 341225 | R4: 328767 | S4: 342108 | T4: 356069 | U4: 345759 | V4: 324695 | W4: 329839 | X4: 343495 | Y4: 339168
A5: 5 | B5: 291815 | C5: 321890 | D5: 318730 | E5: 310156 | F5: 286815 | G5: 317656 | H5: 318311 | I5: 317190 | J5: 298771 | K5: 314975 | L5: 319839 | M5: 316867 | N5: 282881 | O5: 300501 | P5: 312537 | Q5: 319564 | R5: 290293 | S5: 300719 | T5: 315351 | U5: 316733 | V5: 280817 | W5: 303269 | X5: 307434 | Y5: 313536
A6: 6 | B6: 349169 | C6: 374160 | D6: 373103 | E6: 369698 | F6: 344178 | G6: 356070 | H6: 349146 | I6: 371063 | J6: 345794 | K6: 365471 | L6: 365025 | M6: 375939 | N6: 343296 | O6: 368117 | P6: 368370 | Q6: 345128 | R6: 346605 | S6: 375949 | T6: 358006 | U6: 367888 | V6: 333645 | W6: 351268 | X6: 373798 | Y6: 372486
A7: 7 | B7: 348352 | C7: 375137 | D7: 383189 | E7: 389857 | F7: 346068 | G7: 380029 | H7: 370565 | I7: 384814 | J7: 355355 | K7: 368710 | L7: 379992 | M7: 376598 | N7: 347250 | O7: 383009 | P7: 378396 | Q7: 376088 | R7: 360343 | S7: 371844 | T7: 380212 | U7: 373738 | V7: 350809 | W7: 364625 | X7: 376987 | Y7: 378907
A8: 8 | B8: 302373 | C8: 326106 | D8: 310474 | E8: 323196 | F8: 279987 | G8: 311948 | H8: 323120 | I8: 315968 | J8: 282920 | K8: 314290 | L8: 318380 | M8: 321238 | N8: 288690 | O8: 308542 | P8: 303487 | Q8: 307174 | R8: 275853 | S8: 311053 | T8: 298145 | U8: 306444 | V8: 291040 | W8: 314487 | X8: 317354 | Y8: 307209
A9: 9 | B9: 344604 | C9: 344639 | D9: 364743 | E9: 365617 | F9: 338012 | G9: 358138 | H9: 357614 | I9: 357730 | J9: 329028 | K9: 364639 | L9: 356802 | M9: 340096 | N9: 325878 | O9: 347937 | P9: 348615 | Q9: 360418 | R9: 332538 | S9: 354448 | T9: 357721 | U9: 356312 | V9: 325227 | W9: 341576 | X9: 357815 | Y9: 355738
A10: 10 | B10: 332282 | C10: 343400 | D10: 346726 | E10: 345674 | F10: 317442 | G10: 343082 | H10: 350844 | I10: 359940 | J10: 333918 | K10: 353250 | L10: 349186 | M10: 354369 | N10: 332428 | O10: 344905 | P10: 352048 | Q10: 348232 | R10: 316666 | S10: 350009 | T10: 342466 | U10: 355486 | V10: 318802 | W10: 348404 | X10: 348188 | Y10: 355470
A11: 11 | B11: 361298 | C11: 397099 | D11: 410253 | E11: 408349 | F11: 362400 | G11: 398329 | H11: 383337 | I11: 400579 | J11: 358720 | K11: 389121 | L11: 392090 | M11: 399244 | N11: 361714 | O11: 388920 | P11: 394985 | Q11: 396646 | R11: 365386 | S11: 382072 | T11: 385219 | U11: 400069 | V11: 360697 | W11: 391060 | X11: 383908 | Y11: 391523
A12: 12 | B12: 323514 | C12: 358313 | D12: 355836 | E12: 357404 | F12: 330388 | G12: 351268 | H12: 345096 | I12: 350818 | J12: 328184 | K12: 358964 | L12: 354152 | M12: 344258 | N12: 323656 | O12: 346430 | P12: 356234 | Q12: 352003 | R12: 332310 | S12: 351625 | T12: 356233 | U12: 358925 | V12: 329592 | W12: 346865 | X12: 353924 | Y12: 349972
... A60: 60 | B60: 283498 | C60: 294674 | D60: 290681 | E60: 297958 | F60: 269822 | G60: 290889 | H60: 288358 | I60: 293201 | J60: 270880 | K60: 294084 | L60: 293248 | M60: 297961 | N60: 272068 | O60: 282709 | P60: 287238 | Q60: 292253 | R60: 286096 | S60: 286619 | T60: 284468 | U60: 290496 | V60: 283788 | W60: 284517 | X60: 290099 | Y60: 284851

Sheet Planilha6
A1: 1 | B1: 297437 | C1: 314814 | D1: 321705 | E1: 332476 | F1: 294037 | G1: 320779 | H1: 319656 | I1: 323414 | J1: 285044 | K1: 323822 | L1: 317885 | M1: 320288 | N1: 301397 | O1: 311017 | P1: 315611 | Q1: 313668 | R1: 280573 | S1: 312597 | T1: 317601 | U1: 309320 | V1: 283446 | W1: 311413 | X1: 310882 | Y1: 308316
A2: 2 | B2: 303541 | C2: 323015 | D2: 314594 | E2: 315301 | F2: 300638 | G2: 318875 | H2: 315262 | I2: 320260 | J2: 301348 | K2: 319119 | L2: 304925 | M2: 310373 | N2: 295903 | O2: 321049 | P2: 321054 | Q2: 318191 | R2: 299842 | S2: 315794 | T2: 318245 | U2: 318898 | V2: 294142 | W2: 316274 | X2: 315989 | Y2: 312088
A3: 3 | B3: 336020 | C3: 358099 | D3: 355199 | E3: 344337 | F3: 313046 | G3: 345531 | H3: 345798 | I3: 341917 | J3: 318486 | K3: 346986 | L3: 349761 | M3: 354833 | N3: 314428 | O3: 332184 | P3: 344702 | Q3: 350970 | R3: 318440 | S3: 351287 | T3: 345636 | U3: 343284 | V3: 307496 | W3: 326885 | X3: 342345 | Y3: 338423
A4: 4 | B4: 329498 | C4: 345783 | D4: 345782 | E4: 344160 | F4: 321286 | G4: 344181 | H4: 350834 | I4: 343044 | J4: 326069 | K4: 345651 | L4: 350515 | M4: 339795 | N4: 315083 | O4: 340150 | P4: 340798 | Q4: 347374 | R4: 320757 | S4: 345146 | T4: 338155 | U4: 348951 | V4: 317669 | W4: 339470 | X4: 338606 | Y4: 329403
A5: 5 | B5: 297499 | C5: 326121 | D5: 321483 | E5: 319425 | F5: 298701 | G5: 306496 | H5: 313348 | I5: 320535 | J5: 282282 | K5: 310225 | L5: 317507 | M5: 308209 | N5: 284047 | O5: 304209 | P5: 301363 | Q5: 321458 | R5: 291942 | S5: 314657 | T5: 320540 | U5: 317763 | V5: 288476 | W5: 306964 | X5: 313018 | Y5: 303002
A6: 6 | B6: 350242 | C6: 370999 | D6: 369118 | E6: 381076 | F6: 349118 | G6: 359631 | H6: 372083 | I6: 366622 | J6: 326118 | K6: 376508 | L6: 369185 | M6: 371852 | N6: 341228 | O6: 363579 | P6: 362460 | Q6: 365380 | R6: 344885 | S6: 369834 | T6: 374397 | U6: 372695 | V6: 339402 | W6: 362141 | X6: 364932 | Y6: 375044
A7: 7 | B7: 367302 | C7: 379566 | D7: 388896 | E7: 379198 | F7: 354675 | G7: 382308 | H7: 381103 | I7: 362307 | J7: 341353 | K7: 381056 | L7: 373878 | M7: 380823 | N7: 348983 | O7: 368089 | P7: 378144 | Q7: 373972 | R7: 348071 | S7: 377839 | T7: 380489 | U7: 378252 | V7: 346683 | W7: 371765 | X7: 370601 | Y7: 377667
A8: 8 | B8: 288700 | C8: 321323 | D8: 313325 | E8: 320927 | F8: 286507 | G8: 313794 | H8: 301722 | I8: 309533 | J8: 295438 | K8: 312475 | L8: 312730 | M8: 320315 | N8: 279067 | O8: 296060 | P8: 315050 | Q8: 316022 | R8: 282979 | S8: 318187 | T8: 311729 | U8: 318882 | V8: 273492 | W8: 314427 | X8: 309025 | Y8: 307916
A9: 9 | B9: 343167 | C9: 360638 | D9: 369912 | E9: 360133 | F9: 327723 | G9: 354200 | H9: 356558 | I9: 365887 | J9: 318098 | K9: 347793 | L9: 357546 | M9: 362601 | N9: 334325 | O9: 352877 | P9: 351719 | Q9: 358138 | R9: 331901 | S9: 356037 | T9: 362779 | U9: 348841 | V9: 325085 | W9: 342656 | X9: 358469 | Y9: 353596
A10: 10 | B10: 328072 | C10: 347425 | D10: 352696 | E10: 343678 | F10: 321289 | G10: 349700 | H10: 354582 | I10: 348105 | J10: 310734 | K10: 339926 | L10: 351684 | M10: 353693 | N10: 317477 | O10: 335292 | P10: 350519 | Q10: 346777 | R10: 332272 | S10: 351531 | T10: 347311 | U10: 351777 | V10: 322947 | W10: 333019 | X10: 354638 | Y10: 345222
A11: 11 | B11: 369768 | C11: 389303 | D11: 405335 | E11: 403970 | F11: 368842 | G11: 385718 | H11: 397975 | I11: 387307 | J11: 361877 | K11: 400743 | L11: 396010 | M11: 369738 | N11: 365650 | O11: 390968 | P11: 389682 | Q11: 389882 | R11: 368967 | S11: 394414 | T11: 399496 | U11: 399911 | V11: 365939 | W11: 392456 | X11: 387673 | Y11: 373509
A12: 12 | B12: 327377 | C12: 350816 | D12: 362989 | E12: 362843 | F12: 326387 | G12: 340642 | H12: 357669 | I12: 359920 | J12: 334157 | K12: 346496 | L12: 355807 | M12: 366496 | N12: 326561 | O12: 339525 | P12: 338821 | Q12: 348818 | R12: 326062 | S12: 350130 | T12: 349673 | U12: 355598 | V12: 328545 | W12: 348845 | X12: 353606 | Y12: 355337
... A60: 60 | B60: 286313 | C60: 282026 | D60: 301101 | E60: 302362 | F60: 287972 | G60: 287472 | H60: 283819 | I60: 283729 | J60: 286280 | K60: 285046 | L60: 298776 | M60: 290288 | N60: 268290 | O60: 275324 | P60: 289098 | Q60: 291378 | R60: 279020 | S60: 291047 | T60: 284149 | U60: 293875 | V60: 274356 | W60: 283291 | X60: 286199 | Y60: 290858

Sheet Planilha7
A1: 1 | B1: 300880 | C1: 309176 | D1: 307355 | E1: 315034 | F1: 293864 | G1: 312137 | H1: 317751 | I1: 318788 | J1: 301992 | K1: 314883 | L1: 319146 | M1: 320763 | N1: 287512 | O1: 295804 | P1: 304683 | Q1: 315086 | R1: 285446 | S1: 312772 | T1: 309442 | U1: 308337 | V1: 290100 | W1: 307224 | X1: 314217 | Y1: 311023
A2: 2 | B2: 299826 | C2: 322328 | D2: 318642 | E2: 322155 | F2: 296170 | G2: 317557 | H2: 324464 | I2: 319122 | J2: 301594 | K2: 318779 | L2: 320586 | M2: 320350 | N2: 290764 | O2: 311524 | P2: 318880 | Q2: 313611 | R2: 296581 | S2: 316462 | T2: 314945 | U2: 311329 | V2: 297240 | W2: 312235 | X2: 315607 | Y2: 316857
A3: 3 | B3: 309350 | C3: 345573 | D3: 350901 | E3: 354032 | F3: 319720 | G3: 340408 | H3: 336001 | I3: 343905 | J3: 322388 | K3: 351098 | L3: 349331 | M3: 342359 | N3: 314341 | O3: 346517 | P3: 347184 | Q3: 343762 | R3: 315454 | S3: 331274 | T3: 348704 | U3: 351356 | V3: 311261 | W3: 338025 | X3: 339283 | Y3: 342059
A4: 4 | B4: 326564 | C4: 352538 | D4: 357138 | E4: 351721 | F4: 316984 | G4: 341343 | H4: 349879 | I4: 356292 | J4: 324556 | K4: 338577 | L4: 348837 | M4: 347223 | N4: 326999 | O4: 329149 | P4: 346106 | Q4: 349876 | R4: 327964 | S4: 346110 | T4: 346058 | U4: 349252 | V4: 320785 | W4: 346110 | X4: 344941 | Y4: 339469
A5: 5 | B5: 292419 | C5: 314334 | D5: 305283 | E5: 311411 | F5: 283680 | G5: 319987 | H5: 312270 | I5: 323891 | J5: 291601 | K5: 306940 | L5: 320816 | M5: 313426 | N5: 287999 | O5: 313316 | P5: 306800 | Q5: 317488 | R5: 291382 | S5: 316559 | T5: 316047 | U5: 313898 | V5: 294365 | W5: 309196 | X5: 303428 | Y5: 310175
A6: 6 | B6: 332104 | C6: 360903 | D6: 375108 | E6: 370170 | F6: 354281 | G6: 366960 | H6: 372523 | I6: 366229 | J6: 345116 | K6: 362011 | L6: 369242 | M6: 372898 | N6: 345170 | O6: 365858 | P6: 345543 | Q6: 369914 | R6: 343552 | S6: 366220 | T6: 372393 | U6: 368080 | V6: 343630 | W6: 358702 | X6: 371104 | Y6: 372850
A7: 7 | B7: 362892 | C7: 381508 | D7: 388819 | E7: 380928 | F7: 329026 | G7: 377953 | H7: 384009 | I7: 375676 | J7: 348448 | K7: 370914 | L7: 375302 | M7: 374488 | N7: 344460 | O7: 366714 | P7: 371934 | Q7: 368836 | R7: 353958 | S7: 365350 | T7: 376923 | U7: 379148 | V7: 348378 | W7: 365994 | X7: 368551 | Y7: 375889
A8: 8 | B8: 304143 | C8: 314391 | D8: 309803 | E8: 314444 | F8: 295418 | G8: 308043 | H8: 324818 | I8: 315576 | J8: 301966 | K8: 310978 | L8: 315942 | M8: 320344 | N8: 291020 | O8: 306603 | P8: 310963 | Q8: 304557 | R8: 285116 | S8: 317794 | T8: 309457 | U8: 315574 | V8: 296204 | W8: 304792 | X8: 312554 | Y8: 314634
A9: 9 | B9: 341057 | C9: 360851 | D9: 353986 | E9: 370787 | F9: 331380 | G9: 347936 | H9: 360334 | I9: 362972 | J9: 336435 | K9: 360324 | L9: 362243 | M9: 354322 | N9: 332876 | O9: 346084 | P9: 355488 | Q9: 347385 | R9: 328338 | S9: 348211 | T9: 359070 | U9: 366726 | V9: 332745 | W9: 348390 | X9: 341816 | Y9: 360973
A10: 10 | B10: 324507 | C10: 351139 | D10: 359378 | E10: 355248 | F10: 324650 | G10: 337920 | H10: 344531 | I10: 354896 | J10: 325577 | K10: 344242 | L10: 354854 | M10: 353659 | N10: 330694 | O10: 337588 | P10: 346209 | Q10: 349868 | R10: 331673 | S10: 334853 | T10: 341865 | U10: 354985 | V10: 331343 | W10: 334998 | X10: 345631 | Y10: 351703
A11: 11 | B11: 365631 | C11: 407806 | D11: 391051 | E11: 374548 | F11: 373936 | G11: 379499 | H11: 385881 | I11: 404186 | J11: 370660 | K11: 392226 | L11: 391714 | M11: 401434 | N11: 367028 | O11: 389273 | P11: 384933 | Q11: 391400 | R11: 371488 | S11: 384650 | T11: 385849 | U11: 396580 | V11: 359014 | W11: 389515 | X11: 377089 | Y11: 393886
A12: 12 | B12: 323909 | C12: 358870 | D12: 360082 | E12: 352015 | F12: 327643 | G12: 348257 | H12: 363391 | I12: 348703 | J12: 329808 | K12: 341304 | L12: 354370 | M12: 346209 | N12: 324757 | O12: 352684 | P12: 342568 | Q12: 356549 | R12: 331770 | S12: 354484 | T12: 355448 | U12: 361818 | V12: 322936 | W12: 345086 | X12: 351894 | Y12: 352457
... A60: 60 | B60: 284755 | C60: 293322 | D60: 291083 | E60: 299500 | F60: 278154 | G60: 286560 | H60: 291169 | I60: 294224 | J60: 280943 | K60: 287520 | L60: 284414 | M60: 293201 | N60: 281860 | O60: 280902 | P60: 285237 | Q60: 298521 | R60: 281783 | S60: 291998 | T60: 290084 | U60: 291602 | V60: 273995 | W60: 286459 | X60: 286123 | Y60: 285866

Sheet Planilha8
A1: 1 | B1: 302805 | C1: 324770 | D1: 318699 | E1: 322083 | F1: 287297 | G1: 310021 | H1: 306185 | I1: 311554 | J1: 283962 | K1: 316579 | L1: 317254 | M1: 308850 | N1: 277859 | O1: 307588 | P1: 316432 | Q1: 298322 | R1: 300377 | S1: 309415 | T1: 313032 | U1: 303716 | V1: 281791 | W1: 302959 | X1: 312759 | Y1: 316300
A2: 2 | B2: 303132 | C2: 317474 | D2: 324170 | E2: 323702 | F2: 303931 | G2: 308370 | H2: 313780 | I2: 320752 | J2: 292675 | K2: 323867 | L2: 316144 | M2: 307817 | N2: 297534 | O2: 311683 | P2: 320395 | Q2: 315165 | R2: 299670 | S2: 319732 | T2: 306042 | U2: 317665 | V2: 291184 | W2: 315320 | X2: 312073 | Y2: 318477
A3: 3 | B3: 326635 | C3: 356262 | D3: 354789 | E3: 346220 | F3: 312028 | G3: 346378 | H3: 340657 | I3: 350492 | J3: 319550 | K3: 347447 | L3: 352431 | M3: 342978 | N3: 315696 | O3: 339034 | P3: 345224 | Q3: 352259 | R3: 318843 | S3: 344627 | T3: 338327 | U3: 352441 | V3: 314240 | W3: 343316 | X3: 335252 | Y3: 343626
A4: 4 | B4: 330674 | C4: 352500 | D4: 357400 | E4: 351782 | F4: 334670 | G4: 335172 | H4: 343622 | I4: 351932 | J4: 317164 | K4: 334048 | L4: 342209 | M4: 355390 | N4: 328186 | O4: 341627 | P4: 343505 | Q4: 348212 | R4: 326723 | S4: 346948 | T4: 345057 | U4: 353182 | V4: 315823 | W4: 347068 | X4: 343609 | Y4: 331730
A5: 5 | B5: 292213 | C5: 322734 | D5: 308341 | E5: 320159 | F5: 289142 | G5: 306666 | H5: 316698 | I5: 321094 | J5: 286124 | K5: 323024 | L5: 318391 | M5: 311625 | N5: 280215 | O5: 310552 | P5: 315260 | Q5: 313713 | R5: 285742 | S5: 314051 | T5: 311353 | U5: 320794 | V5: 295034 | W5: 299886 | X5: 315580 | Y5: 305098
A6: 6 | B6: 339860 | C6: 359723 | D6: 364236 | E6: 378002 | F6: 346497 | G6: 367090 | H6: 364278 | I6: 376588 | J6: 357540 | K6: 365540 | L6: 365982 | M6: 369243 | N6: 349758 | O6: 361491 | P6: 371353 | Q6: 369013 | R6: 347182 | S6: 362649 | T6: 357289 | U6: 362193 | V6: 329052 | W6: 361020 | X6: 367203 | Y6: 363673
A7: 7 | B7: 353080 | C7: 380418 | D7: 387634 | E7: 391110 | F7: 346705 | G7: 371264 | H7: 381837 | I7: 382384 | J7: 345442 | K7: 371976 | L7: 385341 | M7: 377137 | N7: 347294 | O7: 369392 | P7: 377731 | Q7: 371069 | R7: 353289 | S7: 379073 | T7: 358765 | U7: 378754 | V7: 330679 | W7: 344824 | X7: 379614 | Y7: 374001
A8: 8 | B8: 299787 | C8: 318160 | D8: 324432 | E8: 316174 | F8: 289841 | G8: 314612 | H8: 320827 | I8: 322479 | J8: 291477 | K8: 310883 | L8: 317818 | M8: 323361 | N8: 289761 | O8: 313978 | P8: 311729 | Q8: 316305 | R8: 297825 | S8: 299661 | T8: 314823 | U8: 321682 | V8: 288083 | W8: 311574 | X8: 305163 | Y8: 304943
A9: 9 | B9: 340849 | C9: 368573 | D9: 364816 | E9: 369010 | F9: 339386 | G9: 354748 | H9: 356048 | I9: 359673 | J9: 333498 | K9: 342567 | L9: 339451 | M9: 354528 | N9: 334785 | O9: 350402 | P9: 360292 | Q9: 356765 | R9: 338068 | S9: 354804 | T9: 365938 | U9: 350787 | V9: 328874 | W9: 345899 | X9: 350002 | Y9: 360046
A10: 10 | B10: 331971 | C10: 350614 | D10: 356618 | E10: 340332 | F10: 320405 | G10: 347601 | H10: 348672 | I10: 348107 | J10: 325393 | K10: 344534 | L10: 359616 | M10: 342883 | N10: 315344 | O10: 343773 | P10: 357324 | Q10: 346321 | R10: 311597 | S10: 343626 | T10: 343142 | U10: 353702 | V10: 323129 | W10: 344215 | X10: 349484 | Y10: 346698
A11: 11 | B11: 350305 | C11: 373070 | D11: 402588 | E11: 399245 | F11: 352130 | G11: 377051 | H11: 409136 | I11: 391106 | J11: 375272 | K11: 382243 | L11: 376448 | M11: 400414 | N11: 360701 | O11: 388713 | P11: 392682 | Q11: 387904 | R11: 363000 | S11: 394759 | T11: 390917 | U11: 387907 | V11: 361167 | W11: 389221 | X11: 391945 | Y11: 395461
A12: 12 | B12: 326272 | C12: 356380 | D12: 359116 | E12: 371527 | F12: 332323 | G12: 353248 | H12: 350089 | I12: 361788 | J12: 326556 | K12: 353251 | L12: 358152 | M12: 360335 | N12: 325320 | O12: 354495 | P12: 344085 | Q12: 352091 | R12: 332018 | S12: 358190 | T12: 351369 | U12: 354254 | V12: 321003 | W12: 353668 | X12: 336981 | Y12: 361359
... A60: 60 | B60: 273386 | C60: 287999 | D60: 293201 | E60: 292798 | F60: 268530 | G60: 287329 | H60: 285310 | I60: 291632 | J60: 281462 | K60: 281321 | L60: 291389 | M60: 288362 | N60: 274510 | O60: 282048 | P60: 296524 | Q60: 292314 | R60: 287503 | S60: 287133 | T60: 291679 | U60: 280584 | V60: 275099 | W60: 274842 | X60: 288978 | Y60: 291062

Sheet Planilha9
A1: 1 | B1: 296967 | C1: 312244 | D1: 314836 | E1: 321961 | F1: 296539 | G1: 314590 | H1: 321692 | I1: 319675 | J1: 288925 | K1: 323002 | L1: 305659 | M1: 310710 | N1: 292510 | O1: 314796 | P1: 314809 | Q1: 304296 | R1: 296501 | S1: 316245 | T1: 317963 | U1: 316672 | V1: 283881 | W1: 314803 | X1: 316539 | Y1: 300982
A2: 2 | B2: 291435 | C2: 309286 | D2: 317639 | E2: 318296 | F2: 286084 | G2: 321030 | H2: 321007 | I2: 318162 | J2: 291680 | K2: 322226 | L2: 315348 | M2: 326967 | N2: 291553 | O2: 305299 | P2: 316793 | Q2: 313847 | R2: 299142 | S2: 315985 | T2: 322529 | U2: 313956 | V2: 297756 | W2: 309368 | X2: 311188 | Y2: 314155
A3: 3 | B3: 324548 | C3: 338702 | D3: 343132 | E3: 346913 | F3: 319484 | G3: 350378 | H3: 352711 | I3: 349882 | J3: 316034 | K3: 354739 | L3: 344999 | M3: 360006 | N3: 323275 | O3: 337438 | P3: 344533 | Q3: 347947 | R3: 325111 | S3: 333120 | T3: 349749 | U3: 343575 | V3: 302525 | W3: 337000 | X3: 345785 | Y3: 347361
A4: 4 | B4: 324633 | C4: 362072 | D4: 345091 | E4: 338921 | F4: 318659 | G4: 342432 | H4: 352509 | I4: 355005 | J4: 333541 | K4: 345942 | L4: 342067 | M4: 353426 | N4: 321272 | O4: 336075 | P4: 342846 | Q4: 353258 | R4: 318441 | S4: 338112 | T4: 338887 | U4: 344201 | V4: 329602 | W4: 342570 | X4: 341742 | Y4: 344664
A5: 5 | B5: 302606 | C5: 309828 | D5: 317459 | E5: 315925 | F5: 289877 | G5: 315337 | H5: 314558 | I5: 312298 | J5: 298717 | K5: 320875 | L5: 313164 | M5: 319334 | N5: 291327 | O5: 308784 | P5: 313080 | Q5: 316627 | R5: 299170 | S5: 312748 | T5: 306833 | U5: 309637 | V5: 294403 | W5: 300208 | X5: 314393 | Y5: 307459
A6: 6 | B6: 349915 | C6: 374258 | D6: 364338 | E6: 374886 | F6: 346266 | G6: 372663 | H6: 369410 | I6: 364472 | J6: 345374 | K6: 374067 | L6: 375000 | M6: 371914 | N6: 332725 | O6: 369526 | P6: 361724 | Q6: 368805 | R6: 349667 | S6: 375951 | T6: 378483 | U6: 375569 | V6: 337148 | W6: 362753 | X6: 363800 | Y6: 370353
A7: 7 | B7: 356694 | C7: 374369 | D7: 386729 | E7: 381346 | F7: 345994 | G7: 367999 | H7: 371566 | I7: 368497 | J7: 352379 | K7: 381786 | L7: 372972 | M7: 383754 | N7: 347288 | O7: 375111 | P7: 368197 | Q7: 373070 | R7: 341576 | S7: 372751 | T7: 365550 | U7: 372111 | V7: 338476 | W7: 373041 | X7: 377728 | Y7: 383978
A8: 8 | B8: 294007 | C8: 314192 | D8: 321973 | E8: 324040 | F8: 282510 | G8: 318527 | H8: 313072 | I8: 315888 | J8: 297889 | K8: 303818 | L8: 320908 | M8: 317357 | N8: 279828 | O8: 303319 | P8: 315257 | Q8: 306230 | R8: 297866 | S8: 317694 | T8: 313635 | U8: 304658 | V8: 289824 | W8: 313796 | X8: 306511 | Y8: 302876
A9: 9 | B9: 331591 | C9: 363805 | D9: 359064 | E9: 348528 | F9: 338542 | G9: 354110 | H9: 358825 | I9: 348532 | J9: 334936 | K9: 355946 | L9: 337459 | M9: 356952 | N9: 323793 | O9: 352844 | P9: 343085 | Q9: 354086 | R9: 324409 | S9: 349918 | T9: 362759 | U9: 357337 | V9: 328841 | W9: 349732 | X9: 351901 | Y9: 356231
A10: 10 | B10: 326265 | C10: 355653 | D10: 358448 | E10: 342844 | F10: 332576 | G10: 352736 | H10: 354126 | I10: 346895 | J10: 328399 | K10: 360403 | L10: 352497 | M10: 353070 | N10: 319540 | O10: 348248 | P10: 352859 | Q10: 346757 | R10: 324453 | S10: 337533 | T10: 352696 | U10: 351774 | V10: 317554 | W10: 347085 | X10: 346698 | Y10: 351306
A11: 11 | B11: 367677 | C11: 407248 | D11: 394480 | E11: 406043 | F11: 363210 | G11: 386218 | H11: 396082 | I11: 389864 | J11: 374440 | K11: 388940 | L11: 400343 | M11: 395652 | N11: 357513 | O11: 399403 | P11: 390684 | Q11: 397500 | R11: 360151 | S11: 379953 | T11: 399505 | U11: 395684 | V11: 360271 | W11: 387781 | X11: 383990 | Y11: 390269
A12: 12 | B12: 311077 | C12: 339888 | D12: 357195 | E12: 359259 | F12: 319366 | G12: 356869 | H12: 354913 | I12: 357560 | J12: 330238 | K12: 355870 | L12: 349442 | M12: 356107 | N12: 328303 | O12: 352527 | P12: 346461 | Q12: 347500 | R12: 341689 | S12: 343795 | T12: 357049 | U12: 351997 | V12: 322684 | W12: 351200 | X12: 357596 | Y12: 354624
... A60: 60 | B60: 272230 | C60: 291719 | D60: 293201 | E60: 296033 | F60: 276260 | G60: 290014 | H60: 288734 | I60: 293201 | J60: 282299 | K60: 290302 | L60: 292324 | M60: 293201 | N60: 282217 | O60: 287098 | P60: 294634 | Q60: 289651 | R60: 284238 | S60: 291209 | T60: 294158 | U60: 289828 | V60: 279271 | W60: 290061 | X60: 285334 | Y60: 283677

Sheet Planilha10
A1: 1 | B1: 301419 | C1: 309626 | D1: 319396 | E1: 324263 | F1: 298600 | G1: 313388 | H1: 311662 | I1: 315852 | J1: 291687 | K1: 316944 | L1: 303689 | M1: 318184 | N1: 292725 | O1: 309922 | P1: 303713 | Q1: 312987 | R1: 283372 | S1: 311372 | T1: 314737 | U1: 306259 | V1: 291372 | W1: 300218 | X1: 311043 | Y1: 312440
A2: 2 | B2: 287627 | C2: 319958 | D2: 317550 | E2: 320278 | F2: 300695 | G2: 309050 | H2: 306719 | I2: 321092 | J2: 302872 | K2: 320427 | L2: 320209 | M2: 320831 | N2: 297333 | O2: 316127 | P2: 324999 | Q2: 315542 | R2: 291072 | S2: 317401 | T2: 314324 | U2: 323281 | V2: 294990 | W2: 310299 | X2: 304283 | Y2: 313853
A3: 3 | B3: 328933 | C3: 340878 | D3: 344560 | E3: 350844 | F3: 309276 | G3: 342001 | H3: 337606 | I3: 351741 | J3: 326373 | K3: 347785 | L3: 346801 | M3: 338887 | N3: 317424 | O3: 344025 | P3: 338195 | Q3: 347877 | R3: 320973 | S3: 346261 | T3: 348668 | U3: 346376 | V3: 315676 | W3: 340276 | X3: 341671 | Y3: 350680
A4: 4 | B4: 322266 | C4: 351027 | D4: 340618 | E4: 358823 | F4: 325906 | G4: 343958 | H4: 344736 | I4: 332826 | J4: 323176 | K4: 344341 | L4: 343802 | M4: 342385 | N4: 323808 | O4: 335369 | P4: 332572 | Q4: 347139 | R4: 325120 | S4: 351966 | T4: 346644 | U4: 340436 | V4: 320241 | W4: 340735 | X4: 344350 | Y4: 352912
A5: 5 | B5: 303906 | C5: 307100 | D5: 313894 | E5: 315410 | F5: 297938 | G5: 320148 | H5: 311186 | I5: 312259 | J5: 287853 | K5: 308853 | L5: 310890 | M5: 316932 | N5: 288348 | O5: 293271 | P5: 315680 | Q5: 312122 | R5: 301785 | S5: 313928 | T5: 316281 | U5: 310427 | V5: 280276 | W5: 309380 | X5: 311163 | Y5: 304254
A6: 6 | B6: 346093 | C6: 366700 | D6: 370088 | E6: 378281 | F6: 338194 | G6: 362060 | H6: 373134 | I6: 377436 | J6: 346238 | K6: 371335 | L6: 374278 | M6: 379890 | N6: 339563 | O6: 366588 | P6: 364327 | Q6: 366836 | R6: 340499 | S6: 374453 | T6: 372784 | U6: 366156 | V6: 340994 | W6: 361439 | X6: 366888 | Y6: 372198
A7: 7 | B7: 359676 | C7: 375093 | D7: 378449 | E7: 377747 | F7: 347559 | G7: 374126 | H7: 373595 | I7: 381058 | J7: 346153 | K7: 372923 | L7: 386768 | M7: 377520 | N7: 340859 | O7: 364829 | P7: 382893 | Q7: 362600 | R7: 348483 | S7: 377252 | T7: 387929 | U7: 372708 | V7: 350643 | W7: 366599 | X7: 370805 | Y7: 371921
A8: 8 | B8: 293926 | C8: 315564 | D8: 320340 | E8: 315260 | F8: 300916 | G8: 316614 | H8: 313788 | I8: 313009 | J8: 295855 | K8: 306525 | L8: 319936 | M8: 317956 | N8: 283008 | O8: 311128 | P8: 304043 | Q8: 313644 | R8: 291745 | S8: 318085 | T8: 304089 | U8: 318713 | V8: 290992 | W8: 314413 | X8: 312539 | Y8: 315361
A9: 9 | B9: 335135 | C9: 357864 | D9: 359202 | E9: 345058 | F9: 327176 | G9: 355490 | H9: 359782 | I9: 358096 | J9: 330669 | K9: 359115 | L9: 360656 | M9: 351576 | N9: 330708 | O9: 350236 | P9: 357143 | Q9: 353572 | R9: 335421 | S9: 347811 | T9: 361195 | U9: 365242 | V9: 326224 | W9: 356544 | X9: 346514 | Y9: 353018
A10: 10 | B10: 325981 | C10: 362333 | D10: 357550 | E10: 359258 | F10: 318859 | G10: 350854 | H10: 351323 | I10: 352095 | J10: 327291 | K10: 343906 | L10: 354689 | M10: 349984 | N10: 327060 | O10: 332160 | P10: 346668 | Q10: 345340 | R10: 326611 | S10: 347619 | T10: 354272 | U10: 347843 | V10: 318100 | W10: 343478 | X10: 350993 | Y10: 344184
A11: 11 | B11: 378117 | C11: 398816 | D11: 405819 | E11: 398256 | F11: 359791 | G11: 389636 | H11: 400891 | I11: 384163 | J11: 372630 | K11: 394103 | L11: 403284 | M11: 392676 | N11: 366740 | O11: 385153 | P11: 398851 | Q11: 389953 | R11: 362392 | S11: 397225 | T11: 395602 | U11: 394570 | V11: 365645 | W11: 377671 | X11: 386878 | Y11: 396558
A12: 12 | B12: 331783 | C12: 352276 | D12: 351859 | E12: 369163 | F12: 328091 | G12: 351135 | H12: 358808 | I12: 349965 | J12: 337349 | K12: 348113 | L12: 359537 | M12: 355840 | N12: 332570 | O12: 350999 | P12: 349022 | Q12: 349354 | R12: 333932 | S12: 355076 | T12: 356313 | U12: 360674 | V12: 331997 | W12: 351825 | X12: 347654 | Y12: 360082
... A60: 60 | B60: 294972 | C60: 291883 | D60: 284970 | E60: 287968 | F60: 277325 | G60: 284382 | H60: 292530 | I60: 290416 | J60: 283005 | K60: 288448 | L60: 294510 | M60: 284480 | N60: 268425 | O60: 281176 | P60: 290446 | Q60: 292348 | R60: 276696 | S60: 281054 | T60: 293205 | U60: 294745 | V60: 282626 | W60: 283823 | X60: 276143 | Y60: 291104

Sheet Planilha11
B1: =(Planilha1!B1+Planilha2!B1+Planilha3!B1+Planilha4!B1+Planilha5!B1+Planilha6!B1+Planilha7!B1+Planilha8!B1+Planilha9!B1+Planilha10!B1)/10 -> 297172.1 | C1: =(Planilha1!C1+Planilha2!C1+Planilha3!C1+Planilha4!C1+Planilha5!C1+Planilha6!C1+Planilha7!C1+Planilha8!C1+Planilha9!C1+Planilha10!C1)/10 -> 314766.2 | D1: =(Planilha1!D1+Planilha2!D1+Planilha3!D1+Planilha4!D1+Planilha5!D1+Planilha6!D1+Planilha7!D1+Planilha8!D1+Planilha9!D1+Planilha10!D1)/10 -> 317329.7 | E1: =(Planilha1!E1+Planilha2!E1+Planilha3!E1+Planilha4!E1+Planilha5!E1+Planilha6!E1+Planilha7!E1+Planilha8!E1+Planilha9!E1+Planilha10!E1)/10 -> 320061.3 | F1: =(Planilha1!F1+Planilha2!F1+Planilha3!F1+Planilha4!F1+Planilha5!F1+Planilha6!F1+Planilha7!F1+Planilha8!F1+Planilha9!F1+Planilha10!F1)/10 -> 293355 | G1: =(Planilha1!G1+Planilha2!G1+Planilha3!G1+Planilha4!G1+Planilha5!G1+Planilha6!G1+Planilha7!G1+Planilha8!G1+Planilha9!G1+Planilha10!G1)/10 -> 313669.5 | H1: =(Planilha1!H1+Planilha2!H1+Planilha3!H1+Planilha4!H1+Planilha5!H1+Planilha6!H1+Planilha7!H1+Planilha8!H1+Planilha9!H1+Planilha10!H1)/10 -> 316210.9 | I1: =(Planilha1!I1+Planilha2!I1+Planilha3!I1+Planilha4!I1+Planilha5!I1+Planilha6!I1+Planilha7!I1+Planilha8!I1+Planilha9!I1+Planilha10!I1)/10 -> 315076.2 | ... Y1: =(Planilha1!Y1+Planilha2!Y1+Planilha3!Y1+Planilha4!Y1+Planilha5!Y1+Planilha6!Y1+Planilha7!Y1+Planilha8!Y1+Planilha9!Y1+Planilha10!Y1)/10 -> 308709.2
B2: =(Planilha1!B2+Planilha2!B2+Planilha3!B2+Planilha4!B2+Planilha5!B2+Planilha6!B2+Planilha7!B2+Planilha8!B2+Planilha9!B2+Planilha10!B2)/10 -> 299658.3 | C2: =(Planilha1!C2+Planilha2!C2+Planilha3!C2+Planilha4!C2+Planilha5!C2+Planilha6!C2+Planilha7!C2+Planilha8!C2+Planilha9!C2+Planilha10!C2)/10 -> 319310.1 | D2: =(Planilha1!D2+Planilha2!D2+Planilha3!D2+Planilha4!D2+Planilha5!D2+Planilha6!D2+Planilha7!D2+Planilha8!D2+Planilha9!D2+Planilha10!D2)/10 -> 318580.6 | E2: =(Planilha1!E2+Planilha2!E2+Planilha3!E2+Planilha4!E2+Planilha5!E2+Planilha6!E2+Planilha7!E2+Planilha8!E2+Planilha9!E2+Planilha10!E2)/10 -> 322235.5 | F2: =(Planilha1!F2+Planilha2!F2+Planilha3!F2+Planilha4!F2+Planilha5!F2+Planilha6!F2+Planilha7!F2+Planilha8!F2+Planilha9!F2+Planilha10!F2)/10 -> 296087.5 | G2: =(Planilha1!G2+Planilha2!G2+Planilha3!G2+Planilha4!G2+Planilha5!G2+Planilha6!G2+Planilha7!G2+Planilha8!G2+Planilha9!G2+Planilha10!G2)/10 -> 313938.5 | H2: =(Planilha1!H2+Planilha2!H2+Planilha3!H2+Planilha4!H2+Planilha5!H2+Planilha6!H2+Planilha7!H2+Planilha8!H2+Planilha9!H2+Planilha10!H2)/10 -> 316518.7 | I2: =(Planilha1!I2+Planilha2!I2+Planilha3!I2+Planilha4!I2+Planilha5!I2+Planilha6!I2+Planilha7!I2+Planilha8!I2+Planilha9!I2+Planilha10!I2)/10 -> 319882.9 | ... Y2: =(Planilha1!Y2+Planilha2!Y2+Planilha3!Y2+Planilha4!Y2+Planilha5!Y2+Planilha6!Y2+Planilha7!Y2+Planilha8!Y2+Planilha9!Y2+Planilha10!Y2)/10 -> 314732.7
B3: =(Planilha1!B3+Planilha2!B3+Planilha3!B3+Planilha4!B3+Planilha5!B3+Planilha6!B3+Planilha7!B3+Planilha8!B3+Planilha9!B3+Planilha10!B3)/10 -> 322706.5 | C3: =(Planilha1!C3+Planilha2!C3+Planilha3!C3+Planilha4!C3+Planilha5!C3+Planilha6!C3+Planilha7!C3+Planilha8!C3+Planilha9!C3+Planilha10!C3)/10 -> 345978 | D3: =(Planilha1!D3+Planilha2!D3+Planilha3!D3+Planilha4!D3+Planilha5!D3+Planilha6!D3+Planilha7!D3+Planilha8!D3+Planilha9!D3+Planilha10!D3)/10 -> 352110.6 | E3: =(Planilha1!E3+Planilha2!E3+Planilha3!E3+Planilha4!E3+Planilha5!E3+Planilha6!E3+Planilha7!E3+Planilha8!E3+Planilha9!E3+Planilha10!E3)/10 -> 350741.2 | F3: =(Planilha1!F3+Planilha2!F3+Planilha3!F3+Planilha4!F3+Planilha5!F3+Planilha6!F3+Planilha7!F3+Planilha8!F3+Planilha9!F3+Planilha10!F3)/10 -> 315238.3 | G3: =(Planilha1!G3+Planilha2!G3+Planilha3!G3+Planilha4!G3+Planilha5!G3+Planilha6!G3+Planilha7!G3+Planilha8!G3+Planilha9!G3+Planilha10!G3)/10 -> 344933.8 | H3: =(Planilha1!H3+Planilha2!H3+Planilha3!H3+Planilha4!H3+Planilha5!H3+Planilha6!H3+Planilha7!H3+Planilha8!H3+Planilha9!H3+Planilha10!H3)/10 -> 344541.3 | I3: =(Planilha1!I3+Planilha2!I3+Planilha3!I3+Planilha4!I3+Planilha5!I3+Planilha6!I3+Planilha7!I3+Planilha8!I3+Planilha9!I3+Planilha10!I3)/10 -> 348184.9 | ... Y3: =(Planilha1!Y3+Planilha2!Y3+Planilha3!Y3+Planilha4!Y3+Planilha5!Y3+Planilha6!Y3+Planilha7!Y3+Planilha8!Y3+Planilha9!Y3+Planilha10!Y3)/10 -> 343003.5
B4: =(Planilha1!B4+Planilha2!B4+Planilha3!B4+Planilha4!B4+Planilha5!B4+Planilha6!B4+Planilha7!B4+Planilha8!B4+Planilha9!B4+Planilha10!B4)/10 -> 326541.9 | C4: =(Planilha1!C4+Planilha2!C4+Planilha3!C4+Planilha4!C4+Planilha5!C4+Planilha6!C4+Planilha7!C4+Planilha8!C4+Planilha9!C4+Planilha10!C4)/10 -> 350891.3 | D4: =(Planilha1!D4+Planilha2!D4+Planilha3!D4+Planilha4!D4+Planilha5!D4+Planilha6!D4+Planilha7!D4+Planilha8!D4+Planilha9!D4+Planilha10!D4)/10 -> 350234.7 | E4: =(Planilha1!E4+Planilha2!E4+Planilha3!E4+Planilha4!E4+Planilha5!E4+Planilha6!E4+Planilha7!E4+Planilha8!E4+Planilha9!E4+Planilha10!E4)/10 -> 349193 | F4: =(Planilha1!F4+Planilha2!F4+Planilha3!F4+Planilha4!F4+Planilha5!F4+Planilha6!F4+Planilha7!F4+Planilha8!F4+Planilha9!F4+Planilha10!F4)/10 -> 324743.3 | G4: =(Planilha1!G4+Planilha2!G4+Planilha3!G4+Planilha4!G4+Planilha5!G4+Planilha6!G4+Planilha7!G4+Planilha8!G4+Planilha9!G4+Planilha10!G4)/10 -> 345215 | H4: =(Planilha1!H4+Planilha2!H4+Planilha3!H4+Planilha4!H4+Planilha5!H4+Planilha6!H4+Planilha7!H4+Planilha8!H4+Planilha9!H4+Planilha10!H4)/10 -> 346428.5 | I4: =(Planilha1!I4+Planilha2!I4+Planilha3!I4+Planilha4!I4+Planilha5!I4+Planilha6!I4+Planilha7!I4+Planilha8!I4+Planilha9!I4+Planilha10!I4)/10 -> 346371.9 | ... Y4: =(Planilha1!Y4+Planilha2!Y4+Planilha3!Y4+Planilha4!Y4+Planilha5!Y4+Planilha6!Y4+Planilha7!Y4+Planilha8!Y4+Planilha9!Y4+Planilha10!Y4)/10 -> 341267
B5: =(Planilha1!B5+Planilha2!B5+Planilha3!B5+Planilha4!B5+Planilha5!B5+Planilha6!B5+Planilha7!B5+Planilha8!B5+Planilha9!B5+Planilha10!B5)/10 -> 297357.6 | C5: =(Planilha1!C5+Planilha2!C5+Planilha3!C5+Planilha4!C5+Planilha5!C5+Planilha6!C5+Planilha7!C5+Planilha8!C5+Planilha9!C5+Planilha10!C5)/10 -> 317749.1 | D5: =(Planilha1!D5+Planilha2!D5+Planilha3!D5+Planilha4!D5+Planilha5!D5+Planilha6!D5+Planilha7!D5+Planilha8!D5+Planilha9!D5+Planilha10!D5)/10 -> 314135.7 | E5: =(Planilha1!E5+Planilha2!E5+Planilha3!E5+Planilha4!E5+Planilha5!E5+Planilha6!E5+Planilha7!E5+Planilha8!E5+Planilha9!E5+Planilha10!E5)/10 -> 317775.5 | F5: =(Planilha1!F5+Planilha2!F5+Planilha3!F5+Planilha4!F5+Planilha5!F5+Planilha6!F5+Planilha7!F5+Planilha8!F5+Planilha9!F5+Planilha10!F5)/10 -> 292201.1 | G5: =(Planilha1!G5+Planilha2!G5+Planilha3!G5+Planilha4!G5+Planilha5!G5+Planilha6!G5+Planilha7!G5+Planilha8!G5+Planilha9!G5+Planilha10!G5)/10 -> 313583.1 | H5: =(Planilha1!H5+Planilha2!H5+Planilha3!H5+Planilha4!H5+Planilha5!H5+Planilha6!H5+Planilha7!H5+Planilha8!H5+Planilha9!H5+Planilha10!H5)/10 -> 312874.1 | I5: =(Planilha1!I5+Planilha2!I5+Planilha3!I5+Planilha4!I5+Planilha5!I5+Planilha6!I5+Planilha7!I5+Planilha8!I5+Planilha9!I5+Planilha10!I5)/10 -> 316494.2 | ... Y5: =(Planilha1!Y5+Planilha2!Y5+Planilha3!Y5+Planilha4!Y5+Planilha5!Y5+Planilha6!Y5+Planilha7!Y5+Planilha8!Y5+Planilha9!Y5+Planilha10!Y5)/10 -> 308934.3
B6: =(Planilha1!B6+Planilha2!B6+Planilha3!B6+Planilha4!B6+Planilha5!B6+Planilha6!B6+Planilha7!B6+Planilha8!B6+Planilha9!B6+Planilha10!B6)/10 -> 348037.1 | C6: =(Planilha1!C6+Planilha2!C6+Planilha3!C6+Planilha4!C6+Planilha5!C6+Planilha6!C6+Planilha7!C6+Planilha8!C6+Planilha9!C6+Planilha10!C6)/10 -> 368885.2 | D6: =(Planilha1!D6+Planilha2!D6+Planilha3!D6+Planilha4!D6+Planilha5!D6+Planilha6!D6+Planilha7!D6+Planilha8!D6+Planilha9!D6+Planilha10!D6)/10 -> 369130.9 | E6: =(Planilha1!E6+Planilha2!E6+Planilha3!E6+Planilha4!E6+Planilha5!E6+Planilha6!E6+Planilha7!E6+Planilha8!E6+Planilha9!E6+Planilha10!E6)/10 -> 370023.4 | F6: =(Planilha1!F6+Planilha2!F6+Planilha3!F6+Planilha4!F6+Planilha5!F6+Planilha6!F6+Planilha7!F6+Planilha8!F6+Planilha9!F6+Planilha10!F6)/10 -> 344986.7 | G6: =(Planilha1!G6+Planilha2!G6+Planilha3!G6+Planilha4!G6+Planilha5!G6+Planilha6!G6+Planilha7!G6+Planilha8!G6+Planilha9!G6+Planilha10!G6)/10 -> 364117.4 | H6: =(Planilha1!H6+Planilha2!H6+Planilha3!H6+Planilha4!H6+Planilha5!H6+Planilha6!H6+Planilha7!H6+Planilha8!H6+Planilha9!H6+Planilha10!H6)/10 -> 368472.7 | I6: =(Planilha1!I6+Planilha2!I6+Planilha3!I6+Planilha4!I6+Planilha5!I6+Planilha6!I6+Planilha7!I6+Planilha8!I6+Planilha9!I6+Planilha10!I6)/10 -> 371971.6 | ... Y6: =(Planilha1!Y6+Planilha2!Y6+Planilha3!Y6+Planilha4!Y6+Planilha5!Y6+Planilha6!Y6+Planilha7!Y6+Planilha8!Y6+Planilha9!Y6+Planilha10!Y6)/10 -> 369922.7
B7: =(Planilha1!B7+Planilha2!B7+Planilha3!B7+Planilha4!B7+Planilha5!B7+Planilha6!B7+Planilha7!B7+Planilha8!B7+Planilha9!B7+Planilha10!B7)/10 -> 354808 | C7: =(Planilha1!C7+Planilha2!C7+Planilha3!C7+Planilha4!C7+Planilha5!C7+Planilha6!C7+Planilha7!C7+Planilha8!C7+Planilha9!C7+Planilha10!C7)/10 -> 378926.8 | D7: =(Planilha1!D7+Planilha2!D7+Planilha3!D7+Planilha4!D7+Planilha5!D7+Planilha6!D7+Planilha7!D7+Planilha8!D7+Planilha9!D7+Planilha10!D7)/10 -> 385377.7 | E7: =(Planilha1!E7+Planilha2!E7+Planilha3!E7+Planilha4!E7+Planilha5!E7+Planilha6!E7+Planilha7!E7+Planilha8!E7+Planilha9!E7+Planilha10!E7)/10 -> 382333.7 | F7: =(Planilha1!F7+Planilha2!F7+Planilha3!F7+Planilha4!F7+Planilha5!F7+Planilha6!F7+Planilha7!F7+Planilha8!F7+Planilha9!F7+Planilha10!F7)/10 -> 346972 | G7: =(Planilha1!G7+Planilha2!G7+Planilha3!G7+Planilha4!G7+Planilha5!G7+Planilha6!G7+Planilha7!G7+Planilha8!G7+Planilha9!G7+Planilha10!G7)/10 -> 375683.4 | H7: =(Planilha1!H7+Planilha2!H7+Planilha3!H7+Planilha4!H7+Planilha5!H7+Planilha6!H7+Planilha7!H7+Planilha8!H7+Planilha9!H7+Planilha10!H7)/10 -> 378483.9 | I7: =(Planilha1!I7+Planilha2!I7+Planilha3!I7+Planilha4!I7+Planilha5!I7+Planilha6!I7+Planilha7!I7+Planilha8!I7+Planilha9!I7+Planilha10!I7)/10 -> 374463.3 | ... Y7: =(Planilha1!Y7+Planilha2!Y7+Planilha3!Y7+Planilha4!Y7+Planilha5!Y7+Planilha6!Y7+Planilha7!Y7+Planilha8!Y7+Planilha9!Y7+Planilha10!Y7)/10 -> 374367.1
B8: =(Planilha1!B8+Planilha2!B8+Planilha3!B8+Planilha4!B8+Planilha5!B8+Planilha6!B8+Planilha7!B8+Planilha8!B8+Planilha9!B8+Planilha10!B8)/10 -> 300229.1 | C8: =(Planilha1!C8+Planilha2!C8+Planilha3!C8+Planilha4!C8+Planilha5!C8+Planilha6!C8+Planilha7!C8+Planilha8!C8+Planilha9!C8+Planilha10!C8)/10 -> 318906.3 | D8: =(Planilha1!D8+Planilha2!D8+Planilha3!D8+Planilha4!D8+Planilha5!D8+Planilha6!D8+Planilha7!D8+Planilha8!D8+Planilha9!D8+Planilha10!D8)/10 -> 318456.8 | E8: =(Planilha1!E8+Planilha2!E8+Planilha3!E8+Planilha4!E8+Planilha5!E8+Planilha6!E8+Planilha7!E8+Planilha8!E8+Planilha9!E8+Planilha10!E8)/10 -> 319864.2 | F8: =(Planilha1!F8+Planilha2!F8+Planilha3!F8+Planilha4!F8+Planilha5!F8+Planilha6!F8+Planilha7!F8+Planilha8!F8+Planilha9!F8+Planilha10!F8)/10 -> 289393.2 | G8: =(Planilha1!G8+Planilha2!G8+Planilha3!G8+Planilha4!G8+Planilha5!G8+Planilha6!G8+Planilha7!G8+Planilha8!G8+Planilha9!G8+Planilha10!G8)/10 -> 313446.5 | H8: =(Planilha1!H8+Planilha2!H8+Planilha3!H8+Planilha4!H8+Planilha5!H8+Planilha6!H8+Planilha7!H8+Planilha8!H8+Planilha9!H8+Planilha10!H8)/10 -> 316751.9 | I8: =(Planilha1!I8+Planilha2!I8+Planilha3!I8+Planilha4!I8+Planilha5!I8+Planilha6!I8+Planilha7!I8+Planilha8!I8+Planilha9!I8+Planilha10!I8)/10 -> 316876.7 | ... Y8: =(Planilha1!Y8+Planilha2!Y8+Planilha3!Y8+Planilha4!Y8+Planilha5!Y8+Planilha6!Y8+Planilha7!Y8+Planilha8!Y8+Planilha9!Y8+Planilha10!Y8)/10 -> 307457.2
B9: =(Planilha1!B9+Planilha2!B9+Planilha3!B9+Planilha4!B9+Planilha5!B9+Planilha6!B9+Planilha7!B9+Planilha8!B9+Planilha9!B9+Planilha10!B9)/10 -> 337684.6 | C9: =(Planilha1!C9+Planilha2!C9+Planilha3!C9+Planilha4!C9+Planilha5!C9+Planilha6!C9+Planilha7!C9+Planilha8!C9+Planilha9!C9+Planilha10!C9)/10 -> 357672.2 | D9: =(Planilha1!D9+Planilha2!D9+Planilha3!D9+Planilha4!D9+Planilha5!D9+Planilha6!D9+Planilha7!D9+Planilha8!D9+Planilha9!D9+Planilha10!D9)/10 -> 361136.2 | E9: =(Planilha1!E9+Planilha2!E9+Planilha3!E9+Planilha4!E9+Planilha5!E9+Planilha6!E9+Planilha7!E9+Planilha8!E9+Planilha9!E9+Planilha10!E9)/10 -> 362423.8 | F9: =(Planilha1!F9+Planilha2!F9+Planilha3!F9+Planilha4!F9+Planilha5!F9+Planilha6!F9+Planilha7!F9+Planilha8!F9+Planilha9!F9+Planilha10!F9)/10 -> 333031.7 | G9: =(Planilha1!G9+Planilha2!G9+Planilha3!G9+Planilha4!G9+Planilha5!G9+Planilha6!G9+Planilha7!G9+Planilha8!G9+Planilha9!G9+Planilha10!G9)/10 -> 354257.4 | H9: =(Planilha1!H9+Planilha2!H9+Planilha3!H9+Planilha4!H9+Planilha5!H9+Planilha6!H9+Planilha7!H9+Planilha8!H9+Planilha9!H9+Planilha10!H9)/10 -> 356798 | I9: =(Planilha1!I9+Planilha2!I9+Planilha3!I9+Planilha4!I9+Planilha5!I9+Planilha6!I9+Planilha7!I9+Planilha8!I9+Planilha9!I9+Planilha10!I9)/10 -> 356721.2 | ... Y9: =(Planilha1!Y9+Planilha2!Y9+Planilha3!Y9+Planilha4!Y9+Planilha5!Y9+Planilha6!Y9+Planilha7!Y9+Planilha8!Y9+Planilha9!Y9+Planilha10!Y9)/10 -> 355170.8
B10: =(Planilha1!B10+Planilha2!B10+Planilha3!B10+Planilha4!B10+Planilha5!B10+Planilha6!B10+Planilha7!B10+Planilha8!B10+Planilha9!B10+Planilha10!B10)/10 -> 328540.3 | C10: =(Planilha1!C10+Planilha2!C10+Planilha3!C10+Planilha4!C10+Planilha5!C10+Planilha6!C10+Planilha7!C10+Planilha8!C10+Planilha9!C10+Planilha10!C10)/10 -> 352415.2 | D10: =(Planilha1!D10+Planilha2!D10+Planilha3!D10+Planilha4!D10+Planilha5!D10+Planilha6!D10+Planilha7!D10+Planilha8!D10+Planilha9!D10+Planilha10!D10)/10 -> 354672.8 | E10: =(Planilha1!E10+Planilha2!E10+Planilha3!E10+Planilha4!E10+Planilha5!E10+Planilha6!E10+Planilha7!E10+Planilha8!E10+Planilha9!E10+Planilha10!E10)/10 -> 352030.3 | F10: =(Planilha1!F10+Planilha2!F10+Planilha3!F10+Planilha4!F10+Planilha5!F10+Planilha6!F10+Planilha7!F10+Planilha8!F10+Planilha9!F10+Planilha10!F10)/10 -> 323518 | G10: =(Planilha1!G10+Planilha2!G10+Planilha3!G10+Planilha4!G10+Planilha5!G10+Planilha6!G10+Planilha7!G10+Planilha8!G10+Planilha9!G10+Planilha10!G10)/10 -> 345852.3 | H10: =(Planilha1!H10+Planilha2!H10+Planilha3!H10+Planilha4!H10+Planilha5!H10+Planilha6!H10+Planilha7!H10+Planilha8!H10+Planilha9!H10+Planilha10!H10)/10 -> 350661.6 | I10: =(Planilha1!I10+Planilha2!I10+Planilha3!I10+Planilha4!I10+Planilha5!I10+Planilha6!I10+Planilha7!I10+Planilha8!I10+Planilha9!I10+Planilha10!I10)/10 -> 351560.2 | ... Y10: =(Planilha1!Y10+Planilha2!Y10+Planilha3!Y10+Planilha4!Y10+Planilha5!Y10+Planilha6!Y10+Planilha7!Y10+Planilha8!Y10+Planilha9!Y10+Planilha10!Y10)/10 -> 347536.8
B11: =(Planilha1!B11+Planilha2!B11+Planilha3!B11+Planilha4!B11+Planilha5!B11+Planilha6!B11+Planilha7!B11+Planilha8!B11+Planilha9!B11+Planilha10!B11)/10 -> 364287.1 | C11: =(Planilha1!C11+Planilha2!C11+Planilha3!C11+Planilha4!C11+Planilha5!C11+Planilha6!C11+Planilha7!C11+Planilha8!C11+Planilha9!C11+Planilha10!C11)/10 -> 394533.6 | D11: =(Planilha1!D11+Planilha2!D11+Planilha3!D11+Planilha4!D11+Planilha5!D11+Planilha6!D11+Planilha7!D11+Planilha8!D11+Planilha9!D11+Planilha10!D11)/10 -> 400238.8 | E11: =(Planilha1!E11+Planilha2!E11+Planilha3!E11+Planilha4!E11+Planilha5!E11+Planilha6!E11+Planilha7!E11+Planilha8!E11+Planilha9!E11+Planilha10!E11)/10 -> 399044.8 | F11: =(Planilha1!F11+Planilha2!F11+Planilha3!F11+Planilha4!F11+Planilha5!F11+Planilha6!F11+Planilha7!F11+Planilha8!F11+Planilha9!F11+Planilha10!F11)/10 -> 363778.2 | G11: =(Planilha1!G11+Planilha2!G11+Planilha3!G11+Planilha4!G11+Planilha5!G11+Planilha6!G11+Planilha7!G11+Planilha8!G11+Planilha9!G11+Planilha10!G11)/10 -> 389089.4 | H11: =(Planilha1!H11+Planilha2!H11+Planilha3!H11+Planilha4!H11+Planilha5!H11+Planilha6!H11+Planilha7!H11+Planilha8!H11+Planilha9!H11+Planilha10!H11)/10 -> 394881.7 | I11: =(Planilha1!I11+Planilha2!I11+Planilha3!I11+Planilha4!I11+Planilha5!I11+Planilha6!I11+Planilha7!I11+Planilha8!I11+Planilha9!I11+Planilha10!I11)/10 -> 393655.3 | ... Y11: =(Planilha1!Y11+Planilha2!Y11+Planilha3!Y11+Planilha4!Y11+Planilha5!Y11+Planilha6!Y11+Planilha7!Y11+Planilha8!Y11+Planilha9!Y11+Planilha10!Y11)/10 -> 390743.6
