Workbook

Sheet 1_50J
A1: 40_500_0.2 | B1: 40_800_0.2 | C1: 40_1000_0.2 | D1: 40_500_0.3 | E1: 40_800_0.3 | F1: 40_1000_0.3 | G1: 40_500_0.5 | H1: 40_800_0.5 | I1: 40_1000_0.5 | J1: 50_500_0.2 | K1: 50_800_0.2 | L1: 50_1000_0.2 | M1: 50_500_0.3 | N1: 50_800_0.3 | O1: 50_1000_0.3 | P1: 50_500_0.5 | Q1: 50_800_0.5 | R1: 50_1000_0.5 | S1: 70_500_0.2 | T1: 70_800_0.2 | U1: 70_1000_0.2 | V1: 70_500_0.3 | W1: 70_800_0.3 | X1: 70_1000_0.3 | Y1: 70_500_0.5 | Z1: 70_800_0.5 | AA1: 70_1000_0.5 | AB1: OVER_1 | AC1: OVER_2 | AD1: OVER_3 | AE1: OVER_4 | AF1: OVER_5 | AG1: OVER_6 | AH1: OVER_7 | AI1: OVER_8 | AJ1: OVER_9 | AK1: OVER_10 | AL1: OVER_11 | AM1: OVER_12 | AN1: OVER_13 | AO1: OVER_14 | AP1: OVER_15 | AQ1: OVER_16 | AR1: OVER_17 | AS1: OVER_18 | AT1: OVER_19 | AU1: OVER_20 | AV1: OVER_21 | AW1: OVER_22 | AX1: OVER_23 | AY1: OVER_24 | AZ1: OVER_25 | BA1: OVER_26 | BB1: OVER_27 | BC1: TIME_1 | BD1: TIME_2 | BE1: TIME_3 | BF1: TIME_4 | BG1: TIME_5 | BH1: TIME_6 | BI1: TIME_7 | BJ1: TIME_8 | BK1: TIME_9 | BL1: TIME_10 | BM1: TIME_11 | BN1: TIME_12 | BO1: TIME_13 | BP1: TIME_14 | BQ1: TIME_15 | BR1: TIME_16 | BS1: TIME_17 | BT1: TIME_18 | BU1: TIME_19 | BV1: TIME_20 | BW1: TIME_21 | BX1: TIME_22 | BY1: TIME_23 | BZ1: TIME_24 | CA1: TIME_25 | CB1: TIME_26 | CC1: TIME_27
A2: 323282 | B2: 316952 | C2: 328928 | D2: 321786 | E2: 333387 | F2: 316602 | G2: 334567 | H2: 318923 | I2: 326988 | J2: 333808 | K2: 371988 | L2: 336519 | M2: 336537 | N2: 333994 | O2: 322604 | P2: 313733 | Q2: 333697 | R2: 307310 | S2: 315224 | T2: 313271 | U2: 314792 | V2: 351306 | W2: 322938 | X2: 321158 | Y2: 326939 | Z2: 314428 | AA2: 314368 | AB2: 0 | AC2: 0 | AD2: 0 | AE2: 0 | AF2: 0 | AG2: 0 | AH2: 0 | AI2: 0 | AJ2: 0 | AK2: 0 | AL2: 13 | AM2: 0 | AN2: 0 | AO2: 0 | AP2: 0 | AQ2: 0 | AR2: 0 | AS2: 0 | AT2: 0 | AU2: 0 | AV2: 0 | AW2: 31 | AX2: 0 | AY2: 0 | AZ2: 0 | BA2: 0 | BB2: 0 | BC2: 0 | BD2: 0 | BE2: 1 | BF2: 0 | BG2: 1 | BH2: 0 | BI2: 1 | BJ2: 0 | BK2: 1 | BL2: 0 | BM2: 1 | BN2: 0 | BO2: 1 | BP2: 0 | BQ2: 1 | BR2: 0 | BS2: 1 | BT2: 1 | BU2: 0 | BV2: 1 | BW2: 1 | BX2: 0 | BY2: 1 | BZ2: 1 | CA2: 1 | CB2: 0 | CC2: 2
A3: 328196 | B3: 322148 | C3: 336634 | D3: 312781 | E3: 343476 | F3: 316942 | G3: 319421 | H3: 324218 | I3: 306254 | J3: 359104 | K3: 317862 | L3: 322044 | M3: 334607 | N3: 326470 | O3: 387778 | P3: 314701 | Q3: 333646 | R3: 363637 | S3: 335702 | T3: 299899 | U3: 337266 | V3: 334856 | W3: 322578 | X3: 317492 | Y3: 323630 | Z3: 295155 | AA3: 298900 | AB3: 11 | AC3: 0 | AD3: 0 | AE3: 0 | AF3: 6 | AG3: 0 | AH3: 0 | AI3: 0 | AJ3: 0 | AK3: 1 | AL3: 0 | AM3: 0 | AN3: 0 | AO3: 1 | AP3: 57 | AQ3: 0 | AR3: 0 | AS3: 50 | AT3: 0 | AU3: 0 | AV3: 0 | AW3: 0 | AX3: 0 | AY3: 0 | AZ3: 0 | BA3: 0 | BB3: 0 | BC3: 0 | BD3: 0 | BE3: 1 | BF3: 0 | BG3: 1 | BH3: 0 | BI3: 0 | BJ3: 1 | BK3: 1 | BL3: 0 | BM3: 0 | BN3: 1 | BO3: 0 | BP3: 1 | BQ3: 1 | BR3: 0 | BS3: 1 | BT3: 1 | BU3: 0 | BV3: 1 | BW3: 1 | BX3: 0 | BY3: 1 | BZ3: 1 | CA3: 1 | CB3: 0 | CC3: 2
A4: 374018 | B4: 345454 | C4: 335814 | D4: 350573 | E4: 335030 | F4: 350866 | G4: 307802 | H4: 354425 | I4: 325619 | J4: 339467 | K4: 380134 | L4: 348722 | M4: 340837 | N4: 361393 | O4: 343487 | P4: 411425 | Q4: 418222 | R4: 329685 | S4: 375039 | T4: 341142 | U4: 322272 | V4: 361074 | W4: 351664 | X4: 358384 | Y4: 341738 | Z4: 441481 | AA4: 364948 | AB4: 0 | AC4: 0 | AD4: 0 | AE4: 0 | AF4: 0 | AG4: 0 | AH4: 0 | AI4: 0 | AJ4: 0 | AK4: 0 | AL4: 0 | AM4: 0 | AN4: 0 | AO4: 0 | AP4: 0 | AQ4: 56 | AR4: 69 | AS4: 0 | AT4: 25 | AU4: 0 | AV4: 0 | AW4: 0 | AX4: 0 | AY4: 0 | AZ4: 0 | BA4: 92 | BB4: 25 | BC4: 0 | BD4: 0 | BE4: 1 | BF4: 0 | BG4: 0 | BH4: 1 | BI4: 0 | BJ4: 1 | BK4: 0 | BL4: 1 | BM4: 0 | BN4: 1 | BO4: 0 | BP4: 1 | BQ4: 1 | BR4: 0 | BS4: 1 | BT4: 0 | BU4: 1 | BV4: 1 | BW4: 1 | BX4: 0 | BY4: 1 | BZ4: 1 | CA4: 0 | CB4: 2 | CC4: 1
A5: 413696 | B5: 373944 | C5: 348558 | D5: 376658 | E5: 369338 | F5: 363721 | G5: 357354 | H5: 352257 | I5: 339495 | J5: 356170 | K5: 479722 | L5: 373721 | M5: 356236 | N5: 342143 | O5: 350725 | P5: 334684 | Q5: 338054 | R5: 350166 | S5: 339846 | T5: 353942 | U5: 358031 | V5: 375291 | W5: 339016 | X5: 357740 | Y5: 351029 | Z5: 361780 | AA5: 338894 | AB5: 31 | AC5: 30 | AD5: 0 | AE5: 0 | AF5: 0 | AG5: 0 | AH5: 0 | AI5: 0 | AJ5: 0 | AK5: 0 | AL5: 129 | AM5: 0 | AN5: 0 | AO5: 0 | AP5: 0 | AQ5: 0 | AR5: 0 | AS5: 0 | AT5: 6 | AU5: 17 | AV5: 0 | AW5: 0 | AX5: 0 | AY5: 0 | AZ5: 0 | BA5: 0 | BB5: 0 | BC5: 0 | BD5: 1 | BE5: 0 | BF5: 0 | BG5: 1 | BH5: 0 | BI5: 1 | BJ5: 0 | BK5: 1 | BL5: 0 | BM5: 1 | BN5: 0 | BO5: 1 | BP5: 0 | BQ5: 1 | BR5: 0 | BS5: 1 | BT5: 1 | BU5: 0 | BV5: 1 | BW5: 1 | BX5: 1 | BY5: 0 | BZ5: 1 | CA5: 1 | CB5: 1 | CC5: 1
A6: 338559 | B6: 303590 | C6: 403299 | D6: 342818 | E6: 317418 | F6: 328295 | G6: 339591 | H6: 321941 | I6: 320073 | J6: 322576 | K6: 328651 | L6: 325140 | M6: 351699 | N6: 317650 | O6: 308140 | P6: 320718 | Q6: 301009 | R6: 316607 | S6: 348861 | T6: 338601 | U6: 326626 | V6: 307277 | W6: 329203 | X6: 318469 | Y6: 300587 | Z6: 357779 | AA6: 324034 | AB6: 0 | AC6: 0 | AD6: 83 | AE6: 18 | AF6: 0 | AG6: 12 | AH6: 0 | AI6: 0 | AJ6: 0 | AK6: 4 | AL6: 0 | AM6: 0 | AN6: 0 | AO6: 0 | AP6: 0 | AQ6: 0 | AR6: 0 | AS6: 0 | AT6: 22 | AU6: 0 | AV6: 0 | AW6: 0 | AX6: 0 | AY6: 0 | AZ6: 0 | BA6: 42 | BB6: 2 | BC6: 0 | BD6: 0 | BE6: 1 | BF6: 0 | BG6: 1 | BH6: 1 | BI6: 0 | BJ6: 0 | BK6: 1 | BL6: 0 | BM6: 1 | BN6: 1 | BO6: 0 | BP6: 0 | BQ6: 1 | BR6: 1 | BS6: 0 | BT6: 1 | BU6: 0 | BV6: 1 | BW6: 1 | BX6: 1 | BY6: 0 | BZ6: 1 | CA6: 1 | CB6: 1 | CC6: 1
A7: 457408 | B7: 394170 | C7: 374064 | D7: 399686 | E7: 361523 | F7: 381836 | G7: 378400 | H7: 382778 | I7: 362704 | J7: 395261 | K7: 370746 | L7: 371233 | M7: 354300 | N7: 389632 | O7: 349672 | P7: 418713 | Q7: 359307 | R7: 358940 | S7: 377713 | T7: 389839 | U7: 376268 | V7: 368854 | W7: 368737 | X7: 373689 | Y7: 355299 | Z7: 365342 | AA7: 399425 | AB7: 50 | AC7: 0 | AD7: 0 | AE7: 0 | AF7: 0 | AG7: 0 | AH7: 0 | AI7: 0 | AJ7: 0 | AK7: 0 | AL7: 0 | AM7: 0 | AN7: 0 | AO7: 0 | AP7: 0 | AQ7: 36 | AR7: 0 | AS7: 0 | AT7: 0 | AU7: 0 | AV7: 0 | AW7: 0 | AX7: 0 | AY7: 0 | AZ7: 0 | BA7: 0 | BB7: 46 | BC7: 0 | BD7: 1 | BE7: 0 | BF7: 1 | BG7: 0 | BH7: 1 | BI7: 0 | BJ7: 0 | BK7: 1 | BL7: 0 | BM7: 1 | BN7: 1 | BO7: 0 | BP7: 0 | BQ7: 1 | BR7: 1 | BS7: 0 | BT7: 1 | BU7: 0 | BV7: 1 | BW7: 1 | BX7: 1 | BY7: 0 | BZ7: 1 | CA7: 1 | CB7: 1 | CC7: 1
A8: 383138 | B8: 394711 | C8: 401105 | D8: 392605 | E8: 383075 | F8: 387531 | G8: 378141 | H8: 392238 | I8: 396529 | J8: 384882 | K8: 407512 | L8: 384766 | M8: 389184 | N8: 402838 | O8: 389800 | P8: 400443 | Q8: 389759 | R8: 370259 | S8: 420676 | T8: 419551 | U8: 426133 | V8: 412418 | W8: 388737 | X8: 387254 | Y8: 367655 | Z8: 363350 | AA8: 389676 | AB8: 0 | AC8: 0 | AD8: 0 | AE8: 0 | AF8: 0 | AG8: 0 | AH8: 0 | AI8: 0 | AJ8: 0 | AK8: 0 | AL8: 0 | AM8: 0 | AN8: 0 | AO8: 0 | AP8: 0 | AQ8: 0 | AR8: 0 | AS8: 0 | AT8: 7 | AU8: 0 | AV8: 0 | AW8: 0 | AX8: 0 | AY8: 0 | AZ8: 0 | BA8: 0 | BB8: 0 | BC8: 0 | BD8: 1 | BE8: 0 | BF8: 0 | BG8: 1 | BH8: 0 | BI8: 1 | BJ8: 0 | BK8: 1 | BL8: 0 | BM8: 1 | BN8: 0 | BO8: 1 | BP8: 0 | BQ8: 1 | BR8: 0 | BS8: 1 | BT8: 1 | BU8: 0 | BV8: 1 | BW8: 1 | BX8: 0 | BY8: 1 | BZ8: 1 | CA8: 1 | CB8: 1 | CC8: 1
A9: 312069 | B9: 318162 | C9: 348387 | D9: 320907 | E9: 320315 | F9: 343429 | G9: 397213 | H9: 304333 | I9: 391300 | J9: 326748 | K9: 326956 | L9: 333055 | M9: 316031 | N9: 320488 | O9: 320450 | P9: 327819 | Q9: 319276 | R9: 403759 | S9: 325881 | T9: 336570 | U9: 304132 | V9: 360065 | W9: 336728 | X9: 327822 | Y9: 298207 | Z9: 309414 | AA9: 315299 | AB9: 0 | AC9: 0 | AD9: 0 | AE9: 0 | AF9: 0 | AG9: 11 | AH9: 75 | AI9: 0 | AJ9: 58 | AK9: 0 | AL9: 0 | AM9: 0 | AN9: 0 | AO9: 0 | AP9: 0 | AQ9: 0 | AR9: 0 | AS9: 86 | AT9: 0 | AU9: 40 | AV9: 0 | AW9: 36 | AX9: 0 | AY9: 0 | AZ9: 0 | BA9: 0 | BB9: 0 | BC9: 0 | BD9: 0 | BE9: 1 | BF9: 0 | BG9: 1 | BH9: 0 | BI9: 1 | BJ9: 0 | BK9: 1 | BL9: 0 | BM9: 1 | BN9: 0 | BO9: 1 | BP9: 0 | BQ9: 1 | BR9: 0 | BS9: 1 | BT9: 1 | BU9: 0 | BV9: 1 | BW9: 1 | BX9: 1 | BY9: 0 | BZ9: 1 | CA9: 1 | CB9: 1 | CC9: 1
A10: 406996 | B10: 365990 | C10: 365290 | D10: 373484 | E10: 374612 | F10: 359990 | G10: 352998 | H10: 376624 | I10: 354065 | J10: 432573 | K10: 383838 | L10: 386749 | M10: 367231 | N10: 372204 | O10: 342038 | P10: 345178 | Q10: 355724 | R10: 360248 | S10: 360600 | T10: 365510 | U10: 373045 | V10: 364981 | W10: 386062 | X10: 368585 | Y10: 353834 | Z10: 344963 | AA10: 361982 | AB10: 37 | AC10: 0 | AD10: 0 | AE10: 0 | AF10: 0 | AG10: 0 | AH10: 0 | AI10: 56 | AJ10: 0 | AK10: 64 | AL10: 0 | AM10: 0 | AN10: 0 | AO10: 0 | AP10: 0 | AQ10: 0 | AR10: 0 | AS10: 0 | AT10: 0 | AU10: 0 | AV10: 0 | AW10: 0 | AX10: 0 | AY10: 0 | AZ10: 0 | BA10: 0 | BB10: 0 | BC10: 0 | BD10: 0 | BE10: 1 | BF10: 0 | BG10: 1 | BH10: 0 | BI10: 1 | BJ10: 0 | BK10: 1 | BL10: 0 | BM10: 1 | BN10: 0 | BO10: 1 | BP10: 0 | BQ10: 1 | BR10: 0 | BS10: 1 | BT10: 1 | BU10: 0 | BV10: 1 | BW10: 1 | BX10: 0 | BY10: 1 | BZ10: 1 | CA10: 1 | CB10: 1 | CC10: 1
A11: 373120 | B11: 345891 | C11: 365852 | D11: 377083 | E11: 379991 | F11: 384397 | G11: 358430 | H11: 373381 | I11: 341521 | J11: 374395 | K11: 373710 | L11: 372944 | M11: 373340 | N11: 346719 | O11: 339817 | P11: 336670 | Q11: 352176 | R11: 370020 | S11: 365632 | T11: 358394 | U11: 353481 | V11: 376162 | W11: 347232 | X11: 345341 | Y11: 361925 | Z11: 362386 | AA11: 360611 | AB11: 0 | AC11: 0 | AD11: 0 | AE11: 0 | AF11: 0 | AG11: 0 | AH11: 0 | AI11: 0 | AJ11: 0 | AK11: 0 | AL11: 0 | AM11: 0 | AN11: 0 | AO11: 0 | AP11: 0 | AQ11: 0 | AR11: 0 | AS11: 0 | AT11: 0 | AU11: 0 | AV11: 0 | AW11: 7 | AX11: 0 | AY11: 0 | AZ11: 0 | BA11: 0 | BB11: 0 | BC11: 0 | BD11: 0 | BE11: 1 | BF11: 0 | BG11: 1 | BH11: 0 | BI11: 0 | BJ11: 1 | BK11: 0 | BL11: 1 | BM11: 0 | BN11: 1 | BO11: 0 | BP11: 1 | BQ11: 1 | BR11: 0 | BS11: 1 | BT11: 0 | BU11: 1 | BV11: 1 | BW11: 0 | BX11: 1 | BY11: 1 | BZ11: 1 | CA11: 0 | CB11: 1 | CC11: 1
A12: 397458 | B12: 430060 | C12: 432076 | D12: 401354 | E12: 417616 | F12: 406221 | G12: 409222 | H12: 398235 | I12: 441786 | J12: 404728 | K12: 401141 | L12: 390318 | M12: 406398 | N12: 417908 | O12: 410255 | P12: 380489 | Q12: 414914 | R12: 420756 | S12: 394891 | T12: 413598 | U12: 383296 | V12: 416111 | W12: 413799 | X12: 416136 | Y12: 417777 | Z12: 410469 | AA12: 407025 | AB12: 0 | AC12: 0 | AD12: 0 | AE12: 0 | AF12: 0 | AG12: 0 | AH12: 0 | AI12: 0 | AJ12: 0 | AK12: 0 | AL12: 0 | AM12: 0 | AN12: 0 | AO12: 0 | AP12: 0 | AQ12: 0 | AR12: 0 | AS12: 0 | AT12: 0 | AU12: 0 | AV12: 0 | AW12: 0 | AX12: 0 | AY12: 0 | AZ12: 0 | BA12: 0 | BB12: 0 | BC12: 0 | BD12: 1 | BE12: 0 | BF12: 1 | BG12: 0 | BH12: 1 | BI12: 0 | BJ12: 0 | BK12: 1 | BL12: 0 | BM12: 1 | BN12: 1 | BO12: 0 | BP12: 0 | BQ12: 1 | BR12: 1 | BS12: 0 | BT12: 1 | BU12: 0 | BV12: 1 | BW12: 1 | BX12: 0 | BY12: 1 | BZ12: 1 | CA12: 1 | CB12: 1 | CC12: 1
A13: 367005 | B13: 388478 | C13: 428204 | D13: 407925 | E13: 356846 | F13: 364026 | G13: 350194 | H13: 342390 | I13: 355440 | J13: 370010 | K13: 352030 | L13: 358832 | M13: 364965 | N13: 341908 | O13: 342118 | P13: 379484 | Q13: 356273 | R13: 336107 | S13: 349737 | T13: 362710 | U13: 350520 | V13: 370144 | W13: 332112 | X13: 373906 | Y13: 368351 | Z13: 355136 | AA13: 337456 | AB13: 0 | AC13: 0 | AD13: 35 | AE13: 19 | AF13: 0 | AG13: 0 | AH13: 1 | AI13: 16 | AJ13: 0 | AK13: 0 | AL13: 0 | AM13: 0 | AN13: 0 | AO13: 0 | AP13: 0 | AQ13: 0 | AR13: 0 | AS13: 0 | AT13: 0 | AU13: 0 | AV13: 0 | AW13: 0 | AX13: 0 | AY13: 16 | AZ13: 0 | BA13: 0 | BB13: 0 | BC13: 0 | BD13: 0 | BE13: 1 | BF13: 1 | BG13: 0 | BH13: 1 | BI13: 0 | BJ13: 1 | BK13: 0 | BL13: 0 | BM13: 1 | BN13: 1 | BO13: 0 | BP13: 1 | BQ13: 0 | BR13: 1 | BS13: 0 | BT13: 1 | BU13: 1 | BV13: 0 | BW13: 1 | BX13: 1 | BY13: 1 | BZ13: 1 | CA13: 0 | CB13: 1 | CC13: 1
... A61: 343742 | B61: 330136 | C61: 335913 | D61: 351427 | E61: 332393 | F61: 331753 | G61: 327475 | H61: 334753 | I61: 343715 | J61: 339612 | K61: 340511 | L61: 337016 | M61: 324786 | N61: 336941 | O61: 335842 | P61: 323284 | Q61: 324092 | R61: 327854 | S61: 337727 | T61: 331341 | U61: 328672 | V61: 321775 | W61: 326565 | X61: 322986 | Y61: 322182 | Z61: 338664 | AA61: 330040 | AB61: 0 | AC61: 0 | AD61: 0 | AE61: 0 | AF61: 0 | AG61: 0 | AH61: 0 | AI61: 0 | AJ61: 0 | AK61: 0 | AL61: 0 | AM61: 0 | AN61: 0 | AO61: 0 | AP61: 0 | AQ61: 0 | AR61: 0 | AS61: 0 | AT61: 0 | AU61: 0 | AV61: 0 | AW61: 0 | AX61: 0 | AY61: 0 | AZ61: 0 | BA61: 0 | BB61: 0 | BC61: 1 | BD61: 0 | BE61: 1 | BF61: 0 | BG61: 1 | BH61: 0 | BI61: 1 | BJ61: 0 | BK61: 1 | BL61: 1 | BM61: 0 | BN61: 1 | BO61: 0 | BP61: 1 | BQ61: 1 | BR61: 0 | BS61: 1 | BT61: 1 | BU61: 1 | BV61: 1 | BW61: 1 | BX61: 0 | BY61: 1 | BZ61: 1 | CA61: 1 | CB61: 1 | CC61: 1

Sheet 2_50J
A1: 40_500_0.2 | B1: 40_800_0.2 | C1: 40_1000_0.2 | D1: 40_500_0.3 | E1: 40_800_0.3 | F1: 40_1000_0.3 | G1: 40_500_0.5 | H1: 40_800_0.5 | I1: 40_1000_0.5 | J1: 50_500_0.2 | K1: 50_800_0.2 | L1: 50_1000_0.2 | M1: 50_500_0.3 | N1: 50_800_0.3 | O1: 50_1000_0.3 | P1: 50_500_0.5 | Q1: 50_800_0.5 | R1: 50_1000_0.5 | S1: 70_500_0.2 | T1: 70_800_0.2 | U1: 70_1000_0.2 | V1: 70_500_0.3 | W1: 70_800_0.3 | X1: 70_1000_0.3 | Y1: 70_500_0.5 | Z1: 70_800_0.5 | AA1: 70_1000_0.5 | AB1: OVER_1 | AC1: OVER_2 | AD1: OVER_3 | AE1: OVER_4 | AF1: OVER_5 | AG1: OVER_6 | AH1: OVER_7 | AI1: OVER_8 | AJ1: OVER_9 | AK1: OVER_10 | AL1: OVER_11 | AM1: OVER_12 | AN1: OVER_13 | AO1: OVER_14 | AP1: OVER_15 | AQ1: OVER_16 | AR1: OVER_17 | AS1: OVER_18 | AT1: OVER_19 | AU1: OVER_20 | AV1: OVER_21 | AW1: OVER_22 | AX1: OVER_23 | AY1: OVER_24 | AZ1: OVER_25 | BA1: OVER_26 | BB1: OVER_27 | BC1: TIME_1 | BD1: TIME_2 | BE1: TIME_3 | BF1: TIME_4 | BG1: TIME_5 | BH1: TIME_6 | BI1: TIME_7 | BJ1: TIME_8 | BK1: TIME_9 | BL1: TIME_10 | BM1: TIME_11 | BN1: TIME_12 | BO1: TIME_13 | BP1: TIME_14 | BQ1: TIME_15 | BR1: TIME_16 | BS1: TIME_17 | BT1: TIME_18 | BU1: TIME_19 | BV1: TIME_20 | BW1: TIME_21 | BX1: TIME_22 | BY1: TIME_23 | BZ1: TIME_24 | CA1: TIME_25 | CB1: TIME_26 | CC1: TIME_27
A2: 349713 | B2: 340532 | C2: 344568 | D2: 335556 | E2: 341275 | F2: 324709 | G2: 338593 | H2: 343290 | I2: 343662 | J2: 315054 | K2: 324380 | L2: 322009 | M2: 343473 | N2: 320328 | O2: 336852 | P2: 331018 | Q2: 324423 | R2: 328429 | S2: 344348 | T2: 313810 | U2: 326900 | V2: 328896 | W2: 373567 | X2: 339720 | Y2: 325241 | Z2: 304741 | AA2: 312670 | AB2: 18 | AC2: 0 | AD2: 0 | AE2: 0 | AF2: 0 | AG2: 0 | AH2: 0 | AI2: 0 | AJ2: 0 | AK2: 0 | AL2: 0 | AM2: 0 | AN2: 0 | AO2: 0 | AP2: 0 | AQ2: 17 | AR2: 0 | AS2: 0 | AT2: 0 | AU2: 0 | AV2: 18 | AW2: 0 | AX2: 61 | AY2: 0 | AZ2: 0 | BA2: 0 | BB2: 0 | BC2: 1 | BD2: 0 | BE2: 0 | BF2: 1 | BG2: 0 | BH2: 1 | BI2: 0 | BJ2: 1 | BK2: 0 | BL2: 0 | BM2: 1 | BN2: 1 | BO2: 0 | BP2: 1 | BQ2: 0 | BR2: 1 | BS2: 0 | BT2: 1 | BU2: 1 | BV2: 0 | BW2: 1 | BX2: 1 | BY2: 1 | BZ2: 1 | CA2: 0 | CB2: 1 | CC2: 1
A3: 321666 | B3: 314923 | C3: 324547 | D3: 321244 | E3: 337264 | F3: 356825 | G3: 327038 | H3: 354219 | I3: 312804 | J3: 347845 | K3: 341830 | L3: 308369 | M3: 356247 | N3: 335044 | O3: 327185 | P3: 423807 | Q3: 314317 | R3: 335054 | S3: 316017 | T3: 322137 | U3: 347281 | V3: 323650 | W3: 329000 | X3: 304342 | Y3: 328190 | Z3: 347474 | AA3: 304875 | AB3: 0 | AC3: 0 | AD3: 0 | AE3: 0 | AF3: 0 | AG3: 36 | AH3: 0 | AI3: 24 | AJ3: 0 | AK3: 5 | AL3: 3 | AM3: 0 | AN3: 0 | AO3: 22 | AP3: 0 | AQ3: 96 | AR3: 0 | AS3: 0 | AT3: 0 | AU3: 4 | AV3: 27 | AW3: 0 | AX3: 15 | AY3: 0 | AZ3: 9 | BA3: 44 | BB3: 4 | BC3: 0 | BD3: 1 | BE3: 0 | BF3: 1 | BG3: 0 | BH3: 1 | BI3: 0 | BJ3: 1 | BK3: 0 | BL3: 0 | BM3: 1 | BN3: 1 | BO3: 0 | BP3: 1 | BQ3: 1 | BR3: 0 | BS3: 1 | BT3: 0 | BU3: 1 | BV3: 1 | BW3: 1 | BX3: 0 | BY3: 1 | BZ3: 1 | CA3: 1 | CB3: 1 | CC3: 1
A4: 424067 | B4: 379112 | C4: 353102 | D4: 365016 | E4: 335800 | F4: 372729 | G4: 360440 | H4: 336878 | I4: 393013 | J4: 353706 | K4: 340676 | L4: 337397 | M4: 346437 | N4: 330758 | O4: 323334 | P4: 329397 | Q4: 324942 | R4: 337094 | S4: 341941 | T4: 364946 | U4: 319136 | V4: 350781 | W4: 354547 | X4: 344558 | Y4: 343748 | Z4: 339996 | AA4: 334161 | AB4: 38 | AC4: 22 | AD4: 0 | AE4: 36 | AF4: 0 | AG4: 0 | AH4: 0 | AI4: 0 | AJ4: 41 | AK4: 0 | AL4: 0 | AM4: 0 | AN4: 0 | AO4: 0 | AP4: 0 | AQ4: 0 | AR4: 0 | AS4: 0 | AT4: 0 | AU4: 0 | AV4: 0 | AW4: 0 | AX4: 0 | AY4: 0 | AZ4: 0 | BA4: 0 | BB4: 0 | BC4: 0 | BD4: 1 | BE4: 0 | BF4: 1 | BG4: 0 | BH4: 1 | BI4: 0 | BJ4: 1 | BK4: 0 | BL4: 1 | BM4: 0 | BN4: 1 | BO4: 0 | BP4: 1 | BQ4: 0 | BR4: 1 | BS4: 0 | BT4: 1 | BU4: 1 | BV4: 0 | BW4: 1 | BX4: 1 | BY4: 1 | BZ4: 1 | CA4: 0 | CB4: 1 | CC4: 1
A5: 350026 | B5: 346831 | C5: 376291 | D5: 355905 | E5: 483000 | F5: 391742 | G5: 338500 | H5: 367063 | I5: 346330 | J5: 352068 | K5: 367186 | L5: 361075 | M5: 367189 | N5: 356828 | O5: 368634 | P5: 351329 | Q5: 354820 | R5: 451169 | S5: 373479 | T5: 344968 | U5: 383948 | V5: 424624 | W5: 357732 | X5: 351720 | Y5: 355305 | Z5: 319229 | AA5: 352141 | AB5: 0 | AC5: 0 | AD5: 0 | AE5: 0 | AF5: 110 | AG5: 0 | AH5: 0 | AI5: 0 | AJ5: 0 | AK5: 0 | AL5: 0 | AM5: 0 | AN5: 0 | AO5: 0 | AP5: 0 | AQ5: 0 | AR5: 0 | AS5: 105 | AT5: 0 | AU5: 5 | AV5: 0 | AW5: 44 | AX5: 0 | AY5: 0 | AZ5: 0 | BA5: 0 | BB5: 0 | BC5: 0 | BD5: 1 | BE5: 0 | BF5: 1 | BG5: 0 | BH5: 1 | BI5: 0 | BJ5: 1 | BK5: 0 | BL5: 0 | BM5: 1 | BN5: 1 | BO5: 0 | BP5: 1 | BQ5: 0 | BR5: 1 | BS5: 0 | BT5: 1 | BU5: 1 | BV5: 1 | BW5: 0 | BX5: 1 | BY5: 1 | BZ5: 1 | CA5: 0 | CB5: 1 | CC5: 1
A6: 338613 | B6: 326658 | C6: 315886 | D6: 320005 | E6: 321512 | F6: 327521 | G6: 336724 | H6: 333764 | I6: 317962 | J6: 326232 | K6: 343710 | L6: 323014 | M6: 321841 | N6: 342084 | O6: 322678 | P6: 334892 | Q6: 322995 | R6: 327614 | S6: 325021 | T6: 322857 | U6: 315663 | V6: 311244 | W6: 315667 | X6: 317333 | Y6: 296284 | Z6: 316657 | AA6: 337044 | AB6: 0 | AC6: 0 | AD6: 0 | AE6: 0 | AF6: 0 | AG6: 0 | AH6: 0 | AI6: 0 | AJ6: 0 | AK6: 0 | AL6: 0 | AM6: 0 | AN6: 0 | AO6: 0 | AP6: 0 | AQ6: 0 | AR6: 9 | AS6: 6 | AT6: 0 | AU6: 0 | AV6: 0 | AW6: 0 | AX6: 0 | AY6: 0 | AZ6: 0 | BA6: 0 | BB6: 0 | BC6: 0 | BD6: 1 | BE6: 0 | BF6: 1 | BG6: 0 | BH6: 1 | BI6: 0 | BJ6: 0 | BK6: 1 | BL6: 0 | BM6: 1 | BN6: 1 | BO6: 0 | BP6: 1 | BQ6: 0 | BR6: 1 | BS6: 0 | BT6: 1 | BU6: 1 | BV6: 0 | BW6: 1 | BX6: 1 | BY6: 1 | BZ6: 1 | CA6: 0 | CB6: 1 | CC6: 1
A7: 424679 | B7: 377837 | C7: 366368 | D7: 398210 | E7: 392652 | F7: 380602 | G7: 385218 | H7: 379957 | I7: 360734 | J7: 369008 | K7: 386352 | L7: 376906 | M7: 380296 | N7: 361219 | O7: 388427 | P7: 394424 | Q7: 401124 | R7: 374494 | S7: 418702 | T7: 396717 | U7: 378527 | V7: 498332 | W7: 378576 | X7: 364970 | Y7: 373017 | Z7: 384087 | AA7: 383039 | AB7: 5 | AC7: 0 | AD7: 0 | AE7: 0 | AF7: 7 | AG7: 0 | AH7: 21 | AI7: 0 | AJ7: 0 | AK7: 0 | AL7: 0 | AM7: 0 | AN7: 0 | AO7: 0 | AP7: 0 | AQ7: 18 | AR7: 38 | AS7: 0 | AT7: 0 | AU7: 0 | AV7: 0 | AW7: 122 | AX7: 0 | AY7: 0 | AZ7: 0 | BA7: 0 | BB7: 0 | BC7: 0 | BD7: 1 | BE7: 0 | BF7: 1 | BG7: 0 | BH7: 1 | BI7: 0 | BJ7: 0 | BK7: 1 | BL7: 0 | BM7: 1 | BN7: 1 | BO7: 0 | BP7: 1 | BQ7: 0 | BR7: 1 | BS7: 0 | BT7: 1 | BU7: 1 | BV7: 0 | BW7: 1 | BX7: 1 | BY7: 1 | BZ7: 1 | CA7: 0 | CB7: 1 | CC7: 1
A8: 383458 | B8: 393410 | C8: 383294 | D8: 373830 | E8: 394987 | F8: 361641 | G8: 438726 | H8: 360749 | I8: 362040 | J8: 419760 | K8: 393660 | L8: 408880 | M8: 401969 | N8: 442904 | O8: 417241 | P8: 411010 | Q8: 379655 | R8: 374288 | S8: 400789 | T8: 385367 | U8: 390090 | V8: 382347 | W8: 391528 | X8: 393811 | Y8: 359618 | Z8: 383513 | AA8: 382611 | AB8: 0 | AC8: 0 | AD8: 0 | AE8: 0 | AF8: 0 | AG8: 0 | AH8: 48 | AI8: 0 | AJ8: 0 | AK8: 0 | AL8: 0 | AM8: 0 | AN8: 0 | AO8: 37 | AP8: 0 | AQ8: 0 | AR8: 0 | AS8: 0 | AT8: 0 | AU8: 0 | AV8: 0 | AW8: 0 | AX8: 0 | AY8: 0 | AZ8: 0 | BA8: 0 | BB8: 0 | BC8: 0 | BD8: 1 | BE8: 0 | BF8: 1 | BG8: 0 | BH8: 1 | BI8: 0 | BJ8: 1 | BK8: 0 | BL8: 0 | BM8: 1 | BN8: 1 | BO8: 0 | BP8: 1 | BQ8: 0 | BR8: 1 | BS8: 0 | BT8: 1 | BU8: 1 | BV8: 0 | BW8: 1 | BX8: 1 | BY8: 1 | BZ8: 1 | CA8: 0 | CB8: 1 | CC8: 1
A9: 313967 | B9: 322950 | C9: 315586 | D9: 338172 | E9: 326008 | F9: 330597 | G9: 321366 | H9: 474648 | I9: 307726 | J9: 310127 | K9: 361321 | L9: 350023 | M9: 321773 | N9: 345492 | O9: 302501 | P9: 305232 | Q9: 326686 | R9: 323870 | S9: 330784 | T9: 328668 | U9: 323933 | V9: 328807 | W9: 320229 | X9: 382657 | Y9: 305152 | Z9: 317082 | AA9: 302486 | AB9: 0 | AC9: 0 | AD9: 0 | AE9: 0 | AF9: 0 | AG9: 0 | AH9: 0 | AI9: 141 | AJ9: 0 | AK9: 0 | AL9: 0 | AM9: 0 | AN9: 0 | AO9: 0 | AP9: 0 | AQ9: 0 | AR9: 0 | AS9: 0 | AT9: 0 | AU9: 2 | AV9: 0 | AW9: 0 | AX9: 0 | AY9: 40 | AZ9: 0 | BA9: 0 | BB9: 0 | BC9: 0 | BD9: 1 | BE9: 0 | BF9: 1 | BG9: 0 | BH9: 1 | BI9: 0 | BJ9: 0 | BK9: 1 | BL9: 0 | BM9: 1 | BN9: 1 | BO9: 0 | BP9: 0 | BQ9: 1 | BR9: 1 | BS9: 0 | BT9: 1 | BU9: 0 | BV9: 1 | BW9: 1 | BX9: 1 | BY9: 1 | BZ9: 1 | CA9: 0 | CB9: 1 | CC9: 1
A10: 380731 | B10: 369162 | C10: 381751 | D10: 356554 | E10: 399986 | F10: 334211 | G10: 364785 | H10: 364698 | I10: 357270 | J10: 375558 | K10: 370651 | L10: 360736 | M10: 368944 | N10: 411931 | O10: 359994 | P10: 345148 | Q10: 353550 | R10: 382171 | S10: 366636 | T10: 400100 | U10: 376402 | V10: 376681 | W10: 375716 | X10: 375958 | Y10: 354532 | Z10: 363359 | AA10: 358310 | AB10: 0 | AC10: 0 | AD10: 0 | AE10: 0 | AF10: 0 | AG10: 0 | AH10: 0 | AI10: 0 | AJ10: 0 | AK10: 0 | AL10: 0 | AM10: 0 | AN10: 0 | AO10: 48 | AP10: 0 | AQ10: 0 | AR10: 0 | AS10: 0 | AT10: 0 | AU10: 29 | AV10: 18 | AW10: 19 | AX10: 0 | AY10: 5 | AZ10: 0 | BA10: 0 | BB10: 0 | BC10: 1 | BD10: 0 | BE10: 1 | BF10: 0 | BG10: 0 | BH10: 1 | BI10: 0 | BJ10: 1 | BK10: 0 | BL10: 1 | BM10: 0 | BN10: 1 | BO10: 0 | BP10: 1 | BQ10: 0 | BR10: 1 | BS10: 0 | BT10: 1 | BU10: 1 | BV10: 0 | BW10: 2 | BX10: 0 | BY10: 1 | BZ10: 1 | CA10: 1 | CB10: 1 | CC10: 1
A11: 356004 | B11: 369544 | C11: 359055 | D11: 341881 | E11: 365078 | F11: 351627 | G11: 351070 | H11: 370020 | I11: 361618 | J11: 433681 | K11: 378290 | L11: 365676 | M11: 362059 | N11: 365961 | O11: 380801 | P11: 369636 | Q11: 342323 | R11: 361821 | S11: 364749 | T11: 366553 | U11: 358460 | V11: 376989 | W11: 356398 | X11: 390839 | Y11: 363246 | Z11: 365673 | AA11: 345610 | AB11: 0 | AC11: 0 | AD11: 0 | AE11: 0 | AF11: 0 | AG11: 0 | AH11: 0 | AI11: 0 | AJ11: 0 | AK11: 79 | AL11: 0 | AM11: 0 | AN11: 0 | AO11: 0 | AP11: 0 | AQ11: 0 | AR11: 0 | AS11: 23 | AT11: 0 | AU11: 0 | AV11: 0 | AW11: 0 | AX11: 0 | AY11: 24 | AZ11: 0 | BA11: 0 | BB11: 0 | BC11: 0 | BD11: 0 | BE11: 1 | BF11: 0 | BG11: 1 | BH11: 0 | BI11: 0 | BJ11: 1 | BK11: 1 | BL11: 0 | BM11: 0 | BN11: 1 | BO11: 0 | BP11: 1 | BQ11: 1 | BR11: 0 | BS11: 1 | BT11: 1 | BU11: 0 | BV11: 1 | BW11: 1 | BX11: 0 | BY11: 1 | BZ11: 1 | CA11: 1 | CB11: 0 | CC11: 2
A12: 400348 | B12: 434543 | C12: 383698 | D12: 384520 | E12: 413350 | F12: 419430 | G12: 398264 | H12: 387555 | I12: 389032 | J12: 420481 | K12: 415025 | L12: 386360 | M12: 384640 | N12: 432893 | O12: 378624 | P12: 418630 | Q12: 378529 | R12: 421859 | S12: 415461 | T12: 406766 | U12: 393746 | V12: 405619 | W12: 392272 | X12: 414455 | Y12: 383619 | Z12: 382640 | AA12: 397192 | AB12: 0 | AC12: 0 | AD12: 0 | AE12: 0 | AF12: 0 | AG12: 0 | AH12: 0 | AI12: 0 | AJ12: 0 | AK12: 0 | AL12: 0 | AM12: 0 | AN12: 0 | AO12: 0 | AP12: 0 | AQ12: 0 | AR12: 0 | AS12: 0 | AT12: 0 | AU12: 0 | AV12: 0 | AW12: 0 | AX12: 0 | AY12: 0 | AZ12: 0 | BA12: 0 | BB12: 0 | BC12: 0 | BD12: 0 | BE12: 1 | BF12: 0 | BG12: 0 | BH12: 1 | BI12: 0 | BJ12: 1 | BK12: 0 | BL12: 1 | BM12: 0 | BN12: 1 | BO12: 0 | BP12: 1 | BQ12: 1 | BR12: 0 | BS12: 1 | BT12: 0 | BU12: 1 | BV12: 0 | BW12: 1 | BX12: 1 | BY12: 1 | BZ12: 1 | CA12: 0 | CB12: 1 | CC12: 1
A13: 397464 | B13: 383580 | C13: 361698 | D13: 389942 | E13: 392806 | F13: 363549 | G13: 363819 | H13: 379826 | I13: 351104 | J13: 353072 | K13: 353733 | L13: 369784 | M13: 364891 | N13: 366762 | O13: 342293 | P13: 362217 | Q13: 342473 | R13: 377216 | S13: 368084 | T13: 352074 | U13: 339505 | V13: 371838 | W13: 369574 | X13: 361201 | Y13: 350333 | Z13: 376329 | AA13: 367761 | AB13: 0 | AC13: 0 | AD13: 0 | AE13: 0 | AF13: 0 | AG13: 0 | AH13: 0 | AI13: 0 | AJ13: 0 | AK13: 0 | AL13: 0 | AM13: 0 | AN13: 0 | AO13: 0 | AP13: 0 | AQ13: 0 | AR13: 0 | AS13: 31 | AT13: 0 | AU13: 0 | AV13: 0 | AW13: 0 | AX13: 0 | AY13: 0 | AZ13: 0 | BA13: 0 | BB13: 30 | BC13: 0 | BD13: 1 | BE13: 0 | BF13: 1 | BG13: 0 | BH13: 1 | BI13: 0 | BJ13: 0 | BK13: 1 | BL13: 0 | BM13: 1 | BN13: 1 | BO13: 0 | BP13: 0 | BQ13: 1 | BR13: 1 | BS13: 0 | BT13: 1 | BU13: 0 | BV13: 1 | BW13: 1 | BX13: 1 | BY13: 1 | BZ13: 0 | CA13: 1 | CB13: 1 | CC13: 1
... A61: 325565 | B61: 334590 | C61: 328047 | D61: 319422 | E61: 320659 | F61: 345647 | G61: 344356 | H61: 308282 | I61: 331020 | J61: 338825 | K61: 320996 | L61: 327754 | M61: 335388 | N61: 341194 | O61: 330736 | P61: 330767 | Q61: 325305 | R61: 336653 | S61: 318599 | T61: 334848 | U61: 327973 | V61: 333957 | W61: 332397 | X61: 330811 | Y61: 333666 | Z61: 321494 | AA61: 335875 | AB61: 0 | AC61: 0 | AD61: 0 | AE61: 0 | AF61: 0 | AG61: 0 | AH61: 0 | AI61: 0 | AJ61: 0 | AK61: 0 | AL61: 0 | AM61: 0 | AN61: 0 | AO61: 0 | AP61: 0 | AQ61: 0 | AR61: 0 | AS61: 0 | AT61: 0 | AU61: 0 | AV61: 0 | AW61: 0 | AX61: 1 | AY61: 0 | AZ61: 0 | BA61: 0 | BB61: 0 | BC61: 0 | BD61: 1 | BE61: 1 | BF61: 0 | BG61: 0 | BH61: 1 | BI61: 0 | BJ61: 1 | BK61: 1 | BL61: 0 | BM61: 1 | BN61: 1 | BO61: 0 | BP61: 1 | BQ61: 1 | BR61: 0 | BS61: 1 | BT61: 1 | BU61: 0 | BV61: 1 | BW61: 1 | BX61: 1 | BY61: 1 | BZ61: 1 | CA61: 1 | CB61: 1 | CC61: 1

Sheet 3_50J
A1: 40_500_0.2 | B1: 40_800_0.2 | C1: 40_1000_0.2 | D1: 40_500_0.3 | E1: 40_800_0.3 | F1: 40_1000_0.3 | G1: 40_500_0.5 | H1: 40_800_0.5 | I1: 40_1000_0.5 | J1: 50_500_0.2 | K1: 50_800_0.2 | L1: 50_1000_0.2 | M1: 50_500_0.3 | N1: 50_800_0.3 | O1: 50_1000_0.3 | P1: 50_500_0.5 | Q1: 50_800_0.5 | R1: 50_1000_0.5 | S1: 70_500_0.2 | T1: 70_800_0.2 | U1: 70_1000_0.2 | V1: 70_500_0.3 | W1: 70_800_0.3 | X1: 70_1000_0.3 | Y1: 70_500_0.5 | Z1: 70_800_0.5 | AA1: 70_1000_0.5 | AB1: OVER_1 | AC1: OVER_2 | AD1: OVER_3 | AE1: OVER_4 | AF1: OVER_5 | AG1: OVER_6 | AH1: OVER_7 | AI1: OVER_8 | AJ1: OVER_9 | AK1: OVER_10 | AL1: OVER_11 | AM1: OVER_12 | AN1: OVER_13 | AO1: OVER_14 | AP1: OVER_15 | AQ1: OVER_16 | AR1: OVER_17 | AS1: OVER_18 | AT1: OVER_19 | AU1: OVER_20 | AV1: OVER_21 | AW1: OVER_22 | AX1: OVER_23 | AY1: OVER_24 | AZ1: OVER_25 | BA1: OVER_26 | BB1: OVER_27 | BC1: TIME_1 | BD1: TIME_2 | BE1: TIME_3 | BF1: TIME_4 | BG1: TIME_5 | BH1: TIME_6 | BI1: TIME_7 | BJ1: TIME_8 | BK1: TIME_9 | BL1: TIME_10 | BM1: TIME_11 | BN1: TIME_12 | BO1: TIME_13 | BP1: TIME_14 | BQ1: TIME_15 | BR1: TIME_16 | BS1: TIME_17 | BT1: TIME_18 | BU1: TIME_19 | BV1: TIME_20 | BW1: TIME_21 | BX1: TIME_22 | BY1: TIME_23 | BZ1: TIME_24 | CA1: TIME_25 | CB1: TIME_26 | CC1: TIME_27
A2: 337224 | B2: 339857 | C2: 325064 | D2: 351716 | E2: 391579 | F2: 327308 | G2: 308579 | H2: 308700 | I2: 338978 | J2: 357792 | K2: 340333 | L2: 306100 | M2: 316787 | N2: 354201 | O2: 350723 | P2: 295860 | Q2: 324088 | R2: 312588 | S2: 352973 | T2: 319089 | U2: 326293 | V2: 311401 | W2: 323520 | X2: 320275 | Y2: 353222 | Z2: 298917 | AA2: 335125 | AB2: 0 | AC2: 0 | AD2: 11 | AE2: 0 | AF2: 62 | AG2: 0 | AH2: 0 | AI2: 0 | AJ2: 0 | AK2: 39 | AL2: 0 | AM2: 0 | AN2: 0 | AO2: 0 | AP2: 0 | AQ2: 0 | AR2: 0 | AS2: 0 | AT2: 0 | AU2: 0 | AV2: 0 | AW2: 0 | AX2: 0 | AY2: 0 | AZ2: 48 | BA2: 0 | BB2: 0 | BC2: 0 | BD2: 1 | BE2: 0 | BF2: 1 | BG2: 0 | BH2: 1 | BI2: 0 | BJ2: 1 | BK2: 0 | BL2: 1 | BM2: 0 | BN2: 1 | BO2: 0 | BP2: 1 | BQ2: 0 | BR2: 1 | BS2: 0 | BT2: 1 | BU2: 1 | BV2: 0 | BW2: 1 | BX2: 1 | BY2: 1 | BZ2: 1 | CA2: 0 | CB2: 1 | CC2: 1
A3: 338199 | B3: 340162 | C3: 310534 | D3: 321275 | E3: 345236 | F3: 300762 | G3: 307805 | H3: 310154 | I3: 326287 | J3: 342206 | K3: 340457 | L3: 329293 | M3: 332230 | N3: 341656 | O3: 309459 | P3: 311333 | Q3: 332750 | R3: 316468 | S3: 321913 | T3: 313980 | U3: 317720 | V3: 344545 | W3: 320500 | X3: 320014 | Y3: 327252 | Z3: 326671 | AA3: 317852 | AB3: 0 | AC3: 2 | AD3: 0 | AE3: 0 | AF3: 0 | AG3: 0 | AH3: 0 | AI3: 0 | AJ3: 0 | AK3: 11 | AL3: 4 | AM3: 0 | AN3: 0 | AO3: 0 | AP3: 0 | AQ3: 0 | AR3: 8 | AS3: 0 | AT3: 0 | AU3: 0 | AV3: 1 | AW3: 13 | AX3: 0 | AY3: 0 | AZ3: 0 | BA3: 0 | BB3: 0 | BC3: 0 | BD3: 1 | BE3: 0 | BF3: 1 | BG3: 0 | BH3: 1 | BI3: 0 | BJ3: 0 | BK3: 1 | BL3: 0 | BM3: 1 | BN3: 1 | BO3: 0 | BP3: 0 | BQ3: 1 | BR3: 1 | BS3: 0 | BT3: 1 | BU3: 0 | BV3: 1 | BW3: 1 | BX3: 1 | BY3: 1 | BZ3: 1 | CA3: 0 | CB3: 1 | CC3: 1
A4: 355625 | B4: 343472 | C4: 353624 | D4: 335869 | E4: 361880 | F4: 335507 | G4: 336353 | H4: 375567 | I4: 359797 | J4: 378793 | K4: 367008 | L4: 319202 | M4: 336679 | N4: 335241 | O4: 356417 | P4: 338165 | Q4: 338474 | R4: 350628 | S4: 360382 | T4: 345580 | U4: 349087 | V4: 365036 | W4: 337164 | X4: 375700 | Y4: 337748 | Z4: 338324 | AA4: 329256 | AB4: 0 | AC4: 0 | AD4: 0 | AE4: 0 | AF4: 0 | AG4: 0 | AH4: 0 | AI4: 51 | AJ4: 0 | AK4: 9 | AL4: 0 | AM4: 0 | AN4: 0 | AO4: 0 | AP4: 0 | AQ4: 0 | AR4: 0 | AS4: 0 | AT4: 14 | AU4: 0 | AV4: 0 | AW4: 38 | AX4: 0 | AY4: 24 | AZ4: 0 | BA4: 0 | BB4: 0 | BC4: 0 | BD4: 1 | BE4: 0 | BF4: 1 | BG4: 0 | BH4: 1 | BI4: 0 | BJ4: 0 | BK4: 1 | BL4: 0 | BM4: 1 | BN4: 1 | BO4: 0 | BP4: 1 | BQ4: 0 | BR4: 1 | BS4: 0 | BT4: 1 | BU4: 1 | BV4: 0 | BW4: 1 | BX4: 1 | BY4: 1 | BZ4: 1 | CA4: 0 | CB4: 1 | CC4: 1
A5: 386931 | B5: 355662 | C5: 373501 | D5: 362810 | E5: 365282 | F5: 350248 | G5: 358173 | H5: 343700 | I5: 337632 | J5: 412139 | K5: 376431 | L5: 349743 | M5: 361564 | N5: 376560 | O5: 365034 | P5: 345712 | Q5: 375066 | R5: 349113 | S5: 420361 | T5: 365065 | U5: 340081 | V5: 360693 | W5: 381112 | X5: 346893 | Y5: 355454 | Z5: 325618 | AA5: 354874 | AB5: 0 | AC5: 0 | AD5: 0 | AE5: 0 | AF5: 0 | AG5: 0 | AH5: 0 | AI5: 0 | AJ5: 0 | AK5: 54 | AL5: 0 | AM5: 0 | AN5: 0 | AO5: 0 | AP5: 0 | AQ5: 0 | AR5: 0 | AS5: 0 | AT5: 54 | AU5: 0 | AV5: 0 | AW5: 10 | AX5: 10 | AY5: 0 | AZ5: 0 | BA5: 0 | BB5: 0 | BC5: 0 | BD5: 1 | BE5: 0 | BF5: 1 | BG5: 0 | BH5: 1 | BI5: 0 | BJ5: 1 | BK5: 0 | BL5: 0 | BM5: 1 | BN5: 1 | BO5: 0 | BP5: 1 | BQ5: 0 | BR5: 1 | BS5: 0 | BT5: 1 | BU5: 1 | BV5: 0 | BW5: 1 | BX5: 1 | BY5: 1 | BZ5: 1 | CA5: 0 | CB5: 1 | CC5: 1
A6: 326097 | B6: 310144 | C6: 329856 | D6: 301690 | E6: 337623 | F6: 306303 | G6: 364695 | H6: 320721 | I6: 312552 | J6: 327732 | K6: 321356 | L6: 340182 | M6: 343928 | N6: 299034 | O6: 315512 | P6: 321366 | Q6: 314011 | R6: 344168 | S6: 341199 | T6: 338827 | U6: 312582 | V6: 329613 | W6: 318788 | X6: 290630 | Y6: 308620 | Z6: 319312 | AA6: 326495 | AB6: 0 | AC6: 0 | AD6: 0 | AE6: 0 | AF6: 0 | AG6: 0 | AH6: 0 | AI6: 0 | AJ6: 0 | AK6: 0 | AL6: 0 | AM6: 0 | AN6: 0 | AO6: 0 | AP6: 0 | AQ6: 0 | AR6: 0 | AS6: 0 | AT6: 0 | AU6: 0 | AV6: 0 | AW6: 0 | AX6: 0 | AY6: 0 | AZ6: 0 | BA6: 0 | BB6: 0 | BC6: 1 | BD6: 0 | BE6: 1 | BF6: 0 | BG6: 0 | BH6: 1 | BI6: 0 | BJ6: 1 | BK6: 0 | BL6: 1 | BM6: 0 | BN6: 1 | BO6: 0 | BP6: 1 | BQ6: 0 | BR6: 1 | BS6: 0 | BT6: 1 | BU6: 1 | BV6: 0 | BW6: 1 | BX6: 1 | BY6: 1 | BZ6: 1 | CA6: 0 | CB6: 1 | CC6: 1
A7: 386394 | B7: 377838 | C7: 380591 | D7: 431405 | E7: 369337 | F7: 363936 | G7: 367000 | H7: 372920 | I7: 376253 | J7: 449387 | K7: 385698 | L7: 390102 | M7: 385635 | N7: 358160 | O7: 354541 | P7: 390853 | Q7: 357979 | R7: 371634 | S7: 369119 | T7: 381601 | U7: 383255 | V7: 351750 | W7: 361036 | X7: 385566 | Y7: 381029 | Z7: 368534 | AA7: 384414 | AB7: 0 | AC7: 0 | AD7: 0 | AE7: 35 | AF7: 0 | AG7: 0 | AH7: 0 | AI7: 0 | AJ7: 0 | AK7: 30 | AL7: 0 | AM7: 0 | AN7: 0 | AO7: 0 | AP7: 0 | AQ7: 0 | AR7: 0 | AS7: 0 | AT7: 0 | AU7: 0 | AV7: 0 | AW7: 0 | AX7: 0 | AY7: 0 | AZ7: 0 | BA7: 0 | BB7: 0 | BC7: 0 | BD7: 1 | BE7: 0 | BF7: 1 | BG7: 0 | BH7: 1 | BI7: 0 | BJ7: 1 | BK7: 0 | BL7: 1 | BM7: 0 | BN7: 1 | BO7: 0 | BP7: 1 | BQ7: 1 | BR7: 0 | BS7: 1 | BT7: 0 | BU7: 1 | BV7: 1 | BW7: 0 | BX7: 1 | BY7: 1 | BZ7: 1 | CA7: 0 | CB7: 1 | CC7: 1
A8: 420900 | B8: 380930 | C8: 391561 | D8: 378578 | E8: 391386 | F8: 408342 | G8: 390620 | H8: 382028 | I8: 393496 | J8: 397162 | K8: 397272 | L8: 405025 | M8: 397751 | N8: 395584 | O8: 370416 | P8: 401451 | Q8: 373165 | R8: 435585 | S8: 391402 | T8: 398314 | U8: 430770 | V8: 402534 | W8: 402549 | X8: 513053 | Y8: 376625 | Z8: 385943 | AA8: 432602 | AB8: 7 | AC8: 0 | AD8: 0 | AE8: 0 | AF8: 0 | AG8: 0 | AH8: 0 | AI8: 0 | AJ8: 0 | AK8: 0 | AL8: 0 | AM8: 0 | AN8: 0 | AO8: 0 | AP8: 0 | AQ8: 0 | AR8: 0 | AS8: 38 | AT8: 0 | AU8: 0 | AV8: 23 | AW8: 0 | AX8: 0 | AY8: 120 | AZ8: 0 | BA8: 0 | BB8: 46 | BC8: 1 | BD8: 0 | BE8: 1 | BF8: 0 | BG8: 0 | BH8: 1 | BI8: 0 | BJ8: 1 | BK8: 0 | BL8: 1 | BM8: 0 | BN8: 1 | BO8: 0 | BP8: 1 | BQ8: 0 | BR8: 1 | BS8: 0 | BT8: 1 | BU8: 1 | BV8: 0 | BW8: 1 | BX8: 1 | BY8: 1 | BZ8: 1 | CA8: 1 | CB8: 0 | CC8: 2
A9: 326912 | B9: 350374 | C9: 317853 | D9: 310083 | E9: 321465 | F9: 383040 | G9: 319429 | H9: 327626 | I9: 306081 | J9: 326645 | K9: 423725 | L9: 302990 | M9: 333255 | N9: 331976 | O9: 331808 | P9: 327866 | Q9: 317642 | R9: 321170 | S9: 309309 | T9: 324402 | U9: 348893 | V9: 314048 | W9: 312999 | X9: 330758 | Y9: 337989 | Z9: 321565 | AA9: 319069 | AB9: 0 | AC9: 3 | AD9: 0 | AE9: 0 | AF9: 0 | AG9: 56 | AH9: 0 | AI9: 0 | AJ9: 0 | AK9: 0 | AL9: 87 | AM9: 0 | AN9: 0 | AO9: 0 | AP9: 0 | AQ9: 0 | AR9: 0 | AS9: 0 | AT9: 0 | AU9: 0 | AV9: 28 | AW9: 0 | AX9: 0 | AY9: 0 | AZ9: 0 | BA9: 0 | BB9: 22 | BC9: 0 | BD9: 0 | BE9: 1 | BF9: 0 | BG9: 1 | BH9: 0 | BI9: 1 | BJ9: 0 | BK9: 1 | BL9: 0 | BM9: 1 | BN9: 0 | BO9: 1 | BP9: 0 | BQ9: 1 | BR9: 0 | BS9: 1 | BT9: 1 | BU9: 0 | BV9: 1 | BW9: 1 | BX9: 0 | BY9: 1 | BZ9: 1 | CA9: 1 | CB9: 1 | CC9: 1
A10: 353672 | B10: 372652 | C10: 367114 | D10: 377327 | E10: 377200 | F10: 382982 | G10: 359679 | H10: 358049 | I10: 379706 | J10: 388135 | K10: 342260 | L10: 360798 | M10: 361642 | N10: 370855 | O10: 425078 | P10: 347593 | Q10: 358520 | R10: 354899 | S10: 376308 | T10: 370090 | U10: 386562 | V10: 349154 | W10: 389408 | X10: 365166 | Y10: 346363 | Z10: 356262 | AA10: 365816 | AB10: 0 | AC10: 0 | AD10: 10 | AE10: 0 | AF10: 0 | AG10: 0 | AH10: 0 | AI10: 0 | AJ10: 0 | AK10: 0 | AL10: 0 | AM10: 0 | AN10: 3 | AO10: 0 | AP10: 65 | AQ10: 0 | AR10: 0 | AS10: 0 | AT10: 0 | AU10: 0 | AV10: 0 | AW10: 0 | AX10: 18 | AY10: 0 | AZ10: 0 | BA10: 0 | BB10: 0 | BC10: 0 | BD10: 1 | BE10: 0 | BF10: 0 | BG10: 1 | BH10: 0 | BI10: 1 | BJ10: 0 | BK10: 1 | BL10: 0 | BM10: 1 | BN10: 1 | BO10: 0 | BP10: 0 | BQ10: 1 | BR10: 1 | BS10: 0 | BT10: 1 | BU10: 0 | BV10: 1 | BW10: 1 | BX10: 1 | BY10: 0 | BZ10: 1 | CA10: 1 | CB10: 1 | CC10: 1
A11: 358087 | B11: 364625 | C11: 368160 | D11: 422898 | E11: 336761 | F11: 386009 | G11: 367448 | H11: 348697 | I11: 347381 | J11: 372653 | K11: 359978 | L11: 366429 | M11: 376099 | N11: 326499 | O11: 338520 | P11: 343890 | Q11: 360168 | R11: 354526 | S11: 357750 | T11: 373270 | U11: 344757 | V11: 351907 | W11: 358801 | X11: 369741 | Y11: 357748 | Z11: 330422 | AA11: 332270 | AB11: 0 | AC11: 0 | AD11: 1 | AE11: 46 | AF11: 0 | AG11: 0 | AH11: 0 | AI11: 0 | AJ11: 0 | AK11: 0 | AL11: 0 | AM11: 0 | AN11: 0 | AO11: 0 | AP11: 0 | AQ11: 0 | AR11: 0 | AS11: 0 | AT11: 0 | AU11: 0 | AV11: 0 | AW11: 0 | AX11: 0 | AY11: 0 | AZ11: 0 | BA11: 0 | BB11: 0 | BC11: 0 | BD11: 1 | BE11: 0 | BF11: 1 | BG11: 0 | BH11: 0 | BI11: 1 | BJ11: 0 | BK11: 1 | BL11: 0 | BM11: 1 | BN11: 0 | BO11: 1 | BP11: 0 | BQ11: 1 | BR11: 0 | BS11: 1 | BT11: 1 | BU11: 0 | BV11: 1 | BW11: 1 | BX11: 0 | BY11: 1 | BZ11: 1 | CA11: 1 | CB11: 1 | CC11: 1
A12: 411614 | B12: 427177 | C12: 396390 | D12: 382870 | E12: 414802 | F12: 411215 | G12: 404856 | H12: 372598 | I12: 400574 | J12: 402929 | K12: 438573 | L12: 403999 | M12: 409797 | N12: 402317 | O12: 434276 | P12: 403599 | Q12: 375120 | R12: 432137 | S12: 395502 | T12: 384946 | U12: 416638 | V12: 399566 | W12: 394470 | X12: 390864 | Y12: 428355 | Z12: 409620 | AA12: 391830 | AB12: 0 | AC12: 0 | AD12: 0 | AE12: 0 | AF12: 0 | AG12: 0 | AH12: 0 | AI12: 0 | AJ12: 0 | AK12: 0 | AL12: 0 | AM12: 0 | AN12: 0 | AO12: 0 | AP12: 0 | AQ12: 0 | AR12: 0 | AS12: 0 | AT12: 0 | AU12: 0 | AV12: 0 | AW12: 0 | AX12: 0 | AY12: 0 | AZ12: 0 | BA12: 0 | BB12: 0 | BC12: 0 | BD12: 0 | BE12: 1 | BF12: 0 | BG12: 1 | BH12: 0 | BI12: 0 | BJ12: 1 | BK12: 1 | BL12: 0 | BM12: 0 | BN12: 1 | BO12: 0 | BP12: 1 | BQ12: 1 | BR12: 0 | BS12: 1 | BT12: 0 | BU12: 1 | BV12: 1 | BW12: 1 | BX12: 0 | BY12: 1 | BZ12: 1 | CA12: 0 | CB12: 1 | CC12: 1
A13: 360390 | B13: 376381 | C13: 344259 | D13: 385273 | E13: 337282 | F13: 336375 | G13: 373615 | H13: 359786 | I13: 359252 | J13: 393859 | K13: 345813 | L13: 358964 | M13: 379443 | N13: 368999 | O13: 352732 | P13: 388813 | Q13: 363653 | R13: 331728 | S13: 361118 | T13: 359216 | U13: 359009 | V13: 357558 | W13: 351420 | X13: 339174 | Y13: 354388 | Z13: 341464 | AA13: 322924 | AB13: 0 | AC13: 0 | AD13: 0 | AE13: 0 | AF13: 0 | AG13: 0 | AH13: 0 | AI13: 0 | AJ13: 1 | AK13: 0 | AL13: 0 | AM13: 0 | AN13: 0 | AO13: 0 | AP13: 0 | AQ13: 0 | AR13: 0 | AS13: 0 | AT13: 0 | AU13: 0 | AV13: 0 | AW13: 0 | AX13: 0 | AY13: 0 | AZ13: 0 | BA13: 0 | BB13: 0 | BC13: 1 | BD13: 0 | BE13: 1 | BF13: 0 | BG13: 0 | BH13: 1 | BI13: 0 | BJ13: 1 | BK13: 0 | BL13: 1 | BM13: 0 | BN13: 1 | BO13: 0 | BP13: 1 | BQ13: 1 | BR13: 0 | BS13: 1 | BT13: 0 | BU13: 1 | BV13: 1 | BW13: 1 | BX13: 0 | BY13: 1 | BZ13: 1 | CA13: 0 | CB13: 1 | CC13: 1
... A61: 341204 | B61: 339862 | C61: 338603 | D61: 339655 | E61: 335927 | F61: 332935 | G61: 330257 | H61: 332202 | I61: 334600 | J61: 329497 | K61: 338020 | L61: 332678 | M61: 338310 | N61: 326548 | O61: 335171 | P61: 317539 | Q61: 348332 | R61: 325144 | S61: 344742 | T61: 345191 | U61: 322174 | V61: 326353 | W61: 333222 | X61: 324958 | Y61: 328553 | Z61: 349236 | AA61: 328390 | AB61: 0 | AC61: 0 | AD61: 0 | AE61: 0 | AF61: 0 | AG61: 0 | AH61: 0 | AI61: 0 | AJ61: 0 | AK61: 0 | AL61: 0 | AM61: 0 | AN61: 0 | AO61: 0 | AP61: 0 | AQ61: 0 | AR61: 27 | AS61: 0 | AT61: 0 | AU61: 0 | AV61: 0 | AW61: 0 | AX61: 0 | AY61: 0 | AZ61: 0 | BA61: 0 | BB61: 0 | BC61: 0 | BD61: 1 | BE61: 0 | BF61: 1 | BG61: 0 | BH61: 1 | BI61: 0 | BJ61: 1 | BK61: 0 | BL61: 1 | BM61: 1 | BN61: 0 | BO61: 1 | BP61: 0 | BQ61: 1 | BR61: 1 | BS61: 1 | BT61: 0 | BU61: 1 | BV61: 1 | BW61: 1 | BX61: 1 | BY61: 1 | BZ61: 1 | CA61: 0 | CB61: 1 | CC61: 2

Sheet 4_50J
A1: 40_500_0.2 | B1: 40_800_0.2 | C1: 40_1000_0.2 | D1: 40_500_0.3 | E1: 40_800_0.3 | F1: 40_1000_0.3 | G1: 40_500_0.5 | H1: 40_800_0.5 | I1: 40_1000_0.5 | J1: 50_500_0.2 | K1: 50_800_0.2 | L1: 50_1000_0.2 | M1: 50_500_0.3 | N1: 50_800_0.3 | O1: 50_1000_0.3 | P1: 50_500_0.5 | Q1: 50_800_0.5 | R1: 50_1000_0.5 | S1: 70_500_0.2 | T1: 70_800_0.2 | U1: 70_1000_0.2 | V1: 70_500_0.3 | W1: 70_800_0.3 | X1: 70_1000_0.3 | Y1: 70_500_0.5 | Z1: 70_800_0.5 | AA1: 70_1000_0.5 | AB1: OVER_1 | AC1: OVER_2 | AD1: OVER_3 | AE1: OVER_4 | AF1: OVER_5 | AG1: OVER_6 | AH1: OVER_7 | AI1: OVER_8 | AJ1: OVER_9 | AK1: OVER_10 | AL1: OVER_11 | AM1: OVER_12 | AN1: OVER_13 | AO1: OVER_14 | AP1: OVER_15 | AQ1: OVER_16 | AR1: OVER_17 | AS1: OVER_18 | AT1: OVER_19 | AU1: OVER_20 | AV1: OVER_21 | AW1: OVER_22 | AX1: OVER_23 | AY1: OVER_24 | AZ1: OVER_25 | BA1: OVER_26 | BB1: OVER_27 | BC1: TIME_1 | BD1: TIME_2 | BE1: TIME_3 | BF1: TIME_4 | BG1: TIME_5 | BH1: TIME_6 | BI1: TIME_7 | BJ1: TIME_8 | BK1: TIME_9 | BL1: TIME_10 | BM1: TIME_11 | BN1: TIME_12 | BO1: TIME_13 | BP1: TIME_14 | BQ1: TIME_15 | BR1: TIME_16 | BS1: TIME_17 | BT1: TIME_18 | BU1: TIME_19 | BV1: TIME_20 | BW1: TIME_21 | BX1: TIME_22 | BY1: TIME_23 | BZ1: TIME_24 | CA1: TIME_25 | CB1: TIME_26 | CC1: TIME_27
A2: 334904 | B2: 342793 | C2: 328210 | D2: 316226 | E2: 328126 | F2: 293548 | G2: 320225 | H2: 302894 | I2: 315135 | J2: 340559 | K2: 325287 | L2: 316290 | M2: 340436 | N2: 324625 | O2: 341288 | P2: 331522 | Q2: 309674 | R2: 323264 | S2: 329165 | T2: 339365 | U2: 312691 | V2: 319187 | W2: 331986 | X2: 330049 | Y2: 307622 | Z2: 365608 | AA2: 325434 | AB2: 0 | AC2: 0 | AD2: 0 | AE2: 0 | AF2: 0 | AG2: 0 | AH2: 0 | AI2: 0 | AJ2: 0 | AK2: 0 | AL2: 0 | AM2: 0 | AN2: 0 | AO2: 0 | AP2: 0 | AQ2: 0 | AR2: 0 | AS2: 0 | AT2: 0 | AU2: 0 | AV2: 0 | AW2: 0 | AX2: 0 | AY2: 0 | AZ2: 0 | BA2: 43 | BB2: 0 | BC2: 0 | BD2: 0 | BE2: 1 | BF2: 0 | BG2: 1 | BH2: 0 | BI2: 1 | BJ2: 0 | BK2: 1 | BL2: 0 | BM2: 0 | BN2: 1 | BO2: 0 | BP2: 1 | BQ2: 1 | BR2: 0 | BS2: 1 | BT2: 1 | BU2: 0 | BV2: 1 | BW2: 1 | BX2: 0 | BY2: 1 | BZ2: 1 | CA2: 0 | CB2: 1 | CC2: 2
A3: 368430 | B3: 330089 | C3: 308056 | D3: 346641 | E3: 336182 | F3: 311698 | G3: 311593 | H3: 324259 | I3: 290101 | J3: 322135 | K3: 318377 | L3: 308963 | M3: 317208 | N3: 357026 | O3: 377937 | P3: 321710 | Q3: 328596 | R3: 320922 | S3: 337907 | T3: 318704 | U3: 330011 | V3: 317632 | W3: 346326 | X3: 322817 | Y3: 303799 | Z3: 342349 | AA3: 335117 | AB3: 32 | AC3: 0 | AD3: 0 | AE3: 15 | AF3: 0 | AG3: 0 | AH3: 0 | AI3: 0 | AJ3: 0 | AK3: 0 | AL3: 0 | AM3: 0 | AN3: 0 | AO3: 12 | AP3: 39 | AQ3: 0 | AR3: 0 | AS3: 0 | AT3: 12 | AU3: 0 | AV3: 0 | AW3: 0 | AX3: 23 | AY3: 0 | AZ3: 0 | BA3: 15 | BB3: 0 | BC3: 0 | BD3: 0 | BE3: 1 | BF3: 0 | BG3: 1 | BH3: 0 | BI3: 0 | BJ3: 1 | BK3: 1 | BL3: 0 | BM3: 0 | BN3: 1 | BO3: 0 | BP3: 1 | BQ3: 1 | BR3: 0 | BS3: 1 | BT3: 1 | BU3: 0 | BV3: 1 | BW3: 1 | BX3: 0 | BY3: 1 | BZ3: 1 | CA3: 1 | CB3: 1 | CC3: 1
A4: 356949 | B4: 339011 | C4: 357919 | D4: 356594 | E4: 358344 | F4: 353196 | G4: 389884 | H4: 360322 | I4: 347014 | J4: 365786 | K4: 367783 | L4: 352865 | M4: 405713 | N4: 350827 | O4: 375206 | P4: 365106 | Q4: 347247 | R4: 342950 | S4: 328796 | T4: 344502 | U4: 314540 | V4: 362616 | W4: 359262 | X4: 349493 | Y4: 379943 | Z4: 321572 | AA4: 336416 | AB4: 0 | AC4: 0 | AD4: 0 | AE4: 0 | AF4: 0 | AG4: 0 | AH4: 33 | AI4: 0 | AJ4: 16 | AK4: 19 | AL4: 0 | AM4: 0 | AN4: 33 | AO4: 0 | AP4: 23 | AQ4: 0 | AR4: 0 | AS4: 0 | AT4: 0 | AU4: 0 | AV4: 0 | AW4: 0 | AX4: 0 | AY4: 0 | AZ4: 38 | BA4: 0 | BB4: 0 | BC4: 0 | BD4: 0 | BE4: 1 | BF4: 0 | BG4: 1 | BH4: 0 | BI4: 1 | BJ4: 0 | BK4: 1 | BL4: 0 | BM4: 1 | BN4: 0 | BO4: 1 | BP4: 0 | BQ4: 1 | BR4: 0 | BS4: 1 | BT4: 1 | BU4: 0 | BV4: 1 | BW4: 1 | BX4: 0 | BY4: 1 | BZ4: 1 | CA4: 1 | CB4: 1 | CC4: 1
A5: 362914 | B5: 366126 | C5: 335000 | D5: 387862 | E5: 346321 | F5: 339522 | G5: 348526 | H5: 344829 | I5: 361282 | J5: 362375 | K5: 376512 | L5: 364561 | M5: 335461 | N5: 353498 | O5: 360748 | P5: 375008 | Q5: 361690 | R5: 337593 | S5: 368279 | T5: 351110 | U5: 406420 | V5: 347141 | W5: 343426 | X5: 348698 | Y5: 356340 | Z5: 405888 | AA5: 360339 | AB5: 0 | AC5: 0 | AD5: 0 | AE5: 0 | AF5: 0 | AG5: 0 | AH5: 0 | AI5: 0 | AJ5: 0 | AK5: 0 | AL5: 0 | AM5: 0 | AN5: 0 | AO5: 0 | AP5: 0 | AQ5: 0 | AR5: 0 | AS5: 0 | AT5: 0 | AU5: 0 | AV5: 45 | AW5: 0 | AX5: 0 | AY5: 0 | AZ5: 0 | BA5: 56 | BB5: 0 | BC5: 0 | BD5: 0 | BE5: 1 | BF5: 0 | BG5: 1 | BH5: 0 | BI5: 1 | BJ5: 0 | BK5: 1 | BL5: 0 | BM5: 1 | BN5: 0 | BO5: 1 | BP5: 0 | BQ5: 1 | BR5: 0 | BS5: 1 | BT5: 1 | BU5: 0 | BV5: 1 | BW5: 1 | BX5: 0 | BY5: 1 | BZ5: 1 | CA5: 1 | CB5: 1 | CC5: 1
A6: 332344 | B6: 350645 | C6: 332872 | D6: 339201 | E6: 328631 | F6: 339821 | G6: 335971 | H6: 341894 | I6: 317222 | J6: 308521 | K6: 294428 | L6: 299942 | M6: 331534 | N6: 328848 | O6: 336203 | P6: 310251 | Q6: 298594 | R6: 315742 | S6: 329198 | T6: 318075 | U6: 326751 | V6: 320104 | W6: 330554 | X6: 326002 | Y6: 336325 | Z6: 333594 | AA6: 332161 | AB6: 0 | AC6: 0 | AD6: 0 | AE6: 0 | AF6: 0 | AG6: 0 | AH6: 0 | AI6: 0 | AJ6: 0 | AK6: 0 | AL6: 0 | AM6: 0 | AN6: 0 | AO6: 0 | AP6: 7 | AQ6: 0 | AR6: 0 | AS6: 0 | AT6: 0 | AU6: 0 | AV6: 11 | AW6: 0 | AX6: 0 | AY6: 0 | AZ6: 0 | BA6: 1 | BB6: 0 | BC6: 0 | BD6: 1 | BE6: 0 | BF6: 0 | BG6: 1 | BH6: 0 | BI6: 1 | BJ6: 0 | BK6: 1 | BL6: 0 | BM6: 1 | BN6: 0 | BO6: 1 | BP6: 0 | BQ6: 1 | BR6: 0 | BS6: 1 | BT6: 1 | BU6: 0 | BV6: 1 | BW6: 1 | BX6: 0 | BY6: 1 | BZ6: 1 | CA6: 1 | CB6: 1 | CC6: 1
A7: 386256 | B7: 385152 | C7: 389799 | D7: 393624 | E7: 386107 | F7: 387356 | G7: 462067 | H7: 390769 | I7: 443255 | J7: 378248 | K7: 384121 | L7: 360643 | M7: 380885 | N7: 354594 | O7: 383491 | P7: 375800 | Q7: 370020 | R7: 376024 | S7: 372496 | T7: 369345 | U7: 408320 | V7: 362009 | W7: 358375 | X7: 380441 | Y7: 399123 | Z7: 383746 | AA7: 366583 | AB7: 0 | AC7: 0 | AD7: 0 | AE7: 0 | AF7: 0 | AG7: 0 | AH7: 85 | AI7: 0 | AJ7: 66 | AK7: 0 | AL7: 0 | AM7: 0 | AN7: 0 | AO7: 0 | AP7: 15 | AQ7: 0 | AR7: 0 | AS7: 0 | AT7: 12 | AU7: 0 | AV7: 0 | AW7: 0 | AX7: 0 | AY7: 0 | AZ7: 12 | BA7: 0 | BB7: 0 | BC7: 0 | BD7: 1 | BE7: 0 | BF7: 0 | BG7: 1 | BH7: 0 | BI7: 1 | BJ7: 0 | BK7: 1 | BL7: 0 | BM7: 1 | BN7: 0 | BO7: 1 | BP7: 0 | BQ7: 1 | BR7: 1 | BS7: 0 | BT7: 1 | BU7: 0 | BV7: 1 | BW7: 1 | BX7: 1 | BY7: 0 | BZ7: 1 | CA7: 1 | CB7: 1 | CC7: 1
A8: 402277 | B8: 368740 | C8: 394491 | D8: 407838 | E8: 363901 | F8: 374371 | G8: 383418 | H8: 394511 | I8: 368026 | J8: 384654 | K8: 413899 | L8: 422508 | M8: 393215 | N8: 389905 | O8: 387794 | P8: 416145 | Q8: 374078 | R8: 416109 | S8: 396237 | T8: 385840 | U8: 389370 | V8: 394012 | W8: 379609 | X8: 373553 | Y8: 394362 | Z8: 410515 | AA8: 416035 | AB8: 0 | AC8: 0 | AD8: 0 | AE8: 0 | AF8: 0 | AG8: 0 | AH8: 0 | AI8: 0 | AJ8: 0 | AK8: 0 | AL8: 0 | AM8: 0 | AN8: 0 | AO8: 0 | AP8: 3 | AQ8: 39 | AR8: 0 | AS8: 0 | AT8: 0 | AU8: 0 | AV8: 0 | AW8: 0 | AX8: 0 | AY8: 0 | AZ8: 0 | BA8: 0 | BB8: 29 | BC8: 0 | BD8: 1 | BE8: 0 | BF8: 0 | BG8: 1 | BH8: 0 | BI8: 1 | BJ8: 0 | BK8: 1 | BL8: 0 | BM8: 1 | BN8: 0 | BO8: 1 | BP8: 0 | BQ8: 1 | BR8: 0 | BS8: 1 | BT8: 1 | BU8: 0 | BV8: 1 | BW8: 1 | BX8: 0 | BY8: 1 | BZ8: 1 | CA8: 1 | CB8: 1 | CC8: 1
A9: 340302 | B9: 342711 | C9: 336413 | D9: 316346 | E9: 297532 | F9: 326516 | G9: 342986 | H9: 325816 | I9: 310954 | J9: 329470 | K9: 315748 | L9: 324971 | M9: 306778 | N9: 332304 | O9: 316451 | P9: 331482 | Q9: 306487 | R9: 298819 | S9: 327284 | T9: 348203 | U9: 340079 | V9: 324146 | W9: 330990 | X9: 311060 | Y9: 298564 | Z9: 334510 | AA9: 303610 | AB9: 0 | AC9: 0 | AD9: 13 | AE9: 0 | AF9: 0 | AG9: 0 | AH9: 0 | AI9: 0 | AJ9: 0 | AK9: 10 | AL9: 0 | AM9: 0 | AN9: 0 | AO9: 0 | AP9: 0 | AQ9: 0 | AR9: 0 | AS9: 0 | AT9: 0 | AU9: 0 | AV9: 17 | AW9: 0 | AX9: 0 | AY9: 0 | AZ9: 0 | BA9: 0 | BB9: 0 | BC9: 0 | BD9: 0 | BE9: 1 | BF9: 0 | BG9: 1 | BH9: 0 | BI9: 1 | BJ9: 0 | BK9: 1 | BL9: 0 | BM9: 1 | BN9: 0 | BO9: 1 | BP9: 0 | BQ9: 1 | BR9: 0 | BS9: 1 | BT9: 1 | BU9: 0 | BV9: 1 | BW9: 1 | BX9: 0 | BY9: 1 | BZ9: 1 | CA9: 1 | CB9: 1 | CC9: 1
A10: 387196 | B10: 368571 | C10: 503964 | D10: 342224 | E10: 356170 | F10: 375219 | G10: 377385 | H10: 350081 | I10: 347185 | J10: 369993 | K10: 377660 | L10: 401639 | M10: 395027 | N10: 348099 | O10: 357954 | P10: 384866 | Q10: 360338 | R10: 345670 | S10: 369388 | T10: 374317 | U10: 357254 | V10: 350892 | W10: 357921 | X10: 393846 | Y10: 375341 | Z10: 342968 | AA10: 350434 | AB10: 0 | AC10: 0 | AD10: 120 | AE10: 0 | AF10: 0 | AG10: 0 | AH10: 0 | AI10: 0 | AJ10: 0 | AK10: 0 | AL10: 0 | AM10: 53 | AN10: 0 | AO10: 0 | AP10: 0 | AQ10: 0 | AR10: 0 | AS10: 0 | AT10: 0 | AU10: 0 | AV10: 0 | AW10: 0 | AX10: 0 | AY10: 0 | AZ10: 0 | BA10: 0 | BB10: 0 | BC10: 0 | BD10: 0 | BE10: 1 | BF10: 0 | BG10: 1 | BH10: 0 | BI10: 1 | BJ10: 0 | BK10: 1 | BL10: 0 | BM10: 1 | BN10: 0 | BO10: 1 | BP10: 0 | BQ10: 1 | BR10: 0 | BS10: 1 | BT10: 1 | BU10: 0 | BV10: 1 | BW10: 1 | BX10: 0 | BY10: 1 | BZ10: 1 | CA10: 1 | CB10: 0 | CC10: 2
A11: 400139 | B11: 350514 | C11: 355518 | D11: 373919 | E11: 401364 | F11: 358761 | G11: 357593 | H11: 356600 | I11: 338375 | J11: 383352 | K11: 352636 | L11: 353395 | M11: 360179 | N11: 341782 | O11: 355564 | P11: 371112 | Q11: 337438 | R11: 345691 | S11: 366818 | T11: 389789 | U11: 401036 | V11: 363943 | W11: 352080 | X11: 373475 | Y11: 349393 | Z11: 355724 | AA11: 354450 | AB11: 0 | AC11: 0 | AD11: 0 | AE11: 0 | AF11: 29 | AG11: 0 | AH11: 0 | AI11: 0 | AJ11: 0 | AK11: 0 | AL11: 0 | AM11: 0 | AN11: 0 | AO11: 0 | AP11: 0 | AQ11: 0 | AR11: 0 | AS11: 0 | AT11: 0 | AU11: 0 | AV11: 41 | AW11: 0 | AX11: 0 | AY11: 0 | AZ11: 0 | BA11: 0 | BB11: 0 | BC11: 0 | BD11: 0 | BE11: 1 | BF11: 0 | BG11: 1 | BH11: 0 | BI11: 0 | BJ11: 1 | BK11: 1 | BL11: 0 | BM11: 0 | BN11: 1 | BO11: 0 | BP11: 1 | BQ11: 1 | BR11: 0 | BS11: 1 | BT11: 0 | BU11: 1 | BV11: 1 | BW11: 1 | BX11: 0 | BY11: 1 | BZ11: 1 | CA11: 0 | CB11: 1 | CC11: 1
A12: 406143 | B12: 424920 | C12: 434163 | D12: 445417 | E12: 397147 | F12: 398578 | G12: 400691 | H12: 411441 | I12: 412240 | J12: 406190 | K12: 395406 | L12: 425630 | M12: 395466 | N12: 388305 | O12: 420127 | P12: 412147 | Q12: 382714 | R12: 393699 | S12: 414368 | T12: 414214 | U12: 403650 | V12: 400205 | W12: 407472 | X12: 390581 | Y12: 434712 | Z12: 421787 | AA12: 389010 | AB12: 0 | AC12: 0 | AD12: 0 | AE12: 0 | AF12: 0 | AG12: 0 | AH12: 0 | AI12: 0 | AJ12: 0 | AK12: 0 | AL12: 0 | AM12: 0 | AN12: 0 | AO12: 0 | AP12: 0 | AQ12: 0 | AR12: 0 | AS12: 0 | AT12: 0 | AU12: 0 | AV12: 0 | AW12: 0 | AX12: 0 | AY12: 0 | AZ12: 0 | BA12: 0 | BB12: 0 | BC12: 1 | BD12: 0 | BE12: 1 | BF12: 0 | BG12: 0 | BH12: 1 | BI12: 0 | BJ12: 1 | BK12: 0 | BL12: 1 | BM12: 0 | BN12: 1 | BO12: 0 | BP12: 1 | BQ12: 0 | BR12: 1 | BS12: 0 | BT12: 1 | BU12: 1 | BV12: 0 | BW12: 1 | BX12: 1 | BY12: 0 | BZ12: 1 | CA12: 1 | CB12: 1 | CC12: 1
A13: 374261 | B13: 355753 | C13: 359340 | D13: 355949 | E13: 344830 | F13: 360651 | G13: 347246 | H13: 351557 | I13: 344572 | J13: 361013 | K13: 378946 | L13: 355011 | M13: 369016 | N13: 382538 | O13: 344780 | P13: 351527 | Q13: 345803 | R13: 362436 | S13: 337645 | T13: 340727 | U13: 368258 | V13: 354956 | W13: 358048 | X13: 368714 | Y13: 351326 | Z13: 362557 | AA13: 382826 | AB13: 0 | AC13: 0 | AD13: 0 | AE13: 0 | AF13: 0 | AG13: 0 | AH13: 0 | AI13: 0 | AJ13: 0 | AK13: 0 | AL13: 0 | AM13: 0 | AN13: 0 | AO13: 0 | AP13: 0 | AQ13: 0 | AR13: 0 | AS13: 0 | AT13: 0 | AU13: 0 | AV13: 0 | AW13: 0 | AX13: 0 | AY13: 0 | AZ13: 0 | BA13: 0 | BB13: 0 | BC13: 0 | BD13: 1 | BE13: 0 | BF13: 0 | BG13: 1 | BH13: 0 | BI13: 1 | BJ13: 0 | BK13: 1 | BL13: 0 | BM13: 1 | BN13: 0 | BO13: 1 | BP13: 0 | BQ13: 1 | BR13: 0 | BS13: 1 | BT13: 1 | BU13: 0 | BV13: 1 | BW13: 1 | BX13: 0 | BY13: 1 | BZ13: 1 | CA13: 1 | CB13: 0 | CC13: 2
... A61: 363968 | B61: 330583 | C61: 329102 | D61: 328634 | E61: 335478 | F61: 326069 | G61: 335601 | H61: 334966 | I61: 330912 | J61: 337999 | K61: 327723 | L61: 332589 | M61: 345331 | N61: 312702 | O61: 318031 | P61: 325798 | Q61: 326596 | R61: 328233 | S61: 332545 | T61: 338242 | U61: 325960 | V61: 333053 | W61: 322337 | X61: 332745 | Y61: 333783 | Z61: 324000 | AA61: 323963 | AB61: 33 | AC61: 0 | AD61: 0 | AE61: 0 | AF61: 0 | AG61: 0 | AH61: 0 | AI61: 0 | AJ61: 0 | AK61: 0 | AL61: 0 | AM61: 0 | AN61: 0 | AO61: 0 | AP61: 0 | AQ61: 0 | AR61: 0 | AS61: 0 | AT61: 0 | AU61: 0 | AV61: 0 | AW61: 0 | AX61: 0 | AY61: 0 | AZ61: 0 | BA61: 0 | BB61: 0 | BC61: 1 | BD61: 0 | BE61: 1 | BF61: 0 | BG61: 1 | BH61: 0 | BI61: 1 | BJ61: 0 | BK61: 1 | BL61: 1 | BM61: 0 | BN61: 1 | BO61: 0 | BP61: 1 | BQ61: 1 | BR61: 0 | BS61: 1 | BT61: 1 | BU61: 1 | BV61: 1 | BW61: 1 | BX61: 0 | BY61: 1 | BZ61: 1 | CA61: 1 | CB61: 1 | CC61: 1

Sheet 5_50J
A1: 40_500_0.2 | B1: 40_800_0.2 | C1: 40_1000_0.2 | D1: 40_500_0.3 | E1: 40_800_0.3 | F1: 40_1000_0.3 | G1: 40_500_0.5 | H1: 40_800_0.5 | I1: 40_1000_0.5 | J1: 50_500_0.2 | K1: 50_800_0.2 | L1: 50_1000_0.2 | M1: 50_500_0.3 | N1: 50_800_0.3 | O1: 50_1000_0.3 | P1: 50_500_0.5 | Q1: 50_800_0.5 | R1: 50_1000_0.5 | S1: 70_500_0.2 | T1: 70_800_0.2 | U1: 70_1000_0.2 | V1: 70_500_0.3 | W1: 70_800_0.3 | X1: 70_1000_0.3 | Y1: 70_500_0.5 | Z1: 70_800_0.5 | AA1: 70_1000_0.5 | AB1: OVER_1 | AC1: OVER_2 | AD1: OVER_3 | AE1: OVER_4 | AF1: OVER_5 | AG1: OVER_6 | AH1: OVER_7 | AI1: OVER_8 | AJ1: OVER_9 | AK1: OVER_10 | AL1: OVER_11 | AM1: OVER_12 | AN1: OVER_13 | AO1: OVER_14 | AP1: OVER_15 | AQ1: OVER_16 | AR1: OVER_17 | AS1: OVER_18 | AT1: OVER_19 | AU1: OVER_20 | AV1: OVER_21 | AW1: OVER_22 | AX1: OVER_23 | AY1: OVER_24 | AZ1: OVER_25 | BA1: OVER_26 | BB1: OVER_27 | BC1: TIME_1 | BD1: TIME_2 | BE1: TIME_3 | BF1: TIME_4 | BG1: TIME_5 | BH1: TIME_6 | BI1: TIME_7 | BJ1: TIME_8 | BK1: TIME_9 | BL1: TIME_10 | BM1: TIME_11 | BN1: TIME_12 | BO1: TIME_13 | BP1: TIME_14 | BQ1: TIME_15 | BR1: TIME_16 | BS1: TIME_17 | BT1: TIME_18 | BU1: TIME_19 | BV1: TIME_20 | BW1: TIME_21 | BX1: TIME_22 | BY1: TIME_23 | BZ1: TIME_24 | CA1: TIME_25 | CB1: TIME_26 | CC1: TIME_27
A2: 353921 | B2: 377712 | C2: 343983 | D2: 312334 | E2: 331887 | F2: 322919 | G2: 321823 | H2: 301496 | I2: 306853 | J2: 315140 | K2: 318516 | L2: 362446 | M2: 313572 | N2: 314308 | O2: 293476 | P2: 323989 | Q2: 325526 | R2: 310640 | S2: 310502 | T2: 316240 | U2: 302924 | V2: 334123 | W2: 326276 | X2: 312613 | Y2: 329179 | Z2: 330090 | AA2: 311864 | AB2: 0 | AC2: 56 | AD2: 0 | AE2: 0 | AF2: 0 | AG2: 0 | AH2: 0 | AI2: 0 | AJ2: 0 | AK2: 0 | AL2: 0 | AM2: 0 | AN2: 0 | AO2: 0 | AP2: 0 | AQ2: 0 | AR2: 0 | AS2: 0 | AT2: 0 | AU2: 1 | AV2: 0 | AW2: 0 | AX2: 0 | AY2: 0 | AZ2: 0 | BA2: 0 | BB2: 0 | BC2: 1 | BD2: 0 | BE2: 1 | BF2: 0 | BG2: 0 | BH2: 1 | BI2: 0 | BJ2: 1 | BK2: 0 | BL2: 1 | BM2: 0 | BN2: 1 | BO2: 0 | BP2: 1 | BQ2: 1 | BR2: 0 | BS2: 1 | BT2: 0 | BU2: 1 | BV2: 1 | BW2: 0 | BX2: 1 | BY2: 1 | BZ2: 1 | CA2: 0 | CB2: 1 | CC2: 1
A3: 342957 | B3: 331373 | C3: 333812 | D3: 340847 | E3: 338830 | F3: 321822 | G3: 316478 | H3: 319179 | I3: 316587 | J3: 313372 | K3: 327296 | L3: 333119 | M3: 325972 | N3: 351272 | O3: 304670 | P3: 313256 | Q3: 324998 | R3: 321543 | S3: 294932 | T3: 326781 | U3: 325419 | V3: 357144 | W3: 347516 | X3: 319761 | Y3: 292635 | Z3: 316757 | AA3: 305528 | AB3: 0 | AC3: 20 | AD3: 21 | AE3: 6 | AF3: 0 | AG3: 0 | AH3: 0 | AI3: 0 | AJ3: 0 | AK3: 0 | AL3: 0 | AM3: 0 | AN3: 0 | AO3: 31 | AP3: 0 | AQ3: 0 | AR3: 0 | AS3: 0 | AT3: 0 | AU3: 0 | AV3: 0 | AW3: 38 | AX3: 17 | AY3: 0 | AZ3: 0 | BA3: 0 | BB3: 0 | BC3: 0 | BD3: 1 | BE3: 1 | BF3: 0 | BG3: 0 | BH3: 1 | BI3: 0 | BJ3: 1 | BK3: 0 | BL3: 1 | BM3: 0 | BN3: 1 | BO3: 0 | BP3: 1 | BQ3: 1 | BR3: 0 | BS3: 1 | BT3: 0 | BU3: 1 | BV3: 0 | BW3: 1 | BX3: 1 | BY3: 1 | BZ3: 1 | CA3: 0 | CB3: 1 | CC3: 1
A4: 359028 | B4: 340842 | C4: 348489 | D4: 337887 | E4: 358395 | F4: 337949 | G4: 360076 | H4: 378375 | I4: 335848 | J4: 380670 | K4: 355444 | L4: 383213 | M4: 419072 | N4: 345643 | O4: 352650 | P4: 330273 | Q4: 341992 | R4: 328921 | S4: 336376 | T4: 324470 | U4: 334995 | V4: 332818 | W4: 362376 | X4: 319068 | Y4: 373884 | Z4: 364540 | AA4: 347940 | AB4: 0 | AC4: 0 | AD4: 0 | AE4: 0 | AF4: 19 | AG4: 0 | AH4: 0 | AI4: 33 | AJ4: 0 | AK4: 0 | AL4: 0 | AM4: 0 | AN4: 63 | AO4: 0 | AP4: 0 | AQ4: 0 | AR4: 0 | AS4: 0 | AT4: 0 | AU4: 0 | AV4: 0 | AW4: 0 | AX4: 0 | AY4: 0 | AZ4: 10 | BA4: 0 | BB4: 0 | BC4: 1 | BD4: 0 | BE4: 1 | BF4: 0 | BG4: 0 | BH4: 1 | BI4: 0 | BJ4: 1 | BK4: 0 | BL4: 1 | BM4: 0 | BN4: 1 | BO4: 0 | BP4: 1 | BQ4: 0 | BR4: 1 | BS4: 1 | BT4: 0 | BU4: 1 | BV4: 0 | BW4: 1 | BX4: 1 | BY4: 1 | BZ4: 1 | CA4: 0 | CB4: 1 | CC4: 1
A5: 375649 | B5: 381079 | C5: 362582 | D5: 348918 | E5: 364568 | F5: 362360 | G5: 363563 | H5: 370527 | I5: 368227 | J5: 351698 | K5: 365735 | L5: 355246 | M5: 355591 | N5: 363750 | O5: 371754 | P5: 357621 | Q5: 354314 | R5: 401556 | S5: 360070 | T5: 367518 | U5: 372205 | V5: 350837 | W5: 354269 | X5: 346229 | Y5: 352015 | Z5: 335074 | AA5: 350962 | AB5: 0 | AC5: 24 | AD5: 0 | AE5: 0 | AF5: 0 | AG5: 16 | AH5: 0 | AI5: 0 | AJ5: 0 | AK5: 0 | AL5: 0 | AM5: 0 | AN5: 0 | AO5: 0 | AP5: 26 | AQ5: 0 | AR5: 0 | AS5: 60 | AT5: 0 | AU5: 0 | AV5: 0 | AW5: 0 | AX5: 0 | AY5: 0 | AZ5: 0 | BA5: 0 | BB5: 0 | BC5: 0 | BD5: 1 | BE5: 1 | BF5: 0 | BG5: 0 | BH5: 1 | BI5: 0 | BJ5: 1 | BK5: 0 | BL5: 1 | BM5: 0 | BN5: 1 | BO5: 0 | BP5: 1 | BQ5: 1 | BR5: 0 | BS5: 1 | BT5: 0 | BU5: 1 | BV5: 1 | BW5: 1 | BX5: 0 | BY5: 1 | BZ5: 1 | CA5: 0 | CB5: 1 | CC5: 1
A6: 373560 | B6: 330417 | C6: 343923 | D6: 325718 | E6: 319260 | F6: 326380 | G6: 337647 | H6: 321362 | I6: 343405 | J6: 351464 | K6: 348178 | L6: 324079 | M6: 338552 | N6: 327806 | O6: 323644 | P6: 296492 | Q6: 343096 | R6: 317614 | S6: 319611 | T6: 309850 | U6: 317854 | V6: 324918 | W6: 347205 | X6: 327951 | Y6: 342398 | Z6: 343686 | AA6: 305395 | AB6: 14 | AC6: 0 | AD6: 17 | AE6: 0 | AF6: 0 | AG6: 0 | AH6: 0 | AI6: 0 | AJ6: 0 | AK6: 0 | AL6: 23 | AM6: 0 | AN6: 0 | AO6: 0 | AP6: 0 | AQ6: 0 | AR6: 0 | AS6: 0 | AT6: 0 | AU6: 0 | AV6: 0 | AW6: 0 | AX6: 0 | AY6: 0 | AZ6: 11 | BA6: 0 | BB6: 0 | BC6: 1 | BD6: 0 | BE6: 1 | BF6: 0 | BG6: 0 | BH6: 1 | BI6: 0 | BJ6: 1 | BK6: 0 | BL6: 1 | BM6: 0 | BN6: 1 | BO6: 0 | BP6: 1 | BQ6: 1 | BR6: 0 | BS6: 1 | BT6: 0 | BU6: 1 | BV6: 1 | BW6: 0 | BX6: 1 | BY6: 1 | BZ6: 1 | CA6: 0 | CB6: 1 | CC6: 1
A7: 425299 | B7: 401562 | C7: 422969 | D7: 392722 | E7: 400041 | F7: 388743 | G7: 352115 | H7: 379548 | I7: 399957 | J7: 369292 | K7: 380369 | L7: 395910 | M7: 354272 | N7: 377348 | O7: 368563 | P7: 395019 | Q7: 418723 | R7: 386997 | S7: 388454 | T7: 382944 | U7: 388166 | V7: 387921 | W7: 389057 | X7: 377419 | Y7: 383225 | Z7: 365349 | AA7: 382535 | AB7: 15 | AC7: 9 | AD7: 0 | AE7: 0 | AF7: 0 | AG7: 0 | AH7: 0 | AI7: 0 | AJ7: 0 | AK7: 0 | AL7: 0 | AM7: 12 | AN7: 0 | AO7: 32 | AP7: 0 | AQ7: 0 | AR7: 31 | AS7: 18 | AT7: 0 | AU7: 0 | AV7: 26 | AW7: 0 | AX7: 18 | AY7: 0 | AZ7: 0 | BA7: 0 | BB7: 0 | BC7: 1 | BD7: 0 | BE7: 1 | BF7: 0 | BG7: 0 | BH7: 1 | BI7: 0 | BJ7: 1 | BK7: 0 | BL7: 1 | BM7: 0 | BN7: 1 | BO7: 0 | BP7: 1 | BQ7: 1 | BR7: 0 | BS7: 1 | BT7: 1 | BU7: 0 | BV7: 1 | BW7: 1 | BX7: 0 | BY7: 1 | BZ7: 1 | CA7: 1 | CB7: 1 | CC7: 1
A8: 437913 | B8: 387918 | C8: 369863 | D8: 402489 | E8: 404759 | F8: 389753 | G8: 368565 | H8: 383422 | I8: 389272 | J8: 393152 | K8: 389242 | L8: 365362 | M8: 373670 | N8: 387816 | O8: 394485 | P8: 366568 | Q8: 403010 | R8: 388257 | S8: 402443 | T8: 373960 | U8: 379863 | V8: 403717 | W8: 371087 | X8: 388242 | Y8: 373910 | Z8: 381368 | AA8: 371106 | AB8: 39 | AC8: 0 | AD8: 0 | AE8: 0 | AF8: 0 | AG8: 0 | AH8: 0 | AI8: 0 | AJ8: 0 | AK8: 0 | AL8: 0 | AM8: 0 | AN8: 0 | AO8: 0 | AP8: 0 | AQ8: 0 | AR8: 0 | AS8: 0 | AT8: 0 | AU8: 0 | AV8: 0 | AW8: 0 | AX8: 0 | AY8: 0 | AZ8: 0 | BA8: 0 | BB8: 0 | BC8: 0 | BD8: 0 | BE8: 1 | BF8: 0 | BG8: 1 | BH8: 0 | BI8: 1 | BJ8: 0 | BK8: 1 | BL8: 0 | BM8: 1 | BN8: 0 | BO8: 1 | BP8: 0 | BQ8: 1 | BR8: 0 | BS8: 1 | BT8: 1 | BU8: 0 | BV8: 1 | BW8: 1 | BX8: 0 | BY8: 1 | BZ8: 1 | CA8: 0 | CB8: 1 | CC8: 1
A9: 324286 | B9: 314744 | C9: 331515 | D9: 310244 | E9: 307865 | F9: 334879 | G9: 320578 | H9: 318089 | I9: 321535 | J9: 315334 | K9: 371121 | L9: 317273 | M9: 320470 | N9: 311266 | O9: 333178 | P9: 307500 | Q9: 295276 | R9: 319426 | S9: 332511 | T9: 319271 | U9: 315392 | V9: 343104 | W9: 328554 | X9: 334925 | Y9: 320897 | Z9: 307332 | AA9: 307254 | AB9: 0 | AC9: 0 | AD9: 0 | AE9: 0 | AF9: 0 | AG9: 0 | AH9: 0 | AI9: 0 | AJ9: 25 | AK9: 0 | AL9: 25 | AM9: 0 | AN9: 0 | AO9: 0 | AP9: 0 | AQ9: 0 | AR9: 0 | AS9: 0 | AT9: 0 | AU9: 0 | AV9: 0 | AW9: 18 | AX9: 0 | AY9: 23 | AZ9: 1 | BA9: 0 | BB9: 0 | BC9: 1 | BD9: 0 | BE9: 1 | BF9: 0 | BG9: 0 | BH9: 1 | BI9: 0 | BJ9: 1 | BK9: 0 | BL9: 1 | BM9: 0 | BN9: 1 | BO9: 0 | BP9: 1 | BQ9: 1 | BR9: 0 | BS9: 1 | BT9: 0 | BU9: 1 | BV9: 1 | BW9: 1 | BX9: 0 | BY9: 1 | BZ9: 1 | CA9: 1 | CB9: 1 | CC9: 1
A10: 408308 | B10: 366454 | C10: 372048 | D10: 377644 | E10: 371281 | F10: 370140 | G10: 364900 | H10: 369849 | I10: 366496 | J10: 359791 | K10: 362810 | L10: 346467 | M10: 382629 | N10: 385457 | O10: 364318 | P10: 350374 | Q10: 413193 | R10: 440305 | S10: 385602 | T10: 360223 | U10: 352636 | V10: 371148 | W10: 363843 | X10: 353314 | Y10: 359718 | Z10: 338980 | AA10: 354514 | AB10: 0 | AC10: 6 | AD10: 0 | AE10: 0 | AF10: 0 | AG10: 0 | AH10: 0 | AI10: 0 | AJ10: 0 | AK10: 11 | AL10: 0 | AM10: 0 | AN10: 0 | AO10: 10 | AP10: 0 | AQ10: 0 | AR10: 44 | AS10: 75 | AT10: 0 | AU10: 0 | AV10: 0 | AW10: 0 | AX10: 0 | AY10: 0 | AZ10: 0 | BA10: 0 | BB10: 0 | BC10: 0 | BD10: 0 | BE10: 1 | BF10: 0 | BG10: 1 | BH10: 0 | BI10: 0 | BJ10: 1 | BK10: 1 | BL10: 0 | BM10: 0 | BN10: 1 | BO10: 0 | BP10: 1 | BQ10: 1 | BR10: 0 | BS10: 1 | BT10: 1 | BU10: 0 | BV10: 1 | BW10: 1 | BX10: 0 | BY10: 1 | BZ10: 1 | CA10: 1 | CB10: 1 | CC10: 1
