Workbook
Name _1_FINAL_ILS_PROP_OBJ_F_8jobs: GA_LS!$A$2:$B$301
Name _1_FINAL_ILS_PROP_OBJ_F_8jobs: ILS_RVND_1!$A$2:$B$301
Name _1_FINAL_ILS_PROP_OBJ_F_8jobs: ILS_RVND_2!$A$2:$B$301
Name _1_FINAL_ILS_PROP_OBJ_F_8jobs_1: GA_LS!$A$302:$B$601
Name _1_FINAL_ILS_PROP_OBJ_F_8jobs_1: ILS_RVND_1!$A$302:$B$601
Name _1_FINAL_ILS_PROP_OBJ_F_8jobs_1: ILS_RVND_2!$A$302:$B$601
Name _1_FINAL_ILS_PROP_OBJ_F_8jobs_2: GA_LS!$A$602:$B$901
Name _1_FINAL_ILS_PROP_OBJ_F_8jobs_2: ILS_RVND_1!$A$602:$B$901
Name _1_FINAL_ILS_PROP_OBJ_F_8jobs_2: ILS_RVND_2!$A$602:$B$901
Name _2_FINAL_ILS_PROP_OBJ_F_10jobs: GA_LS!$C$2:$D$301
Name _2_FINAL_ILS_PROP_OBJ_F_10jobs: ILS_RVND_1!$C$2:$D$301
Name _2_FINAL_ILS_PROP_OBJ_F_10jobs: ILS_RVND_2!$C$2:$D$301
Name _2_FINAL_ILS_PROP_OBJ_F_10jobs_1: GA_LS!$C$302:$D$601
Name _2_FINAL_ILS_PROP_OBJ_F_10jobs_1: ILS_RVND_1!$C$302:$D$601
Name _2_FINAL_ILS_PROP_OBJ_F_10jobs_1: ILS_RVND_2!$C$302:$D$601
Name _2_FINAL_ILS_PROP_OBJ_F_10jobs_2: GA_LS!$C$602:$D$901
Name _2_FINAL_ILS_PROP_OBJ_F_10jobs_2: ILS_RVND_1!$C$602:$D$901
Name _2_FINAL_ILS_PROP_OBJ_F_10jobs_2: ILS_RVND_2!$C$602:$D$901
Name _3_FINAL_ILS_PROP_OBJ_F_10jobs: GA_LS!$E$2:$F$301
Name _3_FINAL_ILS_PROP_OBJ_F_10jobs: ILS_RVND_1!$E$2:$F$301
Name _3_FINAL_ILS_PROP_OBJ_F_10jobs: ILS_RVND_2!$E$2:$F$301
Name _3_FINAL_ILS_PROP_OBJ_F_10jobs_1: GA_LS!$E$302:$F$601
Name _3_FINAL_ILS_PROP_OBJ_F_10jobs_1: ILS_RVND_1!$E$302:$F$601
Name _3_FINAL_ILS_PROP_OBJ_F_10jobs_1: ILS_RVND_2!$E$302:$F$601
Name _3_FINAL_ILS_PROP_OBJ_F_10jobs_2: GA_LS!$E$602:$F$901
Name _3_FINAL_ILS_PROP_OBJ_F_10jobs_2: ILS_RVND_1!$E$602:$F$901
Name _3_FINAL_ILS_PROP_OBJ_F_10jobs_2: ILS_RVND_2!$E$602:$F$901
Name _4_FINAL_ILS_PROP_OBJ_F_10jobs: GA_LS!$G$2:$H$301
Name _4_FINAL_ILS_PROP_OBJ_F_10jobs: ILS_RVND_1!$G$2:$H$301
Name _4_FINAL_ILS_PROP_OBJ_F_10jobs: ILS_RVND_2!$G$2:$H$301
Name _4_FINAL_ILS_PROP_OBJ_F_10jobs_1: GA_LS!$G$302:$H$601
Name _4_FINAL_ILS_PROP_OBJ_F_10jobs_1: ILS_RVND_1!$G$302:$H$601
Name _4_FINAL_ILS_PROP_OBJ_F_10jobs_1: ILS_RVND_2!$G$302:$H$601
Name _4_FINAL_ILS_PROP_OBJ_F_10jobs_2: GA_LS!$G$602:$H$901
Name _4_FINAL_ILS_PROP_OBJ_F_10jobs_2: ILS_RVND_1!$G$602:$H$901
Name _4_FINAL_ILS_PROP_OBJ_F_10jobs_2: ILS_RVND_2!$G$602:$H$901
Name _5_FINAL_ILS_PROP_OBJ_F_10jobs: GA_LS!$I$2:$J$301
Name _5_FINAL_ILS_PROP_OBJ_F_10jobs: ILS_RVND_1!$I$2:$J$301
Name _5_FINAL_ILS_PROP_OBJ_F_10jobs: ILS_RVND_2!$I$2:$J$301
Name _5_FINAL_ILS_PROP_OBJ_F_10jobs_1: GA_LS!$I$302:$J$601
Name _5_FINAL_ILS_PROP_OBJ_F_10jobs_1: ILS_RVND_1!$I$302:$J$601
Name _5_FINAL_ILS_PROP_OBJ_F_10jobs_1: ILS_RVND_2!$I$302:$J$601
Name _5_FINAL_ILS_PROP_OBJ_F_10jobs_2: GA_LS!$I$602:$J$901
Name _5_FINAL_ILS_PROP_OBJ_F_10jobs_2: ILS_RVND_1!$I$602:$J$901
Name _5_FINAL_ILS_PROP_OBJ_F_10jobs_2: ILS_RVND_2!$I$602:$J$901
Name SCPLEX_10: 'Average RPD of all algorithms'!$A$3:$A$302
Name SCPLEX_15: 'Average RPD of all algorithms'!$A$303:$A$602
Name SCPLEX_20: 'Average RPD of all algorithms'!$A$603:$A$902

Sheet ILS_RVND_1
A1: Data Result Obj Function (5 rounds) | L1: Average: | M1: Best:
A2: 1 | B2: 12238.1 | C2: 1 | D2: 12238.1 | E2: 1 | F2: 12238.1 | G2: 1 | H2: 12238.1 | I2: 1 | J2: 12238.1 | L2: =(SUM(B2,D2,F2,H2,J2 )/5) -> 12238.1 | M2: =MIN(B2,D2,F2,H2,J2) -> 12238.1
A3: 2 | B3: 11473.8 | C3: 2 | D3: 11473.8 | E3: 2 | F3: 11473.8 | G3: 2 | H3: 11473.8 | I3: 2 | J3: 11473.8 | L3: =(SUM(B3,D3,F3,H3,J3 )/5) -> 11473.8 | M3: =MIN(B3,D3,F3,H3,J3) -> 11473.8
A4: 3 | B4: 13295.8 | C4: 3 | D4: 13295.8 | E4: 3 | F4: 13295.8 | G4: 3 | H4: 13295.8 | I4: 3 | J4: 13295.8 | L4: =(SUM(B4,D4,F4,H4,J4 )/5) -> 13295.8 | M4: =MIN(B4,D4,F4,H4,J4) -> 13295.8
A5: 4 | B5: 13691 | C5: 4 | D5: 13691 | E5: 4 | F5: 13691 | G5: 4 | H5: 13691 | I5: 4 | J5: 13691 | L5: =(SUM(B5,D5,F5,H5,J5 )/5) -> 13691 | M5: =MIN(B5,D5,F5,H5,J5) -> 13691
A6: 5 | B6: 17309.1 | C6: 5 | D6: 17309.1 | E6: 5 | F6: 17309.1 | G6: 5 | H6: 17309.1 | I6: 5 | J6: 17309.1 | L6: =(SUM(B6,D6,F6,H6,J6 )/5) -> 17309.1 | M6: =MIN(B6,D6,F6,H6,J6) -> 17309.1
A7: 6 | B7: 12707.1 | C7: 6 | D7: 12707.1 | E7: 6 | F7: 12707.1 | G7: 6 | H7: 12707.1 | I7: 6 | J7: 12707.1 | L7: =(SUM(B7,D7,F7,H7,J7 )/5) -> 12707.1 | M7: =MIN(B7,D7,F7,H7,J7) -> 12707.1
A8: 7 | B8: 9572.5 | C8: 7 | D8: 9572.5 | E8: 7 | F8: 9572.5 | G8: 7 | H8: 9572.5 | I8: 7 | J8: 9572.5 | L8: =(SUM(B8,D8,F8,H8,J8 )/5) -> 9572.5 | M8: =MIN(B8,D8,F8,H8,J8) -> 9572.5
A9: 8 | B9: 9831.8 | C9: 8 | D9: 9831.8 | E9: 8 | F9: 9831.8 | G9: 8 | H9: 9831.8 | I9: 8 | J9: 9831.8 | L9: =(SUM(B9,D9,F9,H9,J9 )/5) -> 9831.8 | M9: =MIN(B9,D9,F9,H9,J9) -> 9831.8
A10: 9 | B10: 13540 | C10: 9 | D10: 13540 | E10: 9 | F10: 13540 | G10: 9 | H10: 13540 | I10: 9 | J10: 13540 | L10: =(SUM(B10,D10,F10,H10,J10 )/5) -> 13540 | M10: =MIN(B10,D10,F10,H10,J10) -> 13540
A11: 10 | B11: 9455 | C11: 10 | D11: 9455 | E11: 10 | F11: 9455 | G11: 10 | H11: 9455 | I11: 10 | J11: 9455 | L11: =(SUM(B11,D11,F11,H11,J11 )/5) -> 9455 | M11: =MIN(B11,D11,F11,H11,J11) -> 9455
A12: 11 | B12: 11684.3 | C12: 11 | D12: 11684.3 | E12: 11 | F12: 11684.3 | G12: 11 | H12: 11684.3 | I12: 11 | J12: 11684.3 | L12: =(SUM(B12,D12,F12,H12,J12 )/5) -> 11684.3 | M12: =MIN(B12,D12,F12,H12,J12) -> 11684.3
A13: 12 | B13: 12347.8 | C13: 12 | D13: 12347.8 | E13: 12 | F13: 12347.8 | G13: 12 | H13: 12347.8 | I13: 12 | J13: 12347.8 | L13: =(SUM(B13,D13,F13,H13,J13 )/5) -> 12347.8 | M13: =MIN(B13,D13,F13,H13,J13) -> 12347.8
... A901: 300 | B901: 36204.7 | C901: 300 | D901: 36204.7 | E901: 300 | F901: 36204.7 | G901: 300 | H901: 36204.7 | I901: 300 | J901: 36204.7 | L901: =(SUM(B901,D901,F901,H901,J901 )/5) -> 36204.7 | M901: =MIN(B901,D901,F901,H901,J901) -> 36204.7

Sheet ILS_RVND_2
A1: Data Result Obj Function (5 rounds) | L1: Average: | M1: Best:
A2: 1 | B2: 12238.1 | C2: 1 | D2: 12238.1 | E2: 1 | F2: 12238.1 | G2: 1 | H2: 12238.1 | I2: 1 | J2: 12238.1 | L2: =(SUM(B2,D2,F2,H2,J2 )/5) -> 12238.1 | M2: =MIN(B2,D2,F2,H2,J2) -> 12238.1
A3: 2 | B3: 11473.8 | C3: 2 | D3: 11473.8 | E3: 2 | F3: 11473.8 | G3: 2 | H3: 11473.8 | I3: 2 | J3: 11473.8 | L3: =(SUM(B3,D3,F3,H3,J3 )/5) -> 11473.8 | M3: =MIN(B3,D3,F3,H3,J3) -> 11473.8
A4: 3 | B4: 13295.8 | C4: 3 | D4: 13295.8 | E4: 3 | F4: 13295.8 | G4: 3 | H4: 13295.8 | I4: 3 | J4: 13295.8 | L4: =(SUM(B4,D4,F4,H4,J4 )/5) -> 13295.8 | M4: =MIN(B4,D4,F4,H4,J4) -> 13295.8
A5: 4 | B5: 13691 | C5: 4 | D5: 13691 | E5: 4 | F5: 13691 | G5: 4 | H5: 13691 | I5: 4 | J5: 13691 | L5: =(SUM(B5,D5,F5,H5,J5 )/5) -> 13691 | M5: =MIN(B5,D5,F5,H5,J5) -> 13691
A6: 5 | B6: 17309.1 | C6: 5 | D6: 17309.1 | E6: 5 | F6: 17309.1 | G6: 5 | H6: 17309.1 | I6: 5 | J6: 17309.1 | L6: =(SUM(B6,D6,F6,H6,J6 )/5) -> 17309.1 | M6: =MIN(B6,D6,F6,H6,J6) -> 17309.1
A7: 6 | B7: 12707.1 | C7: 6 | D7: 12707.1 | E7: 6 | F7: 12707.1 | G7: 6 | H7: 12707.1 | I7: 6 | J7: 12707.1 | L7: =(SUM(B7,D7,F7,H7,J7 )/5) -> 12707.1 | M7: =MIN(B7,D7,F7,H7,J7) -> 12707.1
A8: 7 | B8: 9572.5 | C8: 7 | D8: 9572.5 | E8: 7 | F8: 9572.5 | G8: 7 | H8: 9572.5 | I8: 7 | J8: 9572.5 | L8: =(SUM(B8,D8,F8,H8,J8 )/5) -> 9572.5 | M8: =MIN(B8,D8,F8,H8,J8) -> 9572.5
A9: 8 | B9: 9831.8 | C9: 8 | D9: 9831.8 | E9: 8 | F9: 9831.8 | G9: 8 | H9: 9831.8 | I9: 8 | J9: 9831.8 | L9: =(SUM(B9,D9,F9,H9,J9 )/5) -> 9831.8 | M9: =MIN(B9,D9,F9,H9,J9) -> 9831.8
A10: 9 | B10: 13540 | C10: 9 | D10: 13540 | E10: 9 | F10: 13540 | G10: 9 | H10: 13540 | I10: 9 | J10: 13540 | L10: =(SUM(B10,D10,F10,H10,J10 )/5) -> 13540 | M10: =MIN(B10,D10,F10,H10,J10) -> 13540
A11: 10 | B11: 9455 | C11: 10 | D11: 9455 | E11: 10 | F11: 9455 | G11: 10 | H11: 9455 | I11: 10 | J11: 9455 | L11: =(SUM(B11,D11,F11,H11,J11 )/5) -> 9455 | M11: =MIN(B11,D11,F11,H11,J11) -> 9455
A12: 11 | B12: 11684.3 | C12: 11 | D12: 11684.3 | E12: 11 | F12: 11684.3 | G12: 11 | H12: 11684.3 | I12: 11 | J12: 11684.3 | L12: =(SUM(B12,D12,F12,H12,J12 )/5) -> 11684.3 | M12: =MIN(B12,D12,F12,H12,J12) -> 11684.3
A13: 12 | B13: 12347.8 | C13: 12 | D13: 12347.8 | E13: 12 | F13: 12347.8 | G13: 12 | H13: 12347.8 | I13: 12 | J13: 12347.8 | L13: =(SUM(B13,D13,F13,H13,J13 )/5) -> 12347.8 | M13: =MIN(B13,D13,F13,H13,J13) -> 12347.8
... A901: 300 | B901: 36734.5 | C901: 300 | D901: 37120.2 | E901: 300 | F901: 36950.6 | G901: 300 | H901: 37070.4 | I901: 300 | J901: 36758.5 | L901: =(SUM(B901,D901,F901,H901,J901 )/5) -> 36926.84 | M901: =MIN(B901,D901,F901,H901,J901) -> 36734.5

Sheet GA_LS
A1: Data Result Obj Function (5 rounds) | L1: Average: | M1: Best:
A2: 1 | B2: 12238.1 | C2: 1 | D2: 12238.1 | E2: 1 | F2: 12238.1 | G2: 1 | H2: 12238.1 | I2: 1 | J2: 12238.1 | L2: =(SUM(B2,D2,F2,H2,J2 )/5) -> 12238.1 | M2: =MIN(B2,D2,F2,H2,J2) -> 12238.1
A3: 2 | B3: 11473.8 | C3: 2 | D3: 11473.8 | E3: 2 | F3: 11473.8 | G3: 2 | H3: 11473.8 | I3: 2 | J3: 11473.8 | L3: =(SUM(B3,D3,F3,H3,J3 )/5) -> 11473.8 | M3: =MIN(B3,D3,F3,H3,J3) -> 11473.8
A4: 3 | B4: 13295.8 | C4: 3 | D4: 13295.8 | E4: 3 | F4: 13295.8 | G4: 3 | H4: 13295.8 | I4: 3 | J4: 13295.8 | L4: =(SUM(B4,D4,F4,H4,J4 )/5) -> 13295.8 | M4: =MIN(B4,D4,F4,H4,J4) -> 13295.8
A5: 4 | B5: 13691 | C5: 4 | D5: 13691 | E5: 4 | F5: 13691 | G5: 4 | H5: 13691 | I5: 4 | J5: 13691 | L5: =(SUM(B5,D5,F5,H5,J5 )/5) -> 13691 | M5: =MIN(B5,D5,F5,H5,J5) -> 13691
A6: 5 | B6: 17309.1 | C6: 5 | D6: 17309.1 | E6: 5 | F6: 17309.1 | G6: 5 | H6: 17309.1 | I6: 5 | J6: 17309.1 | L6: =(SUM(B6,D6,F6,H6,J6 )/5) -> 17309.1 | M6: =MIN(B6,D6,F6,H6,J6) -> 17309.1
A7: 6 | B7: 12707.1 | C7: 6 | D7: 12707.1 | E7: 6 | F7: 12707.1 | G7: 6 | H7: 12707.1 | I7: 6 | J7: 12707.1 | L7: =(SUM(B7,D7,F7,H7,J7 )/5) -> 12707.1 | M7: =MIN(B7,D7,F7,H7,J7) -> 12707.1
A8: 7 | B8: 9572.5 | C8: 7 | D8: 9572.5 | E8: 7 | F8: 9572.5 | G8: 7 | H8: 9572.5 | I8: 7 | J8: 9572.5 | L8: =(SUM(B8,D8,F8,H8,J8 )/5) -> 9572.5 | M8: =MIN(B8,D8,F8,H8,J8) -> 9572.5
A9: 8 | B9: 9831.8 | C9: 8 | D9: 9831.8 | E9: 8 | F9: 9831.8 | G9: 8 | H9: 9831.8 | I9: 8 | J9: 9831.8 | L9: =(SUM(B9,D9,F9,H9,J9 )/5) -> 9831.8 | M9: =MIN(B9,D9,F9,H9,J9) -> 9831.8
A10: 9 | B10: 13540 | C10: 9 | D10: 13540 | E10: 9 | F10: 13540 | G10: 9 | H10: 13540 | I10: 9 | J10: 13540 | L10: =(SUM(B10,D10,F10,H10,J10 )/5) -> 13540 | M10: =MIN(B10,D10,F10,H10,J10) -> 13540
A11: 10 | B11: 9455 | C11: 10 | D11: 9455 | E11: 10 | F11: 9455 | G11: 10 | H11: 9455 | I11: 10 | J11: 9455 | L11: =(SUM(B11,D11,F11,H11,J11 )/5) -> 9455 | M11: =MIN(B11,D11,F11,H11,J11) -> 9455
A12: 11 | B12: 11684.3 | C12: 11 | D12: 11684.3 | E12: 11 | F12: 11684.3 | G12: 11 | H12: 11684.3 | I12: 11 | J12: 11684.3 | L12: =(SUM(B12,D12,F12,H12,J12 )/5) -> 11684.3 | M12: =MIN(B12,D12,F12,H12,J12) -> 11684.3
A13: 12 | B13: 12347.8 | C13: 12 | D13: 12347.8 | E13: 12 | F13: 12347.8 | G13: 12 | H13: 12347.8 | I13: 12 | J13: 12347.8 | L13: =(SUM(B13,D13,F13,H13,J13 )/5) -> 12347.8 | M13: =MIN(B13,D13,F13,H13,J13) -> 12347.8
... A901: 300 | B901: 36204.7 | C901: 300 | D901: 36204.7 | E901: 300 | F901: 36204.7 | G901: 300 | H901: 35704.8 | I901: 300 | J901: 36604.9 | L901: =(SUM(B901,D901,F901,H901,J901 )/5) -> 36184.76 | M901: =MIN(B901,D901,F901,H901,J901) -> 35704.8

Sheet Average RPD of all algorithms
E1: Average RPD (%)
A2: CPLEX Results | C2: Min (1,2,3,4) | E2: ILS_RVND_1 | F2: ILS_RVND_2 | G2: GA_LS | H2: CPLEX
A3: 12238.1 | C3: =MIN(ILS_RVND_1!L2, ILS_RVND_2!L2, GA_LS!L2, A3) -> 12238.1 | E3: =100*( ILS_RVND_1!L2-C3)/C3 -> 0 | F3: =100*( ILS_RVND_2!L2-C3)/C3 -> 0 | G3: =100*(GA_LS!L2-C3)/C3 -> 0 | H3: =100*(A3-C3)/C3 -> 0
A4: 11476.8 | C4: =MIN(ILS_RVND_1!L3, ILS_RVND_2!L3, GA_LS!L3, A4) -> 11473.8 | E4: =100*( ILS_RVND_1!L3-C4)/C4 -> 0 | F4: =100*( ILS_RVND_2!L3-C4)/C4 -> 0 | G4: =100*(GA_LS!L3-C4)/C4 -> 0 | H4: =100*(A4-C4)/C4 -> 0.026146525
A5: 13295.8 | C5: =MIN(ILS_RVND_1!L4, ILS_RVND_2!L4, GA_LS!L4, A5) -> 13295.8 | E5: =100*( ILS_RVND_1!L4-C5)/C5 -> 0 | F5: =100*( ILS_RVND_2!L4-C5)/C5 -> 0 | G5: =100*(GA_LS!L4-C5)/C5 -> 0 | H5: =100*(A5-C5)/C5 -> 0
A6: 13691 | C6: =MIN(ILS_RVND_1!L5, ILS_RVND_2!L5, GA_LS!L5, A6) -> 13691 | E6: =100*( ILS_RVND_1!L5-C6)/C6 -> 0 | F6: =100*( ILS_RVND_2!L5-C6)/C6 -> 0 | G6: =100*(GA_LS!L5-C6)/C6 -> 0 | H6: =100*(A6-C6)/C6 -> 0
A7: 17813.4 | C7: =MIN(ILS_RVND_1!L6, ILS_RVND_2!L6, GA_LS!L6, A7) -> 17309.1 | E7: =100*( ILS_RVND_1!L6-C7)/C7 -> 0 | F7: =100*( ILS_RVND_2!L6-C7)/C7 -> 0 | G7: =100*(GA_LS!L6-C7)/C7 -> 0 | H7: =100*(A7-C7)/C7 -> 2.9134964
A8: 12707.1 | C8: =MIN(ILS_RVND_1!L7, ILS_RVND_2!L7, GA_LS!L7, A8) -> 12707.1 | E8: =100*( ILS_RVND_1!L7-C8)/C8 -> 0 | F8: =100*( ILS_RVND_2!L7-C8)/C8 -> 0 | G8: =100*(GA_LS!L7-C8)/C8 -> 0 | H8: =100*(A8-C8)/C8 -> 0
A9: 9572.5 | C9: =MIN(ILS_RVND_1!L8, ILS_RVND_2!L8, GA_LS!L8, A9) -> 9572.5 | E9: =100*( ILS_RVND_1!L8-C9)/C9 -> 0 | F9: =100*( ILS_RVND_2!L8-C9)/C9 -> 0 | G9: =100*(GA_LS!L8-C9)/C9 -> 0 | H9: =100*(A9-C9)/C9 -> 0
A10: 9831.8 | C10: =MIN(ILS_RVND_1!L9, ILS_RVND_2!L9, GA_LS!L9, A10) -> 9831.8 | E10: =100*( ILS_RVND_1!L9-C10)/C10 -> 0 | F10: =100*( ILS_RVND_2!L9-C10)/C10 -> 0 | G10: =100*(GA_LS!L9-C10)/C10 -> 0 | H10: =100*(A10-C10)/C10 -> 0
A11: 13540 | C11: =MIN(ILS_RVND_1!L10, ILS_RVND_2!L10, GA_LS!L10, A11) -> 13540 | E11: =100*( ILS_RVND_1!L10-C11)/C11 -> 0 | F11: =100*( ILS_RVND_2!L10-C11)/C11 -> 0 | G11: =100*(GA_LS!L10-C11)/C11 -> 0 | H11: =100*(A11-C11)/C11 -> 0
A12: 9455 | C12: =MIN(ILS_RVND_1!L11, ILS_RVND_2!L11, GA_LS!L11, A12) -> 9455 | E12: =100*( ILS_RVND_1!L11-C12)/C12 -> 0 | F12: =100*( ILS_RVND_2!L11-C12)/C12 -> 0 | G12: =100*(GA_LS!L11-C12)/C12 -> 0 | H12: =100*(A12-C12)/C12 -> 0
A13: 11684.3 | C13: =MIN(ILS_RVND_1!L12, ILS_RVND_2!L12, GA_LS!L12, A13) -> 11684.3 | E13: =100*( ILS_RVND_1!L12-C13)/C13 -> 0 | F13: =100*( ILS_RVND_2!L12-C13)/C13 -> 0 | G13: =100*(GA_LS!L12-C13)/C13 -> 0 | H13: =100*(A13-C13)/C13 -> 0
A14: 12347.8 | C14: =MIN(ILS_RVND_1!L13, ILS_RVND_2!L13, GA_LS!L13, A14) -> 12347.8 | E14: =100*( ILS_RVND_1!L13-C14)/C14 -> 0 | F14: =100*( ILS_RVND_2!L13-C14)/C14 -> 0 | G14: =100*(GA_LS!L13-C14)/C14 -> 0 | H14: =100*(A14-C14)/C14 -> 0
... A33: 16342 | C33: =MIN(ILS_RVND_1!L32, ILS_RVND_2!L32, GA_LS!L32, A33) -> 16342 | E33: =100*( ILS_RVND_1!L32-C33)/C33 -> 0.22053604 | F33: =100*( ILS_RVND_2!L32-C33)/C33 -> 1.6448415 | G33: =100*(GA_LS!L32-C33)/C33 -> 0 | H33: =100*(A33-C33)/C33 -> 0
A34: 11968.9 | C34: =MIN(ILS_RVND_1!L33, ILS_RVND_2!L33, GA_LS!L33, A34) -> 11968.9 | E34: =100*( ILS_RVND_1!L33-C34)/C34 -> 0 | G34: =100*(GA_LS!L33-C34)/C34 -> 0 | H34: =100*(A34-C34)/C34 -> 0
A35: 15456.1 | C35: =MIN(ILS_RVND_1!L34, ILS_RVND_2!L34, GA_LS!L34, A35) -> 15418.6 | E35: =100*( ILS_RVND_1!L34-C35)/C35 -> 0 | H35: =100*(A35-C35)/C35 -> 0.24321274
A36: 11018.4 | C36: =MIN(ILS_RVND_1!L35, ILS_RVND_2!L35, GA_LS!L35, A36) -> 10949.6 | E36: =100*( ILS_RVND_1!L35-C36)/C36 -> 0 | F36: =100*( ILS_RVND_2!L35-C36)/C36 -> 0.12566669 | G36: =100*(GA_LS!L35-C36)/C36 -> 0 | H36: =100*(A36-C36)/C36 -> 0.62833346
A37: 10776.6 | C37: =MIN(ILS_RVND_1!L36, ILS_RVND_2!L36, GA_LS!L36, A37) -> 10776.6 | E37: =100*( ILS_RVND_1!L36-C37)/C37 -> 0 | F37: =100*( ILS_RVND_2!L36-C37)/C37 -> 0 | G37: =100*(GA_LS!L36-C37)/C37 -> 0 | H37: =100*(A37-C37)/C37 -> 0
A38: 13511.8 | C38: =MIN(ILS_RVND_1!L37, ILS_RVND_2!L37, GA_LS!L37, A38) -> 13426.6 | E38: =100*( ILS_RVND_1!L37-C38)/C38 -> 0 | F38: =100*( ILS_RVND_2!L37-C38)/C38 -> 0 | G38: =100*(GA_LS!L37-C38)/C38 -> 0 | H38: =100*(A38-C38)/C38 -> 0.63456124
A39: 16568.6 | C39: =MIN(ILS_RVND_1!L38, ILS_RVND_2!L38, GA_LS!L38, A39) -> 16568.6 | E39: =100*( ILS_RVND_1!L38-C39)/C39 -> 0 | F39: =100*( ILS_RVND_2!L38-C39)/C39 -> 0 | G39: =100*(GA_LS!L38-C39)/C39 -> 0 | H39: =100*(A39-C39)/C39 -> 0
A40: 16912.6 | C40: =MIN(ILS_RVND_1!L39, ILS_RVND_2!L39, GA_LS!L39, A40) -> 16475.2 | E40: =100*( ILS_RVND_1!L39-C40)/C40 -> 0 | F40: =100*( ILS_RVND_2!L39-C40)/C40 -> 0 | G40: =100*(GA_LS!L39-C40)/C40 -> 0 | H40: =100*(A40-C40)/C40 -> 2.6548995
A41: 12901.3 | C41: =MIN(ILS_RVND_1!L40, ILS_RVND_2!L40, GA_LS!L40, A41) -> 12901.3 | E41: =100*( ILS_RVND_1!L40-C41)/C41 -> 0 | F41: =100*( ILS_RVND_2!L40-C41)/C41 -> 0 | G41: =100*(GA_LS!L40-C41)/C41 -> 0 | H41: =100*(A41-C41)/C41 -> 0
A42: 14711.8 | C42: =MIN(ILS_RVND_1!L41, ILS_RVND_2!L41, GA_LS!L41, A42) -> 14711.8 | E42: =100*( ILS_RVND_1!L41-C42)/C42 -> 0 | F42: =100*( ILS_RVND_2!L41-C42)/C42 -> 0 | G42: =100*(GA_LS!L41-C42)/C42 -> 0 | H42: =100*(A42-C42)/C42 -> 0
A43: 18247.1 | C43: =MIN(ILS_RVND_1!L42, ILS_RVND_2!L42, GA_LS!L42, A43) -> 17234.7 | E43: =100*( ILS_RVND_1!L42-C43)/C43 -> 0 | F43: =100*( ILS_RVND_2!L42-C43)/C43 -> 0 | G43: =100*(GA_LS!L42-C43)/C43 -> 0 | H43: =100*(A43-C43)/C43 -> 5.8741957
A44: 13945.9 | C44: =MIN(ILS_RVND_1!L43, ILS_RVND_2!L43, GA_LS!L43, A44) -> 13945.9 | E44: =100*( ILS_RVND_1!L43-C44)/C44 -> 0 | F44: =100*( ILS_RVND_2!L43-C44)/C44 -> 0 | G44: =100*(GA_LS!L43-C44)/C44 -> 0 | H44: =100*(A44-C44)/C44 -> 0
A45: 13002.2 | C45: =MIN(ILS_RVND_1!L44, ILS_RVND_2!L44, GA_LS!L44, A45) -> 12547.8 | E45: =100*( ILS_RVND_1!L44-C45)/C45 -> 0 | F45: =100*( ILS_RVND_2!L44-C45)/C45 -> 0 | G45: =100*(GA_LS!L44-C45)/C45 -> 0 | H45: =100*(A45-C45)/C45 -> 3.621352
A46: 13183.2 | C46: =MIN(ILS_RVND_1!L45, ILS_RVND_2!L45, GA_LS!L45, A46) -> 13183.2 | E46: =100*( ILS_RVND_1!L45-C46)/C46 -> 0 | F46: =100*( ILS_RVND_2!L45-C46)/C46 -> 0 | G46: =100*(GA_LS!L45-C46)/C46 -> 0 | H46: =100*(A46-C46)/C46 -> 0
A47: 8499.7 | C47: =MIN(ILS_RVND_1!L46, ILS_RVND_2!L46, GA_LS!L46, A47) -> 8499.7 | E47: =100*( ILS_RVND_1!L46-C47)/C47 -> 0 | F47: =100*( ILS_RVND_2!L46-C47)/C47 -> 0 | G47: =100*(GA_LS!L46-C47)/C47 -> 0 | H47: =100*(A47-C47)/C47 -> 0
... A66: 16803.9 | C66: =MIN(ILS_RVND_1!L65, ILS_RVND_2!L65, GA_LS!L65, A66) -> 16803.9 | E66: =100*( ILS_RVND_1!L65-C66)/C66 -> 0 | F66: =100*( ILS_RVND_2!L65-C66)/C66 -> 0 | G66: =100*(GA_LS!L65-C66)/C66 -> 0 | H66: =100*(A66-C66)/C66 -> 0
A67: 18831.4 | C67: =MIN(ILS_RVND_1!L66, ILS_RVND_2!L66, GA_LS!L66, A67) -> 18718.3 | E67: =100*( ILS_RVND_1!L66-C67)/C67 -> 0 | G67: =100*(GA_LS!L66-C67)/C67 -> 0 | H67: =100*(A67-C67)/C67 -> 0.60422154
A68: 13538.1 | C68: =MIN(ILS_RVND_1!L67, ILS_RVND_2!L67, GA_LS!L67, A68) -> 13538.1 | E68: =100*( ILS_RVND_1!L67-C68)/C68 -> 0 | H68: =100*(A68-C68)/C68 -> 0
A69: 19938.3 | C69: =MIN(ILS_RVND_1!L68, ILS_RVND_2!L68, GA_LS!L68, A69) -> 19938.3 | E69: =100*( ILS_RVND_1!L68-C69)/C69 -> 0 | F69: =100*( ILS_RVND_2!L68-C69)/C69 -> 0 | G69: =100*(GA_LS!L68-C69)/C69 -> 0 | H69: =100*(A69-C69)/C69 -> 0
A70: 12415.4 | C70: =MIN(ILS_RVND_1!L69, ILS_RVND_2!L69, GA_LS!L69, A70) -> 12415.4 | E70: =100*( ILS_RVND_1!L69-C70)/C70 -> 0 | F70: =100*( ILS_RVND_2!L69-C70)/C70 -> 0 | G70: =100*(GA_LS!L69-C70)/C70 -> 0 | H70: =100*(A70-C70)/C70 -> 0
A71: 11244.1 | C71: =MIN(ILS_RVND_1!L70, ILS_RVND_2!L70, GA_LS!L70, A71) -> 11244.1 | E71: =100*( ILS_RVND_1!L70-C71)/C71 -> 0 | F71: =100*( ILS_RVND_2!L70-C71)/C71 -> 0 | G71: =100*(GA_LS!L70-C71)/C71 -> 0 | H71: =100*(A71-C71)/C71 -> 0
A72: 13405.1 | C72: =MIN(ILS_RVND_1!L71, ILS_RVND_2!L71, GA_LS!L71, A72) -> 13401.7 | E72: =100*( ILS_RVND_1!L71-C72)/C72 -> 0 | F72: =100*( ILS_RVND_2!L71-C72)/C72 -> 0 | G72: =100*(GA_LS!L71-C72)/C72 -> 0 | H72: =100*(A72-C72)/C72 -> 0.025369916
A73: 16283.9 | C73: =MIN(ILS_RVND_1!L72, ILS_RVND_2!L72, GA_LS!L72, A73) -> 16283.9 | E73: =100*( ILS_RVND_1!L72-C73)/C73 -> 0 | F73: =100*( ILS_RVND_2!L72-C73)/C73 -> 0 | G73: =100*(GA_LS!L72-C73)/C73 -> 0 | H73: =100*(A73-C73)/C73 -> 0
A74: 10890.9 | C74: =MIN(ILS_RVND_1!L73, ILS_RVND_2!L73, GA_LS!L73, A74) -> 10890.9 | E74: =100*( ILS_RVND_1!L73-C74)/C74 -> 0 | F74: =100*( ILS_RVND_2!L73-C74)/C74 -> 0.53732933 | G74: =100*(GA_LS!L73-C74)/C74 -> 0 | H74: =100*(A74-C74)/C74 -> 0
A75: 11094.1 | C75: =MIN(ILS_RVND_1!L74, ILS_RVND_2!L74, GA_LS!L74, A75) -> 11094.1 | E75: =100*( ILS_RVND_1!L74-C75)/C75 -> 0 | F75: =100*( ILS_RVND_2!L74-C75)/C75 -> 0 | G75: =100*(GA_LS!L74-C75)/C75 -> 0 | H75: =100*(A75-C75)/C75 -> 0
A76: 13707.6 | C76: =MIN(ILS_RVND_1!L75, ILS_RVND_2!L75, GA_LS!L75, A76) -> 13707.6 | E76: =100*( ILS_RVND_1!L75-C76)/C76 -> 0 | F76: =100*( ILS_RVND_2!L75-C76)/C76 -> 0 | G76: =100*(GA_LS!L75-C76)/C76 -> 0 | H76: =100*(A76-C76)/C76 -> 0
...
