Workbook
Name _100: 'GA Arroyo'!$B$783:$M$962
Name _100jobs0_1: 'GA Arroyo'!$O$783:$Z$962
Name _100jobs1_0: 'GA Arroyo'!$AO$783:$AZ$962
Name _100jobs1_1: 'GA Arroyo'!$AB$783:$AM$962
Name _20: 'GA Arroyo'!$B$303:$M$602
Name _20jobs0_1: 'GA Arroyo'!$O$303:$Z$602
Name _20jobs1_0: 'GA Arroyo'!$AO$303:$AZ$602
Name _20jobs1_1: 'GA Arroyo'!$AB$303:$AM$602
Name _50: 'GA Arroyo'!$B$603:$M$782
Name _50jobs0_1: 'GA Arroyo'!$O$603:$Z$782
Name _50jobs1_0: 'GA Arroyo'!$AO$603:$AZ$782
Name _50jobs1_1: 'GA Arroyo'!$AB$603:$AM$782
Name _8: 'GA Arroyo'!$B$3:$M$302
Name _8jobs0_1: 'GA Arroyo'!$O$3:$Z$302
Name _8jobs1_0: 'GA Arroyo'!$AO$3:$AZ$302
Name _8jobs1_1: 'GA Arroyo'!$AB$3:$AM$302

Sheet Parameter <x, y>
A1: <Cross, Mut> | B1: <0,0> | G1: <0,1> | L1: <1,0> | Q1: <1,1> | V1: Quick Test New_GA (Mut: 0.50)
A2: Iter:500 , Pop: 50 | B2: AG1 | C2: Over | D2: AG2 | E2: Over | G2: AG1 | H2: Over | I2: AG2 | J2: Over | L2: AG1 | M2: Over | N2: AG2 | O2: Over | Q2: AG1 | R2: Over | S2: AG2 | T2: Over | V2: <1,0> | W2: Over | X2: Time
A3: 8 Jobs | B3: 11423.2 | C3: 0 | D3: 13861.6 | E3: 27 | G3: 11645.6 | H3: 0 | I3: 11316.2 | J3: 0 | L3: 12069 | M3: 6 | N3: 13861.6 | O3: 27 | Q3: 12110.9 | R3: 0 | S3: 11532.1 | T3: 0 | V3: 11161.6 | W3: 0 | X3: 0
B4: 10583.1 | C4: 0 | D4: 9568.9 | E4: 0 | G4: 10514.1 | H4: 0 | I4: 10708.3 | J4: 0 | L4: 12461.2 | M4: 20 | N4: 10212.8 | O4: 0 | Q4: 16394 | R4: 48 | S4: 12390.5 | T4: 6 | V4: 9568.9 | W4: 0 | X4: 1
B5: 11437.1 | C5: 8 | D5: 10987 | E5: 3 | G5: 11019.9 | H5: 0 | I5: 11437.1 | J5: 8 | L5: 10749.9 | M5: 0 | N5: 10937.1 | O5: 3 | Q5: 11820.4 | R5: 0 | S5: 11750.9 | T5: 0 | V5: 10637.1 | W5: 0 | X5: 0
B6: 13346.7 | C6: 19 | D6: 11778.4 | E6: 0 | G6: 15046.3 | H6: 21 | I6: 11446.7 | J6: 0 | L6: 12657.5 | M6: 0 | N6: 13346.7 | O6: 19 | Q6: 11948.7 | R6: 0 | S6: 13406.2 | T6: 8 | V6: 11778.4 | W6: 0 | X6: 0
B7: 7342.4 | C7: 0 | D7: 6766.4 | E7: 0 | G7: 9043.4 | H7: 17 | I7: 8423.9 | J7: 17 | L7: 8973.2 | M7: 17 | N7: 6723.9 | O7: 0 | Q7: 8059.9 | R7: 2 | S7: 10825.3 | T7: 26 | V7: 6723.9 | W7: 0 | X7: 0
B8: 7085 | C8: 0 | D8: 6140.1 | E8: 0 | G8: 6760.4 | H8: 0 | I8: 6760.4 | J8: 0 | L8: 8674.6 | M8: 22 | N8: 6140.1 | O8: 0 | Q8: 10503.8 | R8: 34 | S8: 9420.1 | T8: 22 | V8: 6140.1 | W8: 0 | X8: 0
B9: 10887 | C9: 0 | D9: 10536.4 | E9: 0 | G9: 10579.8 | H9: 0 | I9: 9986.9 | J9: 0 | L9: 10860 | M9: 0 | N9: 9986.9 | O9: 0 | Q9: 10536.4 | R9: 0 | S9: 10657 | T9: 0 | V9: 10657 | W9: 0 | X9: 0
B10: 11455.3 | C10: 0 | D10: 10293.6 | E10: 1 | G10: 10641 | H10: 1 | I10: 17173 | J10: 55 | L10: 12741 | M10: 22 | N10: 12484 | O10: 17 | Q10: 18477.4 | R10: 57 | S10: 12484.5 | T10: 17 | V10: 10784 | W10: 0 | X10: 1
B11: 13226.3 | C11: 22 | D11: 10912.5 | E11: 11 | G11: 11187 | H11: 0 | I11: 10494.4 | J11: 0 | L11: 11558.5 | M11: 16 | N11: 12481.7 | O11: 22 | Q11: 11873.4 | R11: 0 | S11: 11945.5 | T11: 9 | V11: 9813.9 | W11: 0 | X11: 0
B12: 8434.5 | C12: 0 | D12: 9561.1 | E12: 15 | G12: 8258.7 | H12: 0 | I12: 7865.7 | J12: 2 | L12: 9057 | M12: 10 | N12: 7665.7 | O12: 0 | Q12: 8533.6 | R12: 0 | S12: 9563.2 | T12: 0 | V12: 7665.7 | W12: 0 | X12: 0
B13: 6247.5 | C13: 4 | D13: 6096.2 | E13: 3 | G13: 6605.8 | H13: 0 | I13: 6247.5 | J13: 4 | L13: 5576.6 | M13: 1 | N13: 6196.2 | O13: 4 | Q13: 7880.3 | R13: 1 | S13: 7813.1 | T13: 0 | V13: 5576.6 | W13: 1 | X13: 0
B14: 11567 | C14: 34 | D14: 8981.9 | E14: 0 | G14: 11567 | H14: 34 | I14: 11721.6 | J14: 36 | L14: 11915.8 | M14: 36 | N14: 11196.2 | O14: 34 | Q14: 15220.7 | R14: 56 | S14: 12448.2 | T14: 16 | V14: 8846.9 | W14: 0 | X14: 0
B15: 10313.1 | C15: 0 | D15: 9704.7 | E15: 0 | G15: 10105 | H15: 0 | I15: 9704.7 | J15: 0 | L15: 10558.5 | M15: 0 | N15: 9727.2 | O15: 0 | Q15: 10930.8 | R15: 0 | S15: 11869.4 | T15: 0 | V15: 9979.6 | W15: 0 | X15: 0
... B302: 11214 | C302: 0 | D302: 11199.3 | E302: 0 | G302: 9936.5 | H302: 0 | I302: 11048.3 | J302: 0 | L302: 11489.8 | M302: 0 | N302: 11359.9 | O302: 0 | Q302: 11186.8 | R302: 0 | S302: 11795.8 | T302: 0 | V302: 9952.5 | W302: 0 | X302: 1
A303: 20 Jobs | B303: 94862.9 | C303: 40 | D303: 101878 | E303: 84 | G303: 112771 | H303: 86 | I303: 115004 | J303: 111 | L303: 88566.7 | M303: 31 | N303: 73812.4 | O303: 20 | Q303: 76540.4 | R303: 4 | S303: 107248 | T303: 85 | V303: 61396 | W303: 2 | X303: 0
B304: 116362 | C304: 85 | D304: 100643 | E304: 62 | G304: 86453.1 | H304: 20 | I304: 67042.6 | J304: 0 | L304: 94548.7 | M304: 35 | N304: 110665 | O304: 100 | Q304: 100375 | R304: 42 | S304: 63658.8 | T304: 0 | V304: 55878.6 | W304: 0 | X304: 1
B305: 88343.7 | C305: 38 | D305: 92710.6 | E305: 71 | G305: 69772.9 | H305: 0 | I305: 93815.9 | J305: 63 | L305: 85623.9 | M305: 32 | N305: 66979.3 | O305: 16 | Q305: 85624.5 | R305: 25 | S305: 78446.7 | T305: 30 | V305: 74880.4 | W305: 43 | X305: 0
B306: 104958 | C306: 73 | D306: 93704.3 | E306: 74 | G306: 84562.2 | H306: 30 | I306: 98615.7 | J306: 86 | L306: 76449.4 | M306: 7 | N306: 76549 | O306: 43 | Q306: 86045.2 | R306: 21 | S306: 85632.4 | T306: 43 | V306: 52371.9 | W306: 0 | X306: 0
B307: 137860 | C307: 114 | D307: 124500 | E307: 117 | G307: 143355 | H307: 117 | I307: 113705 | J307: 78 | L307: 145483 | M307: 140 | N307: 57976.7 | O307: 0 | Q307: 117145 | R307: 79 | S307: 131183 | T307: 118 | V307: 98205.6 | W307: 81 | X307: 1
B308: 109897 | C308: 75 | D308: 68639.5 | E308: 24 | G308: 130347 | H308: 130 | I308: 92472 | J308: 62 | L308: 110978 | M308: 78 | N308: 82946.5 | O308: 63 | Q308: 117168 | R308: 102 | S308: 107598 | T308: 100 | V308: 62891.4 | W308: 23 | X308: 0
B309: 67544.9 | C309: 15 | D309: 93893.2 | E309: 85 | G309: 59112.2 | H309: 0 | I309: 67753.1 | J309: 26 | L309: 70480.5 | M309: 30 | N309: 66932.9 | O309: 38 | Q309: 61223.2 | R309: 0 | S309: 70078.4 | T309: 35 | V309: 44650.9 | W309: 0 | X309: 1
B310: 139130 | C310: 138 | D310: 66482.3 | E310: 17 | G310: 103782 | H310: 66 | I310: 119546 | J310: 107 | L310: 105207 | M310: 69 | N310: 104810 | O310: 102 | Q310: 88693.5 | R310: 30 | S310: 108448 | T310: 100 | V310: 92757.7 | W310: 72 | X310: 0
B311: 86295.3 | C311: 20 | D311: 83534 | E311: 43 | G311: 89793.6 | H311: 28 | I311: 64377.2 | J311: 14 | L311: 108292 | M311: 63 | N311: 60837.5 | O311: 0 | Q311: 111216 | R311: 71 | S311: 69289.8 | T311: 3 | V311: 57849.8 | W311: 0 | X311: 1
B312: 96905.3 | C312: 59 | D312: 117910 | E312: 120 | G312: 104636 | H312: 71 | I312: 115077 | J312: 108 | L312: 101748 | M312: 59 | N312: 93487.7 | O312: 82 | Q312: 73533.4 | R312: 0 | S312: 81535.9 | T312: 39 | V312: 64639.9 | W312: 28 | X312: 0
B313: 157824 | C313: 160 | D313: 114158 | E313: 101 | G313: 137299 | H313: 122 | I313: 118724 | J313: 98 | L313: 105247 | M313: 49 | N313: 62145.4 | O313: 3 | Q313: 107669 | R313: 58 | S313: 107838 | T313: 81 | V313: 59688.6 | W313: 0 | X313: 0
B314: 88664.4 | C314: 32 | D314: 62254.3 | E314: 0 | G314: 83820.3 | H314: 23 | I314: 55120.8 | J314: 0 | L314: 69838 | M314: 0 | N314: 82618.7 | O314: 53 | Q314: 108789 | R314: 74 | S314: 67731.8 | T314: 0 | V314: 64694.7 | W314: 16 | X314: 1
B315: 100286 | C315: 66 | D315: 56845 | E315: 16 | G315: 131606 | H315: 140 | I315: 87900.1 | J315: 62 | L315: 96808.6 | M315: 66 | N315: 81367.2 | O315: 66 | Q315: 92196.8 | R315: 51 | S315: 78504.7 | T315: 40 | V315: 65364.2 | W315: 29 | X315: 0
... B602: 57001.6 | C602: 0 | D602: 52035.2 | E602: 21 | G602: 58071.4 | H602: 0 | I602: 89772.7 | J602: 71 | L602: 75172.5 | M602: 31 | N602: 50253.5 | O602: 19 | Q602: 67065.1 | R602: 13 | S602: 92304.8 | T602: 70 | V602: 39112.7 | W602: 0 | X602: 1
A603: 50 Jobs | B603: 463307 | C603: 0 | D603: 413879 | E603: 36 | G603: 496614 | H603: 0 | I603: 419920 | J603: 0 | L603: 525783 | M603: 34 | N603: 355962 | O603: 0 | Q603: 497620 | R603: 0 | S603: 377537 | T603: 0 | V603: 337584 | W603: 0 | X603: 0
B604: 598771 | C604: 84 | D604: 450172 | E604: 23 | G604: 498925 | H604: 0 | I604: 463835 | J604: 38 | L604: 498364 | M604: 0 | N604: 400869 | O604: 0 | Q604: 553669 | R604: 51 | S604: 422742 | T604: 0 | V604: 352215 | W604: 2 | X604: 2
B605: 567213 | C605: 0 | D605: 500339 | E605: 34 | G605: 581203 | H605: 0 | I605: 461427 | J605: 0 | L605: 568330 | M605: 0 | N605: 436570 | O605: 0 | Q605: 571659 | R605: 3 | S605: 455496 | T605: 0 | V605: 349872 | W605: 0 | X605: 1
B606: 572496 | C606: 60 | D606: 415289 | E606: 0 | G606: 510228 | H606: 0 | I606: 422600 | J606: 11 | L606: 595222 | M606: 70 | N606: 491938 | O606: 96 | Q606: 505149 | R606: 9 | S606: 441624 | T606: 18 | V606: 314874 | W606: 0 | X606: 2
B607: 504766 | C607: 0 | D607: 393351 | E607: 0 | G607: 512557 | H607: 21 | I607: 450709 | J607: 35 | L607: 505830 | M607: 0 | N607: 344085 | O607: 0 | Q607: 484237 | R607: 0 | S607: 419065 | T607: 0 | V607: 324954 | W607: 0 | X607: 1
B608: 583869 | C608: 51 | D608: 440674 | E608: 43 | G608: 536717 | H608: 0 | I608: 449187 | J608: 0 | L608: 536599 | M608: 0 | N608: 371416 | O608: 0 | Q608: 548124 | R608: 2 | S608: 393086 | T608: 0 | V608: 331916 | W608: 4 | X608: 2
B609: 483021 | C609: 0 | D609: 427617 | E609: 0 | G609: 527767 | H609: 13 | I609: 403937 | J609: 0 | L609: 547125 | M609: 38 | N609: 427688 | O609: 84 | Q609: 524215 | R609: 0 | S609: 393904 | T609: 0 | V609: 344364 | W609: 0 | X609: 2
B610: 586454 | C610: 20 | D610: 560096 | E610: 98 | G610: 573323 | H610: 0 | I610: 624667 | J610: 140 | L610: 597227 | M610: 0 | N610: 417813 | O610: 0 | Q610: 609121 | R610: 18 | S610: 491466 | T610: 0 | V610: 384805 | W610: 0 | X610: 0
B611: 474662 | C611: 0 | D611: 364309 | E611: 0 | G611: 468769 | H611: 0 | I611: 401290 | J611: 0 | L611: 479951 | M611: 0 | N611: 363382 | O611: 28 | Q611: 482667 | R611: 0 | S611: 368680 | T611: 0 | V611: 340106 | W611: 0 | X611: 1
B612: 549564 | C612: 0 | D612: 458488 | E612: 0 | G612: 561375 | H612: 0 | I612: 476752 | J612: 0 | L612: 540185 | M612: 0 | N612: 416980 | O612: 0 | Q612: 561561 | R612: 0 | S612: 477087 | T612: 26 | V612: 364274 | W612: 0 | X612: 1
...

Sheet RPD Parameter
E1: RPD GA1 | J1: RPD GA2
B2: min GA1 | C2: min GA2 | E2: <0,0> | F2: <0,1> | G2: <1,0> | H2: <1,1> | J2: <0,0> | K2: <0,1> | L2: <1,0> | M2: <1,1> | O2: Average of RPD:
A3: 8 jobs | B3: =MIN('Parameter <x, y>'!B3,'Parameter <x, y>'!G3,'Parameter <x, y>'!L3,'Parameter <x, y>'!Q3) -> 11423.2 | C3: =MIN('Parameter <x, y>'!D3,'Parameter <x, y>'!I3,'Parameter <x, y>'!N3,'Parameter <x, y>'!S3) -> 11316.2 | E3: =100*('Parameter <x, y>'!B3-B3)/B3 -> 0 | F3: =100*('Parameter <x, y>'!G3-B3)/B3 -> 1.9469151 | G3: =100*('Parameter <x, y>'!L3-B3)/B3 -> 5.6534071 | H3: =100*('Parameter <x, y>'!Q3-B3)/B3 -> 6.0202045 | J3: =100*('Parameter <x, y>'!D3-C3)/C3 -> 22.493417 | K3: =100*('Parameter <x, y>'!I3-C3)/C3 -> 0 | L3: =100*('Parameter <x, y>'!N3-C3)/C3 -> 22.493417 | M3: =100*('Parameter <x, y>'!S3-C3)/C3 -> 1.9078843
B4: =MIN('Parameter <x, y>'!B4,'Parameter <x, y>'!G4,'Parameter <x, y>'!L4,'Parameter <x, y>'!Q4) -> 10514.1 | C4: =MIN('Parameter <x, y>'!D4,'Parameter <x, y>'!I4,'Parameter <x, y>'!N4,'Parameter <x, y>'!S4) -> 9568.9 | E4: =100*('Parameter <x, y>'!B4-B4)/B4 -> 0.65626159 | F4: =100*('Parameter <x, y>'!G4-B4)/B4 -> 0 | G4: =100*('Parameter <x, y>'!L4-B4)/B4 -> 18.518941 | H4: =100*('Parameter <x, y>'!Q4-B4)/B4 -> 55.92395 | J4: =100*('Parameter <x, y>'!D4-C4)/C4 -> 0 | K4: =100*('Parameter <x, y>'!I4-C4)/C4 -> 11.907325 | L4: =100*('Parameter <x, y>'!N4-C4)/C4 -> 6.7290911 | M4: =100*('Parameter <x, y>'!S4-C4)/C4 -> 29.487193 | O4: GA1
B5: =MIN('Parameter <x, y>'!B5,'Parameter <x, y>'!G5,'Parameter <x, y>'!L5,'Parameter <x, y>'!Q5) -> 10749.9 | C5: =MIN('Parameter <x, y>'!D5,'Parameter <x, y>'!I5,'Parameter <x, y>'!N5,'Parameter <x, y>'!S5) -> 10937.1 | E5: =100*('Parameter <x, y>'!B5-B5)/B5 -> 6.3926176 | F5: =100*('Parameter <x, y>'!G5-B5)/B5 -> 2.5116513 | G5: =100*('Parameter <x, y>'!L5-B5)/B5 -> 0 | H5: =100*('Parameter <x, y>'!Q5-B5)/B5 -> 9.9582322 | J5: =100*('Parameter <x, y>'!D5-C5)/C5 -> 0.45624526 | K5: =100*('Parameter <x, y>'!I5-C5)/C5 -> 4.5715958 | L5: =100*('Parameter <x, y>'!N5-C5)/C5 -> 0 | M5: =100*('Parameter <x, y>'!S5-C5)/C5 -> 7.4407293 | P5: <0,0> | Q5: <0,1> | R5: <1,0> | S5: <1,1>
B6: =MIN('Parameter <x, y>'!B6,'Parameter <x, y>'!G6,'Parameter <x, y>'!L6,'Parameter <x, y>'!Q6) -> 11948.7 | C6: =MIN('Parameter <x, y>'!D6,'Parameter <x, y>'!I6,'Parameter <x, y>'!N6,'Parameter <x, y>'!S6) -> 11446.7 | E6: =100*('Parameter <x, y>'!B6-B6)/B6 -> 11.700018 | F6: =100*('Parameter <x, y>'!G6-B6)/B6 -> 25.924159 | G6: =100*('Parameter <x, y>'!L6-B6)/B6 -> 5.9320261 | H6: =100*('Parameter <x, y>'!Q6-B6)/B6 -> 0 | J6: =100*('Parameter <x, y>'!D6-C6)/C6 -> 2.8977784 | K6: =100*('Parameter <x, y>'!I6-C6)/C6 -> 0 | L6: =100*('Parameter <x, y>'!N6-C6)/C6 -> 16.59867 | M6: =100*('Parameter <x, y>'!S6-C6)/C6 -> 17.118471 | O6: 8 Jobs | P6: =AVERAGE(E3:E302) -> 4.9240205 | Q6: =AVERAGE(F3:F302) -> 6.5129564 | R6: =AVERAGE(G3:G302) -> 6.3195959 | S6: =AVERAGE(H3:H302) -> 12.353624
B7: =MIN('Parameter <x, y>'!B7,'Parameter <x, y>'!G7,'Parameter <x, y>'!L7,'Parameter <x, y>'!Q7) -> 7342.4 | C7: =MIN('Parameter <x, y>'!D7,'Parameter <x, y>'!I7,'Parameter <x, y>'!N7,'Parameter <x, y>'!S7) -> 6723.9 | E7: =100*('Parameter <x, y>'!B7-B7)/B7 -> 0 | F7: =100*('Parameter <x, y>'!G7-B7)/B7 -> 23.166812 | G7: =100*('Parameter <x, y>'!L7-B7)/B7 -> 22.210721 | H7: =100*('Parameter <x, y>'!Q7-B7)/B7 -> 9.7720092 | J7: =100*('Parameter <x, y>'!D7-C7)/C7 -> 0.63207365 | K7: =100*('Parameter <x, y>'!I7-C7)/C7 -> 25.282946 | L7: =100*('Parameter <x, y>'!N7-C7)/C7 -> 0 | M7: =100*('Parameter <x, y>'!S7-C7)/C7 -> 60.997338 | O7: 20 Jobs | P7: =AVERAGE(E303:E602) -> 14.440591 | Q7: =AVERAGE(F303:F602) -> 17.330661 | R7: =AVERAGE(G303:G602) -> 19.942405 | S7: =AVERAGE(H303:H602) -> 15.654555
B8: =MIN('Parameter <x, y>'!B8,'Parameter <x, y>'!G8,'Parameter <x, y>'!L8,'Parameter <x, y>'!Q8) -> 6760.4 | C8: =MIN('Parameter <x, y>'!D8,'Parameter <x, y>'!I8,'Parameter <x, y>'!N8,'Parameter <x, y>'!S8) -> 6140.1 | E8: =100*('Parameter <x, y>'!B8-B8)/B8 -> 4.801491 | F8: =100*('Parameter <x, y>'!G8-B8)/B8 -> 0 | G8: =100*('Parameter <x, y>'!L8-B8)/B8 -> 28.314893 | H8: =100*('Parameter <x, y>'!Q8-B8)/B8 -> 55.372463 | J8: =100*('Parameter <x, y>'!D8-C8)/C8 -> 0 | K8: =100*('Parameter <x, y>'!I8-C8)/C8 -> 10.102441 | L8: =100*('Parameter <x, y>'!N8-C8)/C8 -> 0 | M8: =100*('Parameter <x, y>'!S8-C8)/C8 -> 53.419325 | O8: 50 Jobs | P8: =AVERAGE(E603:E782) -> 3.4568055 | Q8: =AVERAGE(F603:F782) -> 3.8577907 | R8: =AVERAGE(G603:G782) -> 3.8324872 | S8: =AVERAGE(H603:H782) -> 4.0335519
B9: =MIN('Parameter <x, y>'!B9,'Parameter <x, y>'!G9,'Parameter <x, y>'!L9,'Parameter <x, y>'!Q9) -> 10536.4 | C9: =MIN('Parameter <x, y>'!D9,'Parameter <x, y>'!I9,'Parameter <x, y>'!N9,'Parameter <x, y>'!S9) -> 9986.9 | E9: =100*('Parameter <x, y>'!B9-B9)/B9 -> 3.3275122 | F9: =100*('Parameter <x, y>'!G9-B9)/B9 -> 0.41190539 | G9: =100*('Parameter <x, y>'!L9-B9)/B9 -> 3.0712577 | H9: =100*('Parameter <x, y>'!Q9-B9)/B9 -> 0 | J9: =100*('Parameter <x, y>'!D9-C9)/C9 -> 5.5022079 | K9: =100*('Parameter <x, y>'!I9-C9)/C9 -> 0 | L9: =100*('Parameter <x, y>'!N9-C9)/C9 -> 0 | M9: =100*('Parameter <x, y>'!S9-C9)/C9 -> 6.7097898 | O9: 100 Jobs | P9: =AVERAGE(E783:E962) -> 1.4783687 | Q9: =AVERAGE(F783:F962) -> 1.8792799 | R9: =AVERAGE(G783:G962) -> 1.7521462 | S9: =AVERAGE(H783:H962) -> 2.7100171
B10: =MIN('Parameter <x, y>'!B10,'Parameter <x, y>'!G10,'Parameter <x, y>'!L10,'Parameter <x, y>'!Q10) -> 10641 | C10: =MIN('Parameter <x, y>'!D10,'Parameter <x, y>'!I10,'Parameter <x, y>'!N10,'Parameter <x, y>'!S10) -> 10293.6 | E10: =100*('Parameter <x, y>'!B10-B10)/B10 -> 7.6524763 | F10: =100*('Parameter <x, y>'!G10-B10)/B10 -> 0 | G10: =100*('Parameter <x, y>'!L10-B10)/B10 -> 19.734987 | H10: =100*('Parameter <x, y>'!Q10-B10)/B10 -> 73.643455 | J10: =100*('Parameter <x, y>'!D10-C10)/C10 -> 0 | K10: =100*('Parameter <x, y>'!I10-C10)/C10 -> 66.831818 | L10: =100*('Parameter <x, y>'!N10-C10)/C10 -> 21.279241 | M10: =100*('Parameter <x, y>'!S10-C10)/C10 -> 21.284099
B11: =MIN('Parameter <x, y>'!B11,'Parameter <x, y>'!G11,'Parameter <x, y>'!L11,'Parameter <x, y>'!Q11) -> 11187 | C11: =MIN('Parameter <x, y>'!D11,'Parameter <x, y>'!I11,'Parameter <x, y>'!N11,'Parameter <x, y>'!S11) -> 10494.4 | E11: =100*('Parameter <x, y>'!B11-B11)/B11 -> 18.229195 | F11: =100*('Parameter <x, y>'!G11-B11)/B11 -> 0 | G11: =100*('Parameter <x, y>'!L11-B11)/B11 -> 3.3208188 | H11: =100*('Parameter <x, y>'!Q11-B11)/B11 -> 6.1356932 | J11: =100*('Parameter <x, y>'!D11-C11)/C11 -> 3.9840296 | K11: =100*('Parameter <x, y>'!I11-C11)/C11 -> 0 | L11: =100*('Parameter <x, y>'!N11-C11)/C11 -> 18.936766 | M11: =100*('Parameter <x, y>'!S11-C11)/C11 -> 13.827375 | O11: GA2
B12: =MIN('Parameter <x, y>'!B12,'Parameter <x, y>'!G12,'Parameter <x, y>'!L12,'Parameter <x, y>'!Q12) -> 8258.7 | C12: =MIN('Parameter <x, y>'!D12,'Parameter <x, y>'!I12,'Parameter <x, y>'!N12,'Parameter <x, y>'!S12) -> 7665.7 | E12: =100*('Parameter <x, y>'!B12-B12)/B12 -> 2.1286643 | F12: =100*('Parameter <x, y>'!G12-B12)/B12 -> 0 | G12: =100*('Parameter <x, y>'!L12-B12)/B12 -> 9.6661702 | H12: =100*('Parameter <x, y>'!Q12-B12)/B12 -> 3.328611 | J12: =100*('Parameter <x, y>'!D12-C12)/C12 -> 24.725726 | K12: =100*('Parameter <x, y>'!I12-C12)/C12 -> 2.6090246 | L12: =100*('Parameter <x, y>'!N12-C12)/C12 -> 0 | M12: =100*('Parameter <x, y>'!S12-C12)/C12 -> 24.753121 | P12: <0,0> | Q12: <0,1> | R12: <1,0> | S12: <1,1>
B13: =MIN('Parameter <x, y>'!B13,'Parameter <x, y>'!G13,'Parameter <x, y>'!L13,'Parameter <x, y>'!Q13) -> 5576.6 | C13: =MIN('Parameter <x, y>'!D13,'Parameter <x, y>'!I13,'Parameter <x, y>'!N13,'Parameter <x, y>'!S13) -> 6096.2 | E13: =100*('Parameter <x, y>'!B13-B13)/B13 -> 12.030628 | F13: =100*('Parameter <x, y>'!G13-B13)/B13 -> 18.45569 | G13: =100*('Parameter <x, y>'!L13-B13)/B13 -> 0 | H13: =100*('Parameter <x, y>'!Q13-B13)/B13 -> 41.310117 | J13: =100*('Parameter <x, y>'!D13-C13)/C13 -> 0 | K13: =100*('Parameter <x, y>'!I13-C13)/C13 -> 2.481874 | L13: =100*('Parameter <x, y>'!N13-C13)/C13 -> 1.6403661 | M13: =100*('Parameter <x, y>'!S13-C13)/C13 -> 28.163446 | O13: 8 Jobs | P13: =AVERAGE(J3:J302) -> 4.8062347 | Q13: =AVERAGE(K3:K302) -> 7.5121597 | R13: =AVERAGE(L3:L302) -> 4.2834636 | S13: =AVERAGE(M3:M302) -> 17.481847
B14: =MIN('Parameter <x, y>'!B14,'Parameter <x, y>'!G14,'Parameter <x, y>'!L14,'Parameter <x, y>'!Q14) -> 11567 | C14: =MIN('Parameter <x, y>'!D14,'Parameter <x, y>'!I14,'Parameter <x, y>'!N14,'Parameter <x, y>'!S14) -> 8981.9 | E14: =100*('Parameter <x, y>'!B14-B14)/B14 -> 0 | F14: =100*('Parameter <x, y>'!G14-B14)/B14 -> 0 | G14: =100*('Parameter <x, y>'!L14-B14)/B14 -> 3.0154751 | H14: =100*('Parameter <x, y>'!Q14-B14)/B14 -> 31.587274 | J14: =100*('Parameter <x, y>'!D14-C14)/C14 -> 0 | K14: =100*('Parameter <x, y>'!I14-C14)/C14 -> 30.502455 | L14: =100*('Parameter <x, y>'!N14-C14)/C14 -> 24.652913 | M14: =100*('Parameter <x, y>'!S14-C14)/C14 -> 38.592057 | O14: 20 Jobs | P14: =AVERAGE(J303:J602) -> 22.396564 | Q14: =AVERAGE(K303:K602) -> 23.591228 | R14: =AVERAGE(L303:L602) -> 16.085848 | S14: =AVERAGE(M303:M602) -> 32.879638
B15: =MIN('Parameter <x, y>'!B15,'Parameter <x, y>'!G15,'Parameter <x, y>'!L15,'Parameter <x, y>'!Q15) -> 10105 | C15: =MIN('Parameter <x, y>'!D15,'Parameter <x, y>'!I15,'Parameter <x, y>'!N15,'Parameter <x, y>'!S15) -> 9704.7 | E15: =100*('Parameter <x, y>'!B15-B15)/B15 -> 2.0593765 | F15: =100*('Parameter <x, y>'!G15-B15)/B15 -> 0 | G15: =100*('Parameter <x, y>'!L15-B15)/B15 -> 4.4878773 | H15: =100*('Parameter <x, y>'!Q15-B15)/B15 -> 8.172192 | J15: =100*('Parameter <x, y>'!D15-C15)/C15 -> 0 | K15: =100*('Parameter <x, y>'!I15-C15)/C15 -> 0 | L15: =100*('Parameter <x, y>'!N15-C15)/C15 -> 0.23184642 | M15: =100*('Parameter <x, y>'!S15-C15)/C15 -> 22.305687 | O15: 50 Jobs | P15: =AVERAGE(J603:J782) -> 8.9608132 | Q15: =AVERAGE(K603:K782) -> 12.074712 | R15: =AVERAGE(L603:L782) -> 1.8694924 | S15: =AVERAGE(M603:M782) -> 11.388232
B16: =MIN('Parameter <x, y>'!B16,'Parameter <x, y>'!G16,'Parameter <x, y>'!L16,'Parameter <x, y>'!Q16) -> 9695.5 | C16: =MIN('Parameter <x, y>'!D16,'Parameter <x, y>'!I16,'Parameter <x, y>'!N16,'Parameter <x, y>'!S16) -> 10032.2 | E16: =100*('Parameter <x, y>'!B16-B16)/B16 -> 50.366665 | F16: =100*('Parameter <x, y>'!G16-B16)/B16 -> 53.042133 | G16: =100*('Parameter <x, y>'!L16-B16)/B16 -> 0 | H16: =100*('Parameter <x, y>'!Q16-B16)/B16 -> 54.684132 | J16: =100*('Parameter <x, y>'!D16-C16)/C16 -> 41.05281 | K16: =100*('Parameter <x, y>'!I16-C16)/C16 -> 41.05281 | L16: =100*('Parameter <x, y>'!N16-C16)/C16 -> 38.062439 | M16: =100*('Parameter <x, y>'!S16-C16)/C16 -> 0 | O16: 100 Jobs | P16: =AVERAGE(J783:J962) -> 10.582831 | Q16: =AVERAGE(K783:K962) -> 11.449433 | R16: =AVERAGE(L783:L962) -> 1.6646038 | S16: =AVERAGE(M783:M962) -> 4.6932012
B17: =MIN('Parameter <x, y>'!B17,'Parameter <x, y>'!G17,'Parameter <x, y>'!L17,'Parameter <x, y>'!Q17) -> 10702.2 | C17: =MIN('Parameter <x, y>'!D17,'Parameter <x, y>'!I17,'Parameter <x, y>'!N17,'Parameter <x, y>'!S17) -> 11173.5 | E17: =100*('Parameter <x, y>'!B17-B17)/B17 -> 0 | F17: =100*('Parameter <x, y>'!G17-B17)/B17 -> 13.797163 | G17: =100*('Parameter <x, y>'!L17-B17)/B17 -> 9.5671918 | H17: =100*('Parameter <x, y>'!Q17-B17)/B17 -> 9.2364187 | J17: =100*('Parameter <x, y>'!D17-C17)/C17 -> 0 | K17: =100*('Parameter <x, y>'!I17-C17)/C17 -> 12.803508 | L17: =100*('Parameter <x, y>'!N17-C17)/C17 -> 8.9497472 | M17: =100*('Parameter <x, y>'!S17-C17)/C17 -> 2.2875554
B18: =MIN('Parameter <x, y>'!B18,'Parameter <x, y>'!G18,'Parameter <x, y>'!L18,'Parameter <x, y>'!Q18) -> 7720.7 | C18: =MIN('Parameter <x, y>'!D18,'Parameter <x, y>'!I18,'Parameter <x, y>'!N18,'Parameter <x, y>'!S18) -> 7675.2 | E18: =100*('Parameter <x, y>'!B18-B18)/B18 -> 6.6198661 | F18: =100*('Parameter <x, y>'!G18-B18)/B18 -> 0 | G18: =100*('Parameter <x, y>'!L18-B18)/B18 -> 6.6198661 | H18: =100*('Parameter <x, y>'!Q18-B18)/B18 -> 17.278226 | J18: =100*('Parameter <x, y>'!D18-C18)/C18 -> 10.167813 | K18: =100*('Parameter <x, y>'!I18-C18)/C18 -> 10.303315 | L18: =100*('Parameter <x, y>'!N18-C18)/C18 -> 0 | M18: =100*('Parameter <x, y>'!S18-C18)/C18 -> 23.401345
B19: =MIN('Parameter <x, y>'!B19,'Parameter <x, y>'!G19,'Parameter <x, y>'!L19,'Parameter <x, y>'!Q19) -> 8384.2 | C19: =MIN('Parameter <x, y>'!D19,'Parameter <x, y>'!I19,'Parameter <x, y>'!N19,'Parameter <x, y>'!S19) -> 7957.6 | E19: =100*('Parameter <x, y>'!B19-B19)/B19 -> 0 | F19: =100*('Parameter <x, y>'!G19-B19)/B19 -> 0 | G19: =100*('Parameter <x, y>'!L19-B19)/B19 -> 9.7290141 | H19: =100*('Parameter <x, y>'!Q19-B19)/B19 -> 5.4244889 | J19: =100*('Parameter <x, y>'!D19-C19)/C19 -> 3.7699809 | K19: =100*('Parameter <x, y>'!I19-C19)/C19 -> 8.2424349 | L19: =100*('Parameter <x, y>'!N19-C19)/C19 -> 0 | M19: =100*('Parameter <x, y>'!S19-C19)/C19 -> 0
B20: =MIN('Parameter <x, y>'!B20,'Parameter <x, y>'!G20,'Parameter <x, y>'!L20,'Parameter <x, y>'!Q20) -> 6680.5 | C20: =MIN('Parameter <x, y>'!D20,'Parameter <x, y>'!I20,'Parameter <x, y>'!N20,'Parameter <x, y>'!S20) -> 6558.7 | E20: =100*('Parameter <x, y>'!B20-B20)/B20 -> 5.1268618 | F20: =100*('Parameter <x, y>'!G20-B20)/B20 -> 0 | G20: =100*('Parameter <x, y>'!L20-B20)/B20 -> 6.0399671 | H20: =100*('Parameter <x, y>'!Q20-B20)/B20 -> 12.783474 | J20: =100*('Parameter <x, y>'!D20-C20)/C20 -> 2.5767301 | K20: =100*('Parameter <x, y>'!I20-C20)/C20 -> 0 | L20: =100*('Parameter <x, y>'!N20-C20)/C20 -> 2.5767301 | M20: =100*('Parameter <x, y>'!S20-C20)/C20 -> 4.8652934
B21: =MIN('Parameter <x, y>'!B21,'Parameter <x, y>'!G21,'Parameter <x, y>'!L21,'Parameter <x, y>'!Q21) -> 6656.8 | C21: =MIN('Parameter <x, y>'!D21,'Parameter <x, y>'!I21,'Parameter <x, y>'!N21,'Parameter <x, y>'!S21) -> 6620.1 | E21: =100*('Parameter <x, y>'!B21-B21)/B21 -> 7.5697032 | F21: =100*('Parameter <x, y>'!G21-B21)/B21 -> 16.79035 | G21: =100*('Parameter <x, y>'!L21-B21)/B21 -> 19.3922 | H21: =100*('Parameter <x, y>'!Q21-B21)/B21 -> 0 | J21: =100*('Parameter <x, y>'!D21-C21)/C21 -> 1.8217247 | K21: =100*('Parameter <x, y>'!I21-C21)/C21 -> 0 | L21: =100*('Parameter <x, y>'!N21-C21)/C21 -> 1.8217247 | M21: =100*('Parameter <x, y>'!S21-C21)/C21 -> 6.7446111
B22: =MIN('Parameter <x, y>'!B22,'Parameter <x, y>'!G22,'Parameter <x, y>'!L22,'Parameter <x, y>'!Q22) -> 6383.8 | C22: =MIN('Parameter <x, y>'!D22,'Parameter <x, y>'!I22,'Parameter <x, y>'!N22,'Parameter <x, y>'!S22) -> 5444.4 | E22: =100*('Parameter <x, y>'!B22-B22)/B22 -> 0.71744102 | F22: =100*('Parameter <x, y>'!G22-B22)/B22 -> 0 | G22: =100*('Parameter <x, y>'!L22-B22)/B22 -> 19.159435 | H22: =100*('Parameter <x, y>'!Q22-B22)/B22 -> 2.4812807 | J22: =100*('Parameter <x, y>'!D22-C22)/C22 -> 11.830505 | K22: =100*('Parameter <x, y>'!I22-C22)/C22 -> 23.510396 | L22: =100*('Parameter <x, y>'!N22-C22)/C22 -> 0 | M22: =100*('Parameter <x, y>'!S22-C22)/C22 -> 24.496731
B23: =MIN('Parameter <x, y>'!B23,'Parameter <x, y>'!G23,'Parameter <x, y>'!L23,'Parameter <x, y>'!Q23) -> 8696 | C23: =MIN('Parameter <x, y>'!D23,'Parameter <x, y>'!I23,'Parameter <x, y>'!N23,'Parameter <x, y>'!S23) -> 8767.3 | E23: =100*('Parameter <x, y>'!B23-B23)/B23 -> 32.98758 | F23: =100*('Parameter <x, y>'!G23-B23)/B23 -> 0 | G23: =100*('Parameter <x, y>'!L23-B23)/B23 -> 1.7617295 | H23: =100*('Parameter <x, y>'!Q23-B23)/B23 -> 16.968721 | J23: =100*('Parameter <x, y>'!D23-C23)/C23 -> 60.927538 | K23: =100*('Parameter <x, y>'!I23-C23)/C23 -> 60.927538 | L23: =100*('Parameter <x, y>'!N23-C23)/C23 -> 5.5878092 | M23: =100*('Parameter <x, y>'!S23-C23)/C23 -> 0
B24: =MIN('Parameter <x, y>'!B24,'Parameter <x, y>'!G24,'Parameter <x, y>'!L24,'Parameter <x, y>'!Q24) -> 10581.8 | C24: =MIN('Parameter <x, y>'!D24,'Parameter <x, y>'!I24,'Parameter <x, y>'!N24,'Parameter <x, y>'!S24) -> 9914.2 | E24: =100*('Parameter <x, y>'!B24-B24)/B24 -> 0.34398685 | F24: =100*('Parameter <x, y>'!G24-B24)/B24 -> 0 | G24: =100*('Parameter <x, y>'!L24-B24)/B24 -> 34.408135 | H24: =100*('Parameter <x, y>'!Q24-B24)/B24 -> 0.8694173 | J24: =100*('Parameter <x, y>'!D24-C24)/C24 -> 46.957899 | K24: =100*('Parameter <x, y>'!I24-C24)/C24 -> 7.1009259 | L24: =100*('Parameter <x, y>'!N24-C24)/C24 -> 8.8590103 | M24: =100*('Parameter <x, y>'!S24-C24)/C24 -> 0
B25: =MIN('Parameter <x, y>'!B25,'Parameter <x, y>'!G25,'Parameter <x, y>'!L25,'Parameter <x, y>'!Q25) -> 9315.1 | C25: =MIN('Parameter <x, y>'!D25,'Parameter <x, y>'!I25,'Parameter <x, y>'!N25,'Parameter <x, y>'!S25) -> 8667.9 | E25: =100*('Parameter <x, y>'!B25-B25)/B25 -> 1.2721281 | F25: =100*('Parameter <x, y>'!G25-B25)/B25 -> 10.936007 | G25: =100*('Parameter <x, y>'!L25-B25)/B25 -> 0 | H25: =100*('Parameter <x, y>'!Q25-B25)/B25 -> 10.025657 | J25: =100*('Parameter <x, y>'!D25-C25)/C25 -> 67.876879 | K25: =100*('Parameter <x, y>'!I25-C25)/C25 -> 78.354619 | L25: =100*('Parameter <x, y>'!N25-C25)/C25 -> 0 | M25: =100*('Parameter <x, y>'!S25-C25)/C25 -> 50.152863
B26: =MIN('Parameter <x, y>'!B26,'Parameter <x, y>'!G26,'Parameter <x, y>'!L26,'Parameter <x, y>'!Q26) -> 11098.4 | C26: =MIN('Parameter <x, y>'!D26,'Parameter <x, y>'!I26,'Parameter <x, y>'!N26,'Parameter <x, y>'!S26) -> 10881.6 | E26: =100*('Parameter <x, y>'!B26-B26)/B26 -> 4.1141065 | F26: =100*('Parameter <x, y>'!G26-B26)/B26 -> 18.009803 | G26: =100*('Parameter <x, y>'!L26-B26)/B26 -> 0 | H26: =100*('Parameter <x, y>'!Q26-B26)/B26 -> 3.9375045 | J26: =100*('Parameter <x, y>'!D26-C26)/C26 -> 3.8836201 | K26: =100*('Parameter <x, y>'!I26-C26)/C26 -> 6.0083076 | L26: =100*('Parameter <x, y>'!N26-C26)/C26 -> 0 | M26: =100*('Parameter <x, y>'!S26-C26)/C26 -> 20.261726
B27: =MIN('Parameter <x, y>'!B27,'Parameter <x, y>'!G27,'Parameter <x, y>'!L27,'Parameter <x, y>'!Q27) -> 9400.2 | C27: =MIN('Parameter <x, y>'!D27,'Parameter <x, y>'!I27,'Parameter <x, y>'!N27,'Parameter <x, y>'!S27) -> 8778.4 | E27: =100*('Parameter <x, y>'!B27-B27)/B27 -> 0 | F27: =100*('Parameter <x, y>'!G27-B27)/B27 -> 1.1627412 | G27: =100*('Parameter <x, y>'!L27-B27)/B27 -> 4.2339525 | H27: =100*('Parameter <x, y>'!Q27-B27)/B27 -> 44.022468 | J27: =100*('Parameter <x, y>'!D27-C27)/C27 -> 0 | K27: =100*('Parameter <x, y>'!I27-C27)/C27 -> 0 | L27: =100*('Parameter <x, y>'!N27-C27)/C27 -> 1.590267 | M27: =100*('Parameter <x, y>'!S27-C27)/C27 -> 78.355965
B28: =MIN('Parameter <x, y>'!B28,'Parameter <x, y>'!G28,'Parameter <x, y>'!L28,'Parameter <x, y>'!Q28) -> 7931.7 | C28: =MIN('Parameter <x, y>'!D28,'Parameter <x, y>'!I28,'Parameter <x, y>'!N28,'Parameter <x, y>'!S28) -> 7390.8 | E28: =100*('Parameter <x, y>'!B28-B28)/B28 -> 6.2735605 | F28: =100*('Parameter <x, y>'!G28-B28)/B28 -> 8.0562805 | G28: =100*('Parameter <x, y>'!L28-B28)/B28 -> 11.000164 | H28: =100*('Parameter <x, y>'!Q28-B28)/B28 -> 0 | J28: =100*('Parameter <x, y>'!D28-C28)/C28 -> 0 | K28: =100*('Parameter <x, y>'!I28-C28)/C28 -> 4.2295827 | L28: =100*('Parameter <x, y>'!N28-C28)/C28 -> 6.9383558 | M28: =100*('Parameter <x, y>'!S28-C28)/C28 -> 17.566434
... B302: =MIN('Parameter <x, y>'!B302,'Parameter <x, y>'!G302,'Parameter <x, y>'!L302,'Parameter <x, y>'!Q302) -> 9936.5 | C302: =MIN('Parameter <x, y>'!D302,'Parameter <x, y>'!I302,'Parameter <x, y>'!N302,'Parameter <x, y>'!S302) -> 11048.3 | E302: =100*('Parameter <x, y>'!B302-B302)/B302 -> 12.85664 | F302: =100*('Parameter <x, y>'!G302-B302)/B302 -> 0 | G302: =100*('Parameter <x, y>'!L302-B302)/B302 -> 15.632265 | H302: =100*('Parameter <x, y>'!Q302-B302)/B302 -> 12.582901 | J302: =100*('Parameter <x, y>'!D302-C302)/C302 -> 1.3667261 | K302: =100*('Parameter <x, y>'!I302-C302)/C302 -> 0 | L302: =100*('Parameter <x, y>'!N302-C302)/C302 -> 2.8203434 | M302: =100*('Parameter <x, y>'!S302-C302)/C302 -> 6.7657468
A303: 20 jobs | B303: =MIN('Parameter <x, y>'!B303,'Parameter <x, y>'!G303,'Parameter <x, y>'!L303,'Parameter <x, y>'!Q303) -> 76540.4 | C303: =MIN('Parameter <x, y>'!D303,'Parameter <x, y>'!I303,'Parameter <x, y>'!N303,'Parameter <x, y>'!S303) -> 73812.4 | E303: =100*('Parameter <x, y>'!B303-B303)/B303 -> 23.938338 | F303: =100*('Parameter <x, y>'!G303-B303)/B303 -> 47.335263 | G303: =100*('Parameter <x, y>'!L303-B303)/B303 -> 15.712356 | H303: =100*('Parameter <x, y>'!Q303-B303)/B303 -> 0 | J303: =100*('Parameter <x, y>'!D303-C303)/C303 -> 38.02288 | K303: =100*('Parameter <x, y>'!I303-C303)/C303 -> 55.8058 | L303: =100*('Parameter <x, y>'!N303-C303)/C303 -> 0 | M303: =100*('Parameter <x, y>'!S303-C303)/C303 -> 45.29808
B304: =MIN('Parameter <x, y>'!B304,'Parameter <x, y>'!G304,'Parameter <x, y>'!L304,'Parameter <x, y>'!Q304) -> 86453.1 | C304: =MIN('Parameter <x, y>'!D304,'Parameter <x, y>'!I304,'Parameter <x, y>'!N304,'Parameter <x, y>'!S304) -> 63658.8 | E304: =100*('Parameter <x, y>'!B304-B304)/B304 -> 34.595521 | F304: =100*('Parameter <x, y>'!G304-B304)/B304 -> 0 | G304: =100*('Parameter <x, y>'!L304-B304)/B304 -> 9.3641524 | H304: =100*('Parameter <x, y>'!Q304-B304)/B304 -> 16.103413 | J304: =100*('Parameter <x, y>'!D304-C304)/C304 -> 58.097545 | K304: =100*('Parameter <x, y>'!I304-C304)/C304 -> 5.3155259 | L304: =100*('Parameter <x, y>'!N304-C304)/C304 -> 73.840852 | M304: =100*('Parameter <x, y>'!S304-C304)/C304 -> 0
B305: =MIN('Parameter <x, y>'!B305,'Parameter <x, y>'!G305,'Parameter <x, y>'!L305,'Parameter <x, y>'!Q305) -> 69772.9 | C305: =MIN('Parameter <x, y>'!D305,'Parameter <x, y>'!I305,'Parameter <x, y>'!N305,'Parameter <x, y>'!S305) -> 66979.3 | E305: =100*('Parameter <x, y>'!B305-B305)/B305 -> 26.616064 | F305: =100*('Parameter <x, y>'!G305-B305)/B305 -> 0 | G305: =100*('Parameter <x, y>'!L305-B305)/B305 -> 22.717989 | H305: =100*('Parameter <x, y>'!Q305-B305)/B305 -> 22.718849 | J305: =100*('Parameter <x, y>'!D305-C305)/C305 -> 38.416794 | K305: =100*('Parameter <x, y>'!I305-C305)/C305 -> 40.067006 | L305: =100*('Parameter <x, y>'!N305-C305)/C305 -> 0 | M305: =100*('Parameter <x, y>'!S305-C305)/C305 -> 17.120812
B306: =MIN('Parameter <x, y>'!B306,'Parameter <x, y>'!G306,'Parameter <x, y>'!L306,'Parameter <x, y>'!Q306) -> 76449.4 | C306: =MIN('Parameter <x, y>'!D306,'Parameter <x, y>'!I306,'Parameter <x, y>'!N306,'Parameter <x, y>'!S306) -> 76549 | E306: =100*('Parameter <x, y>'!B306-B306)/B306 -> 37.290809 | F306: =100*('Parameter <x, y>'!G306-B306)/B306 -> 10.611986 | G306: =100*('Parameter <x, y>'!L306-B306)/B306 -> 0 | H306: =100*('Parameter <x, y>'!Q306-B306)/B306 -> 12.551832 | J306: =100*('Parameter <x, y>'!D306-C306)/C306 -> 22.410874 | K306: =100*('Parameter <x, y>'!I306-C306)/C306 -> 28.826895 | L306: =100*('Parameter <x, y>'!N306-C306)/C306 -> 0 | M306: =100*('Parameter <x, y>'!S306-C306)/C306 -> 11.866125
B307: =MIN('Parameter <x, y>'!B307,'Parameter <x, y>'!G307,'Parameter <x, y>'!L307,'Parameter <x, y>'!Q307) -> 117145 | C307: =MIN('Parameter <x, y>'!D307,'Parameter <x, y>'!I307,'Parameter <x, y>'!N307,'Parameter <x, y>'!S307) -> 57976.7 | E307: =100*('Parameter <x, y>'!B307-B307)/B307 -> 17.683213 | F307: =100*('Parameter <x, y>'!G307-B307)/B307 -> 22.373981 | G307: =100*('Parameter <x, y>'!L307-B307)/B307 -> 24.190533 | H307: =100*('Parameter <x, y>'!Q307-B307)/B307 -> 0 | J307: =100*('Parameter <x, y>'!D307-C307)/C307 -> 114.74144 | K307: =100*('Parameter <x, y>'!I307-C307)/C307 -> 96.12189 | L307: =100*('Parameter <x, y>'!N307-C307)/C307 -> 0 | M307: =100*('Parameter <x, y>'!S307-C307)/C307 -> 126.26848
B308: =MIN('Parameter <x, y>'!B308,'Parameter <x, y>'!G308,'Parameter <x, y>'!L308,'Parameter <x, y>'!Q308) -> 109897 | C308: =MIN('Parameter <x, y>'!D308,'Parameter <x, y>'!I308,'Parameter <x, y>'!N308,'Parameter <x, y>'!S308) -> 68639.5 | E308: =100*('Parameter <x, y>'!B308-B308)/B308 -> 0 | F308: =100*('Parameter <x, y>'!G308-B308)/B308 -> 18.608333 | G308: =100*('Parameter <x, y>'!L308-B308)/B308 -> 0.98364833 | H308: =100*('Parameter <x, y>'!Q308-B308)/B308 -> 6.6161952 | J308: =100*('Parameter <x, y>'!D308-C308)/C308 -> 0 | K308: =100*('Parameter <x, y>'!I308-C308)/C308 -> 34.721261 | L308: =100*('Parameter <x, y>'!N308-C308)/C308 -> 20.843683 | M308: =100*('Parameter <x, y>'!S308-C308)/C308 -> 56.758135
B309: =MIN('Parameter <x, y>'!B309,'Parameter <x, y>'!G309,'Parameter <x, y>'!L309,'Parameter <x, y>'!Q309) -> 59112.2 | C309: =MIN('Parameter <x, y>'!D309,'Parameter <x, y>'!I309,'Parameter <x, y>'!N309,'Parameter <x, y>'!S309) -> 66932.9 | E309: =100*('Parameter <x, y>'!B309-B309)/B309 -> 14.265583 | F309: =100*('Parameter <x, y>'!G309-B309)/B309 -> 0 | G309: =100*('Parameter <x, y>'!L309-B309)/B309 -> 19.231732 | H309: =100*('Parameter <x, y>'!Q309-B309)/B309 -> 3.5711748 | J309: =100*('Parameter <x, y>'!D309-C309)/C309 -> 40.279593 | K309: =100*('Parameter <x, y>'!I309-C309)/C309 -> 1.2254063 | L309: =100*('Parameter <x, y>'!N309-C309)/C309 -> 0 | M309: =100*('Parameter <x, y>'!S309-C309)/C309 -> 4.6994826
B310: =MIN('Parameter <x, y>'!B310,'Parameter <x, y>'!G310,'Parameter <x, y>'!L310,'Parameter <x, y>'!Q310) -> 88693.5 | C310: =MIN('Parameter <x, y>'!D310,'Parameter <x, y>'!I310,'Parameter <x, y>'!N310,'Parameter <x, y>'!S310) -> 66482.3 | E310: =100*('Parameter <x, y>'!B310-B310)/B310 -> 56.866061 | F310: =100*('Parameter <x, y>'!G310-B310)/B310 -> 17.011957 | G310: =100*('Parameter <x, y>'!L310-B310)/B310 -> 18.618614 | H310: =100*('Parameter <x, y>'!Q310-B310)/B310 -> 0 | J310: =100*('Parameter <x, y>'!D310-C310)/C310 -> 0 | K310: =100*('Parameter <x, y>'!I310-C310)/C310 -> 79.816282 | L310: =100*('Parameter <x, y>'!N310-C310)/C310 -> 57.650984 | M310: =100*('Parameter <x, y>'!S310-C310)/C310 -> 63.123117
B311: =MIN('Parameter <x, y>'!B311,'Parameter <x, y>'!G311,'Parameter <x, y>'!L311,'Parameter <x, y>'!Q311) -> 86295.3 | C311: =MIN('Parameter <x, y>'!D311,'Parameter <x, y>'!I311,'Parameter <x, y>'!N311,'Parameter <x, y>'!S311) -> 60837.5 | E311: =100*('Parameter <x, y>'!B311-B311)/B311 -> 0 | F311: =100*('Parameter <x, y>'!G311-B311)/B311 -> 4.0538708 | G311: =100*('Parameter <x, y>'!L311-B311)/B311 -> 25.490032 | H311: =100*('Parameter <x, y>'!Q311-B311)/B311 -> 28.878398 | J311: =100*('Parameter <x, y>'!D311-C311)/C311 -> 37.30676 | K311: =100*('Parameter <x, y>'!I311-C311)/C311 -> 5.8182864 | L311: =100*('Parameter <x, y>'!N311-C311)/C311 -> 0 | M311: =100*('Parameter <x, y>'!S311-C311)/C311 -> 13.89324
B312: =MIN('Parameter <x, y>'!B312,'Parameter <x, y>'!G312,'Parameter <x, y>'!L312,'Parameter <x, y>'!Q312) -> 73533.4 | C312: =MIN('Parameter <x, y>'!D312,'Parameter <x, y>'!I312,'Parameter <x, y>'!N312,'Parameter <x, y>'!S312) -> 81535.9 | E312: =100*('Parameter <x, y>'!B312-B312)/B312 -> 31.78406 | F312: =100*('Parameter <x, y>'!G312-B312)/B312 -> 42.297242 | G312: =100*('Parameter <x, y>'!L312-B312)/B312 -> 38.369775 | H312: =100*('Parameter <x, y>'!Q312-B312)/B312 -> 0 | J312: =100*('Parameter <x, y>'!D312-C312)/C312 -> 44.611147 | K312: =100*('Parameter <x, y>'!I312-C312)/C312 -> 41.136604 | L312: =100*('Parameter <x, y>'!N312-C312)/C312 -> 14.658328 | M312: =100*('Parameter <x, y>'!S312-C312)/C312 -> 0
B313: =MIN('Parameter <x, y>'!B313,'Parameter <x, y>'!G313,'Parameter <x, y>'!L313,'Parameter <x, y>'!Q313) -> 105247 | C313: =MIN('Parameter <x, y>'!D313,'Parameter <x, y>'!I313,'Parameter <x, y>'!N313,'Parameter <x, y>'!S313) -> 62145.4 | E313: =100*('Parameter <x, y>'!B313-B313)/B313 -> 49.955818 | F313: =100*('Parameter <x, y>'!G313-B313)/B313 -> 30.454075 | G313: =100*('Parameter <x, y>'!L313-B313)/B313 -> 0 | H313: =100*('Parameter <x, y>'!Q313-B313)/B313 -> 2.3012532 | J313: =100*('Parameter <x, y>'!D313-C313)/C313 -> 83.695012 | K313: =100*('Parameter <x, y>'!I313-C313)/C313 -> 91.042298 | L313: =100*('Parameter <x, y>'!N313-C313)/C313 -> 0 | M313: =100*('Parameter <x, y>'!S313-C313)/C313 -> 73.525313
...

Sheet GA Arroyo
B1: <0, 0> | O1: <0, 1> | AB1: <1, 1> | AO1: <1, 0>
A2: nIter: 500 psize: 50 | B2: pMut 0.1 | C2: OV | D2: T(s) | E2: pMut 0.2 | F2: OV | G2: T(s) | H2: pMut 0.3 | I2: OV | J2: T(s) | K2: pMut 0.5 | L2: OV | M2: T(s) | O2: pMut 0.1 | P2: OV | Q2: T(s) | R2: pMut 0.2 | S2: OV | T2: T(s) | U2: pMut 0.3 | V2: OV | W2: T(s) | X2: pMut 0.5 | Y2: OV | Z2: T(s) | AB2: pMut 0.1 | AC2: OV | AD2: T(s) | AE2: pMut 0.2 | AF2: OV | AG2: T(s) | AH2: pMut 0.3 | AI2: OV | AJ2: T(s) | AK2: pMut 0.5 | AL2: OV | AM2: T(s) | AO2: pMut 0.1 | AP2: OV | AQ2: T(s) | AR2: pMut 0.2 | AS2: OV | AT2: T(s) | AU2: pMut 0.3 | AV2: OV | AW2: T(s) | AX2: pMut 0.5 | AY2: OV | AZ2: T(s)
B3: 11423.2 | C3: 0 | D3: 0 | E3: 11316.2 | F3: 0 | G3: 0 | H3: 11505.4 | I3: 0 | J3: 0 | K3: 11470.6 | L3: 0 | M3: 0 | O3: 11613.8 | P3: 0 | Q3: 1 | R3: 11747.9 | S3: 0 | T3: 0 | U3: 13861.6 | V3: 27 | W3: 0 | X3: 11316.2 | Y3: 0 | Z3: 0 | AB3: 11981.3 | AC3: 0 | AD3: 0 | AE3: 11845.5 | AF3: 0 | AG3: 0 | AH3: 11925.7 | AI3: 0 | AJ3: 0 | AK3: 11795 | AL3: 0 | AM3: 1 | AO3: 11161.6 | AP3: 0 | AQ3: 0 | AR3: 11685.9 | AS3: 0 | AT3: 0 | AU3: 13861.6 | AV3: 27 | AW3: 0 | AX3: 11316.2 | AY3: 0 | AZ3: 0
B4: 9568.9 | C4: 0 | D4: 0 | E4: 9568.9 | F4: 0 | G4: 0 | H4: 9568.9 | I4: 0 | J4: 0 | K4: 9810 | L4: 0 | M4: 1 | O4: 9568.9 | P4: 0 | Q4: 1 | R4: 10155 | S4: 0 | T4: 0 | U4: 9810 | V4: 0 | W4: 0 | X4: 9568.9 | Y4: 0 | Z4: 1 | AB4: 11155.3 | AC4: 0 | AD4: 0 | AE4: 10560.5 | AF4: 0 | AG4: 0 | AH4: 10684.3 | AI4: 0 | AJ4: 0 | AK4: 12001.3 | AL4: 0 | AM4: 1 | AO4: 10155 | AP4: 0 | AQ4: 0 | AR4: 9568.9 | AS4: 0 | AT4: 1 | AU4: 9568.9 | AV4: 0 | AW4: 0 | AX4: 9568.9 | AY4: 0 | AZ4: 0
B5: 11056 | C5: 0 | D5: 0 | E5: 10978.4 | F5: 0 | G5: 0 | H5: 11056 | I5: 0 | J5: 0 | K5: 10637.1 | L5: 0 | M5: 0 | O5: 10749.9 | P5: 0 | Q5: 0 | R5: 10637.1 | S5: 0 | T5: 0 | U5: 10637.1 | V5: 0 | W5: 0 | X5: 10637.1 | Y5: 0 | Z5: 1 | AB5: 11814.5 | AC5: 0 | AD5: 0 | AE5: 12053.3 | AF5: 0 | AG5: 0 | AH5: 10637.1 | AI5: 0 | AJ5: 1 | AK5: 11169.7 | AL5: 0 | AM5: 0 | AO5: 10978.4 | AP5: 0 | AQ5: 0 | AR5: 10749.9 | AS5: 0 | AT5: 0 | AU5: 10978.4 | AV5: 0 | AW5: 0 | AX5: 10637.1 | AY5: 0 | AZ5: 1
B6: 13626.1 | C6: 19 | D6: 0 | E6: 11948.7 | F6: 0 | G6: 0 | H6: 11446.7 | I6: 0 | J6: 1 | K6: 11446.7 | L6: 0 | M6: 0 | O6: 12508.9 | P6: 0 | Q6: 0 | R6: 11446.7 | S6: 0 | T6: 0 | U6: 11446.7 | V6: 0 | W6: 1 | X6: 11446.7 | Y6: 0 | Z6: 0 | AB6: 12819.9 | AC6: 0 | AD6: 0 | AE6: 12626.9 | AF6: 0 | AG6: 0 | AH6: 13116.3 | AI6: 0 | AJ6: 1 | AK6: 13721.8 | AL6: 0 | AM6: 0 | AO6: 11895.4 | AP6: 0 | AQ6: 0 | AR6: 11948.7 | AS6: 0 | AT6: 0 | AU6: 11446.7 | AV6: 0 | AW6: 0 | AX6: 13346.7 | AY6: 19 | AZ6: 0
B7: 6772.5 | C7: 0 | D7: 0 | E7: 6723.9 | F7: 0 | G7: 0 | H7: 6818.1 | I7: 0 | J7: 0 | K7: 6831.1 | L7: 0 | M7: 0 | O7: 6766.4 | P7: 0 | Q7: 0 | R7: 6723.9 | S7: 0 | T7: 0 | U7: 7612.7 | V7: 0 | W7: 1 | X7: 6723.9 | Y7: 0 | Z7: 0 | AB7: 7498.3 | AC7: 0 | AD7: 0 | AE7: 7643.7 | AF7: 0 | AG7: 0 | AH7: 7060.1 | AI7: 0 | AJ7: 1 | AK7: 7579.9 | AL7: 0 | AM7: 0 | AO7: 6723.9 | AP7: 0 | AQ7: 1 | AR7: 7188.3 | AS7: 0 | AT7: 0 | AU7: 6766.4 | AV7: 0 | AW7: 0 | AX7: 6766.4 | AY7: 0 | AZ7: 0
B8: 6515.7 | C8: 0 | D8: 0 | E8: 6140.1 | F8: 0 | G8: 1 | H8: 6515.7 | I8: 0 | J8: 0 | K8: 6140.1 | L8: 0 | M8: 0 | O8: 6140.1 | P8: 0 | Q8: 0 | R8: 6140.1 | S8: 0 | T8: 1 | U8: 6140.1 | V8: 0 | W8: 0 | X8: 6140.1 | Y8: 0 | Z8: 0 | AB8: 6733.7 | AC8: 0 | AD8: 0 | AE8: 6519.3 | AF8: 0 | AG8: 0 | AH8: 6231.5 | AI8: 0 | AJ8: 1 | AK8: 6661.5 | AL8: 0 | AM8: 0 | AO8: 6140.1 | AP8: 0 | AQ8: 0 | AR8: 6515.7 | AS8: 0 | AT8: 0 | AU8: 6140.1 | AV8: 0 | AW8: 1 | AX8: 6140.1 | AY8: 0 | AZ8: 0
B9: 10380.7 | C9: 0 | D9: 0 | E9: 10149.2 | F9: 0 | G9: 0 | H9: 10779.3 | I9: 0 | J9: 0 | K9: 10156.1 | L9: 0 | M9: 0 | O9: 11184.2 | P9: 0 | Q9: 0 | R9: 9986.9 | S9: 0 | T9: 1 | U9: 10415.3 | V9: 0 | W9: 0 | X9: 10315.1 | Y9: 0 | Z9: 0 | AB9: 10760 | AC9: 0 | AD9: 0 | AE9: 11076.4 | AF9: 0 | AG9: 0 | AH9: 9986.9 | AI9: 0 | AJ9: 1 | AK9: 9986.9 | AL9: 0 | AM9: 0 | AO9: 9986.9 | AP9: 0 | AQ9: 0 | AR9: 10415.3 | AS9: 0 | AT9: 0 | AU9: 9986.9 | AV9: 0 | AW9: 0 | AX9: 9986.9 | AY9: 0 | AZ9: 0
B10: 10193.6 | C10: 0 | D10: 1 | E10: 10894.8 | F10: 0 | G10: 0 | H10: 10784 | I10: 0 | J10: 0 | K10: 10293.6 | L10: 1 | M10: 0 | O10: 10818.1 | P10: 0 | Q10: 0 | R10: 10193.6 | S10: 0 | T10: 1 | U10: 10894.8 | V10: 0 | W10: 0 | X10: 10818.1 | Y10: 0 | Z10: 0 | AB10: 11353.5 | AC10: 0 | AD10: 0 | AE10: 11277.5 | AF10: 0 | AG10: 0 | AH10: 10931.5 | AI10: 0 | AJ10: 1 | AK10: 10818.1 | AL10: 0 | AM10: 0 | AO10: 10784 | AP10: 0 | AQ10: 1 | AR10: 10541 | AS10: 0 | AT10: 0 | AU10: 10784 | AV10: 0 | AW10: 0 | AX10: 10784 | AY10: 0 | AZ10: 0
B11: 10701.2 | C11: 11 | D11: 0 | E11: 11205.7 | F11: 16 | G11: 0 | H11: 10227 | I11: 3 | J11: 1 | K11: 11801.2 | L11: 22 | M11: 0 | O11: 10601.5 | P11: 0 | Q11: 1 | R11: 10701.2 | S11: 11 | T11: 0 | U11: 10701.2 | V11: 11 | W11: 0 | X11: 10701.2 | Y11: 11 | Z11: 1 | AB11: 11721.5 | AC11: 0 | AD11: 0 | AE11: 10776.2 | AF11: 0 | AG11: 1 | AH11: 10494.4 | AI11: 0 | AJ11: 0 | AK11: 10494.4 | AL11: 0 | AM11: 0 | AO11: 10418.1 | AP11: 0 | AQ11: 0 | AR11: 10776.2 | AS11: 0 | AT11: 0 | AU11: 10713.9 | AV11: 9 | AW11: 1 | AX11: 11201.2 | AY11: 16 | AZ11: 0
B12: 7743.3 | C12: 0 | D12: 0 | E12: 7865.7 | F12: 2 | G12: 0 | H12: 7665.7 | I12: 0 | J12: 0 | K12: 7743.3 | L12: 0 | M12: 0 | O12: 8184.5 | P12: 0 | Q12: 0 | R12: 8052.2 | S12: 0 | T12: 0 | U12: 7665.7 | V12: 0 | W12: 1 | X12: 7665.7 | Y12: 0 | Z12: 0 | AB12: 7911.6 | AC12: 0 | AD12: 0 | AE12: 8346.3 | AF12: 0 | AG12: 1 | AH12: 8265.3 | AI12: 0 | AJ12: 0 | AK12: 7911.6 | AL12: 0 | AM12: 0 | AO12: 7911.6 | AP12: 0 | AQ12: 0 | AR12: 7665.7 | AS12: 0 | AT12: 0 | AU12: 7665.7 | AV12: 0 | AW12: 0 | AX12: 7665.7 | AY12: 0 | AZ12: 0
B13: 5938.1 | C13: 1 | D13: 0 | E13: 6351.6 | F13: 0 | G13: 1 | H13: 5796.2 | I13: 0 | J13: 0 | K13: 5682.8 | L13: 0 | M13: 0 | O13: 5796.2 | P13: 0 | Q13: 0 | R13: 5796.2 | S13: 0 | T13: 0 | U13: 5476.6 | V13: 0 | W13: 1 | X13: 5796.2 | Y13: 0 | Z13: 0 | AB13: 7312.9 | AC13: 0 | AD13: 0 | AE13: 6870.7 | AF13: 0 | AG13: 1 | AH13: 7078.3 | AI13: 0 | AJ13: 0 | AK13: 6605.8 | AL13: 0 | AM13: 0 | AO13: 5796.2 | AP13: 0 | AQ13: 1 | AR13: 5476.6 | AS13: 0 | AT13: 0 | AU13: 5838.1 | AV13: 0 | AW13: 0 | AX13: 5796.2 | AY13: 0 | AZ13: 0
B14: 9014.8 | C14: 0 | D14: 0 | E14: 11396.2 | F14: 36 | G14: 0 | H14: 9198.9 | I14: 0 | J14: 0 | K14: 11196.2 | L14: 34 | M14: 1 | O14: 11396.2 | P14: 36 | Q14: 1 | R14: 8986.4 | S14: 0 | T14: 0 | U14: 8986.4 | V14: 0 | W14: 0 | X14: 11196.2 | Y14: 34 | Z14: 0 | AB14: 8932.2 | AC14: 0 | AD14: 0 | AE14: 8932.2 | AF14: 0 | AG14: 1 | AH14: 9198.9 | AI14: 0 | AJ14: 0 | AK14: 9090.6 | AL14: 0 | AM14: 0 | AO14: 8986.4 | AP14: 0 | AQ14: 0 | AR14: 8846.9 | AS14: 0 | AT14: 1 | AU14: 8846.9 | AV14: 0 | AW14: 0 | AX14: 11196.2 | AY14: 34 | AZ14: 0
... B962: 1316260 | C962: 0 | D962: 9 | E962: 1266500 | F962: 0 | G962: 13 | H962: 1292720 | I962: 0 | J962: 11 | K962: 1274740 | L962: 0 | M962: 5 | O962: 1459980 | P962: 0 | Q962: 4 | R962: 1443050 | S962: 0 | T962: 5 | U962: 1398780 | V962: 0 | W962: 4 | X962: 1346560 | Y962: 0 | Z962: 6 | AB962: 1285440 | AC962: 0 | AD962: 6 | AE962: 1304970 | AF962: 0 | AG962: 5 | AH962: 1285800 | AI962: 0 | AJ962: 8 | AK962: 1306480 | AL962: 0 | AM962: 6 | AO962: 1294930 | AP962: 0 | AQ962: 11 | AR962: 1299180 | AS962: 0 | AT962: 16 | AU962: 1328400 | AV962: 0 | AW962: 4 | AX962: 1249480 | AY962: 0 | AZ962: 11

Sheet GA Arroyo Analysis
I1: RPD (ref: Best Min) | T1: RPD <1, 0> (ref: min<1, 0>)
B2: min <0,0> | C2: min <0,1> | D2: min <1,1> | E2: min <1,0> | G2: Best min | I2: <0,0> | J2: <0,1> | K2: <1, 1> | L2: <1, 0> | T2: 0.1 | U2: 0.2 | V2: 0.3 | W2: 0.5
B3: =MIN('GA Arroyo'!B3,'GA Arroyo'!E3,'GA Arroyo'!H3,'GA Arroyo'!K3) -> 11316.2 | C3: =MIN('GA Arroyo'!O3, 'GA Arroyo'!R3, 'GA Arroyo'!U3, 'GA Arroyo'!X3) -> 11316.2 | D3: =MIN('GA Arroyo'!AB3, 'GA Arroyo'!AE3, 'GA Arroyo'!AH3, 'GA Arroyo'!AK3) -> 11795 | E3: =MIN('GA Arroyo'!AO3, 'GA Arroyo'!AR3, 'GA Arroyo'!AU3, 'GA Arroyo'!AX3) -> 11161.6 | G3: =MIN(B3,C3,D3,E3) -> 11161.6 | I3: =(100*(B3-G3))/G3 -> 1.3851061 | J3: =(100*(C3-G3))/G3 -> 1.3851061 | K3: =(100*(D3-G3))/G3 -> 5.6748136 | L3: =(100*(E3-G3))/G3 -> 0 | N3: RPD Average: Parameter Combination Analysis | T3: =(100*('GA Arroyo'!AO3-E3))/E3 -> 0 | U3: =(100*('GA Arroyo'!AR3-E3))/E3 -> 4.6973552 | V3: =(100*('GA Arroyo'!AU3-E3))/E3 -> 24.19008 | W3: =(100*('GA Arroyo'!AX3-E3))/E3 -> 1.3851061 | Y3: RPD Average: probMut Analysis in <1, 0> combination
B4: =MIN('GA Arroyo'!B4,'GA Arroyo'!E4,'GA Arroyo'!H4,'GA Arroyo'!K4) -> 9568.9 | C4: =MIN('GA Arroyo'!O4, 'GA Arroyo'!R4, 'GA Arroyo'!U4, 'GA Arroyo'!X4) -> 9568.9 | D4: =MIN('GA Arroyo'!AB4, 'GA Arroyo'!AE4, 'GA Arroyo'!AH4, 'GA Arroyo'!AK4) -> 10560.5 | E4: =MIN('GA Arroyo'!AO4, 'GA Arroyo'!AR4, 'GA Arroyo'!AU4, 'GA Arroyo'!AX4) -> 9568.9 | G4: =MIN(B4,C4,D4,E4) -> 9568.9 | I4: =(100*(B4-G4))/G4 -> 0 | J4: =(100*(C4-G4))/G4 -> 0 | K4: =(100*(D4-G4))/G4 -> 10.362738 | L4: =(100*(E4-G4))/G4 -> 0 | O4: <0,0> | P4: <0,1> | Q4: <1, 1> | R4: <1, 0> | T4: =(100*('GA Arroyo'!AO4-E4))/E4 -> 6.1250509 | U4: =(100*('GA Arroyo'!AR4-E4))/E4 -> 0 | V4: =(100*('GA Arroyo'!AU4-E4))/E4 -> 0 | W4: =(100*('GA Arroyo'!AX4-E4))/E4 -> 0 | Z4: 0.1 | AA4: 0.2 | AB4: 0.3 | AC4: 0.5
B5: =MIN('GA Arroyo'!B5,'GA Arroyo'!E5,'GA Arroyo'!H5,'GA Arroyo'!K5) -> 10637.1 | C5: =MIN('GA Arroyo'!O5, 'GA Arroyo'!R5, 'GA Arroyo'!U5, 'GA Arroyo'!X5) -> 10637.1 | D5: =MIN('GA Arroyo'!AB5, 'GA Arroyo'!AE5, 'GA Arroyo'!AH5, 'GA Arroyo'!AK5) -> 10637.1 | E5: =MIN('GA Arroyo'!AO5, 'GA Arroyo'!AR5, 'GA Arroyo'!AU5, 'GA Arroyo'!AX5) -> 10637.1 | G5: =MIN(B5,C5,D5,E5) -> 10637.1 | I5: =(100*(B5-G5))/G5 -> 0 | J5: =(100*(C5-G5))/G5 -> 0 | K5: =(100*(D5-G5))/G5 -> 0 | L5: =(100*(E5-G5))/G5 -> 0 | N5: 8 Jobs | O5: =AVERAGE(I3:I302) -> 1.1108944 | P5: =AVERAGE(J3:J302) -> 0.57684811 | Q5: =AVERAGE(K3:K302) -> 7.3465053 | R5: =AVERAGE(L3:L302) -> 2.0765893 | T5: =(100*('GA Arroyo'!AO5-E5))/E5 -> 3.2085813 | U5: =(100*('GA Arroyo'!AR5-E5))/E5 -> 1.0604394 | V5: =(100*('GA Arroyo'!AU5-E5))/E5 -> 3.2085813 | W5: =(100*('GA Arroyo'!AX5-E5))/E5 -> 0 | Y5: 8 Jobs | Z5: =AVERAGE(T3:T302) -> 4.7142493 | AA5: =AVERAGE(U3:U302) -> 4.1939385 | AB5: =AVERAGE(V3:V302) -> 3.4361798 | AC5: =AVERAGE(W3:W302) -> 2.514907
B6: =MIN('GA Arroyo'!B6,'GA Arroyo'!E6,'GA Arroyo'!H6,'GA Arroyo'!K6) -> 11446.7 | C6: =MIN('GA Arroyo'!O6, 'GA Arroyo'!R6, 'GA Arroyo'!U6, 'GA Arroyo'!X6) -> 11446.7 | D6: =MIN('GA Arroyo'!AB6, 'GA Arroyo'!AE6, 'GA Arroyo'!AH6, 'GA Arroyo'!AK6) -> 12626.9 | E6: =MIN('GA Arroyo'!AO6, 'GA Arroyo'!AR6, 'GA Arroyo'!AU6, 'GA Arroyo'!AX6) -> 11446.7 | G6: =MIN(B6,C6,D6,E6) -> 11446.7 | I6: =(100*(B6-G6))/G6 -> 0 | J6: =(100*(C6-G6))/G6 -> 0 | K6: =(100*(D6-G6))/G6 -> 10.310395 | L6: =(100*(E6-G6))/G6 -> 0 | N6: 20 Jobs | O6: =AVERAGE(I303:I602) -> 5.7454658 | P6: =AVERAGE(J303:J602) -> 6.623894 | Q6: =AVERAGE(K303:K602) -> 3.637588 | R6: =AVERAGE(L303:L602) -> 3.9370245 | T6: =(100*('GA Arroyo'!AO6-E6))/E6 -> 3.919907 | U6: =(100*('GA Arroyo'!AR6-E6))/E6 -> 4.3855434 | V6: =(100*('GA Arroyo'!AU6-E6))/E6 -> 0 | W6: =(100*('GA Arroyo'!AX6-E6))/E6 -> 16.59867 | Y6: 20 Jobs | Z6: =AVERAGE(T303:T602) -> 14.662745 | AA6: =AVERAGE(U303:U602) -> 13.826514 | AB6: =AVERAGE(V303:V602) -> 10.851248 | AC6: =AVERAGE(W303:W602) -> 7.7840153
B7: =MIN('GA Arroyo'!B7,'GA Arroyo'!E7,'GA Arroyo'!H7,'GA Arroyo'!K7) -> 6723.9 | C7: =MIN('GA Arroyo'!O7, 'GA Arroyo'!R7, 'GA Arroyo'!U7, 'GA Arroyo'!X7) -> 6723.9 | D7: =MIN('GA Arroyo'!AB7, 'GA Arroyo'!AE7, 'GA Arroyo'!AH7, 'GA Arroyo'!AK7) -> 7060.1 | E7: =MIN('GA Arroyo'!AO7, 'GA Arroyo'!AR7, 'GA Arroyo'!AU7, 'GA Arroyo'!AX7) -> 6723.9 | G7: =MIN(B7,C7,D7,E7) -> 6723.9 | I7: =(100*(B7-G7))/G7 -> 0 | J7: =(100*(C7-G7))/G7 -> 0 | K7: =(100*(D7-G7))/G7 -> 5.0000744 | L7: =(100*(E7-G7))/G7 -> 0 | N7: 50 Jobs | O7: =AVERAGE(I603:I782) -> 1.3410435 | P7: =AVERAGE(J603:J782) -> 7.4112019 | Q7: =AVERAGE(K603:K782) -> 20.13039 | R7: =AVERAGE(L603:L782) -> 1.3213031 | T7: =(100*('GA Arroyo'!AO7-E7))/E7 -> 0 | U7: =(100*('GA Arroyo'!AR7-E7))/E7 -> 6.9067059 | V7: =(100*('GA Arroyo'!AU7-E7))/E7 -> 0.63207365 | W7: =(100*('GA Arroyo'!AX7-E7))/E7 -> 0.63207365 | Y7: 50 Jobs | Z7: =AVERAGE(T603:T782) -> 5.0752607 | AA7: =AVERAGE(U603:U782) -> 4.1990377 | AB7: =AVERAGE(V603:V782) -> 3.2943328 | AC7: =AVERAGE(W603:W782) -> 3.3663971
B8: =MIN('GA Arroyo'!B8,'GA Arroyo'!E8,'GA Arroyo'!H8,'GA Arroyo'!K8) -> 6140.1 | C8: =MIN('GA Arroyo'!O8, 'GA Arroyo'!R8, 'GA Arroyo'!U8, 'GA Arroyo'!X8) -> 6140.1 | D8: =MIN('GA Arroyo'!AB8, 'GA Arroyo'!AE8, 'GA Arroyo'!AH8, 'GA Arroyo'!AK8) -> 6231.5 | E8: =MIN('GA Arroyo'!AO8, 'GA Arroyo'!AR8, 'GA Arroyo'!AU8, 'GA Arroyo'!AX8) -> 6140.1 | G8: =MIN(B8,C8,D8,E8) -> 6140.1 | I8: =(100*(B8-G8))/G8 -> 0 | J8: =(100*(C8-G8))/G8 -> 0 | K8: =(100*(D8-G8))/G8 -> 1.4885751 | L8: =(100*(E8-G8))/G8 -> 0 | N8: 100 Jobs | O8: =AVERAGE(I783:I962) -> 1.3744496 | P8: =AVERAGE(J783:J962) -> 8.0258494 | Q8: =AVERAGE(K783:K962) -> 1.7349571 | R8: =AVERAGE(L783:L962) -> 1.8397303 | T8: =(100*('GA Arroyo'!AO8-E8))/E8 -> 0 | U8: =(100*('GA Arroyo'!AR8-E8))/E8 -> 6.1171642 | V8: =(100*('GA Arroyo'!AU8-E8))/E8 -> 0 | W8: =(100*('GA Arroyo'!AX8-E8))/E8 -> 0 | Y8: 100 Jobs | Z8: =AVERAGE(T783:T962) -> 5.407537 | AA8: =AVERAGE(U783:U962) -> 3.6341816 | AB8: =AVERAGE(V783:V962) -> 3.2601921 | AC8: =AVERAGE(W783:W962) -> 2.7364521
B9: =MIN('GA Arroyo'!B9,'GA Arroyo'!E9,'GA Arroyo'!H9,'GA Arroyo'!K9) -> 10149.2 | C9: =MIN('GA Arroyo'!O9, 'GA Arroyo'!R9, 'GA Arroyo'!U9, 'GA Arroyo'!X9) -> 9986.9 | D9: =MIN('GA Arroyo'!AB9, 'GA Arroyo'!AE9, 'GA Arroyo'!AH9, 'GA Arroyo'!AK9) -> 9986.9 | E9: =MIN('GA Arroyo'!AO9, 'GA Arroyo'!AR9, 'GA Arroyo'!AU9, 'GA Arroyo'!AX9) -> 9986.9 | G9: =MIN(B9,C9,D9,E9) -> 9986.9 | I9: =(100*(B9-G9))/G9 -> 1.6251289 | J9: =(100*(C9-G9))/G9 -> 0 | K9: =(100*(D9-G9))/G9 -> 0 | L9: =(100*(E9-G9))/G9 -> 0 | N9: AVG: | O9: =AVERAGE(O5:O8) -> 2.3929633 | P9: =AVERAGE(P5:P8) -> 5.6594484 | Q9: =AVERAGE(Q5:Q8) -> 8.21236 | R9: =AVERAGE(R5:R8) -> 2.2936618 | T9: =(100*('GA Arroyo'!AO9-E9))/E9 -> 0 | U9: =(100*('GA Arroyo'!AR9-E9))/E9 -> 4.2896194 | V9: =(100*('GA Arroyo'!AU9-E9))/E9 -> 0 | W9: =(100*('GA Arroyo'!AX9-E9))/E9 -> 0 | Y9: AVG: | Z9: =AVERAGE(Z5:Z8) -> 7.464948 | AA9: =AVERAGE(AA5:AA8) -> 6.4634179 | AB9: =AVERAGE(AB5:AB8) -> 5.2104883 | AC9: =AVERAGE(AC5:AC8) -> 4.1004429
B10: =MIN('GA Arroyo'!B10,'GA Arroyo'!E10,'GA Arroyo'!H10,'GA Arroyo'!K10) -> 10193.6 | C10: =MIN('GA Arroyo'!O10, 'GA Arroyo'!R10, 'GA Arroyo'!U10, 'GA Arroyo'!X10) -> 10193.6 | D10: =MIN('GA Arroyo'!AB10, 'GA Arroyo'!AE10, 'GA Arroyo'!AH10, 'GA Arroyo'!AK10) -> 10818.1 | E10: =MIN('GA Arroyo'!AO10, 'GA Arroyo'!AR10, 'GA Arroyo'!AU10, 'GA Arroyo'!AX10) -> 10541 | G10: =MIN(B10,C10,D10,E10) -> 10193.6 | I10: =(100*(B10-G10))/G10 -> 0 | J10: =(100*(C10-G10))/G10 -> 0 | K10: =(100*(D10-G10))/G10 -> 6.126393 | L10: =(100*(E10-G10))/G10 -> 3.4080207 | T10: =(100*('GA Arroyo'!AO10-E10))/E10 -> 2.3052841 | U10: =(100*('GA Arroyo'!AR10-E10))/E10 -> 0 | V10: =(100*('GA Arroyo'!AU10-E10))/E10 -> 2.3052841 | W10: =(100*('GA Arroyo'!AX10-E10))/E10 -> 2.3052841
B11: =MIN('GA Arroyo'!B11,'GA Arroyo'!E11,'GA Arroyo'!H11,'GA Arroyo'!K11) -> 10227 | C11: =MIN('GA Arroyo'!O11, 'GA Arroyo'!R11, 'GA Arroyo'!U11, 'GA Arroyo'!X11) -> 10601.5 | D11: =MIN('GA Arroyo'!AB11, 'GA Arroyo'!AE11, 'GA Arroyo'!AH11, 'GA Arroyo'!AK11) -> 10494.4 | E11: =MIN('GA Arroyo'!AO11, 'GA Arroyo'!AR11, 'GA Arroyo'!AU11, 'GA Arroyo'!AX11) -> 10418.1 | G11: =MIN(B11,C11,D11,E11) -> 10227 | I11: =(100*(B11-G11))/G11 -> 0 | J11: =(100*(C11-G11))/G11 -> 3.6618754 | K11: =(100*(D11-G11))/G11 -> 2.6146475 | L11: =(100*(E11-G11))/G11 -> 1.8685832 | T11: =(100*('GA Arroyo'!AO11-E11))/E11 -> 0 | U11: =(100*('GA Arroyo'!AR11-E11))/E11 -> 3.437287 | V11: =(100*('GA Arroyo'!AU11-E11))/E11 -> 2.8392893 | W11: =(100*('GA Arroyo'!AX11-E11))/E11 -> 7.5167257
B12: =MIN('GA Arroyo'!B12,'GA Arroyo'!E12,'GA Arroyo'!H12,'GA Arroyo'!K12) -> 7665.7 | C12: =MIN('GA Arroyo'!O12, 'GA Arroyo'!R12, 'GA Arroyo'!U12, 'GA Arroyo'!X12) -> 7665.7 | D12: =MIN('GA Arroyo'!AB12, 'GA Arroyo'!AE12, 'GA Arroyo'!AH12, 'GA Arroyo'!AK12) -> 7911.6 | E12: =MIN('GA Arroyo'!AO12, 'GA Arroyo'!AR12, 'GA Arroyo'!AU12, 'GA Arroyo'!AX12) -> 7665.7 | G12: =MIN(B12,C12,D12,E12) -> 7665.7 | I12: =(100*(B12-G12))/G12 -> 0 | J12: =(100*(C12-G12))/G12 -> 0 | K12: =(100*(D12-G12))/G12 -> 3.2077958 | L12: =(100*(E12-G12))/G12 -> 0 | T12: =(100*('GA Arroyo'!AO12-E12))/E12 -> 3.2077958 | U12: =(100*('GA Arroyo'!AR12-E12))/E12 -> 0 | V12: =(100*('GA Arroyo'!AU12-E12))/E12 -> 0 | W12: =(100*('GA Arroyo'!AX12-E12))/E12 -> 0
B13: =MIN('GA Arroyo'!B13,'GA Arroyo'!E13,'GA Arroyo'!H13,'GA Arroyo'!K13) -> 5682.8 | C13: =MIN('GA Arroyo'!O13, 'GA Arroyo'!R13, 'GA Arroyo'!U13, 'GA Arroyo'!X13) -> 5476.6 | D13: =MIN('GA Arroyo'!AB13, 'GA Arroyo'!AE13, 'GA Arroyo'!AH13, 'GA Arroyo'!AK13) -> 6605.8 | E13: =MIN('GA Arroyo'!AO13, 'GA Arroyo'!AR13, 'GA Arroyo'!AU13, 'GA Arroyo'!AX13) -> 5476.6 | G13: =MIN(B13,C13,D13,E13) -> 5476.6 | I13: =(100*(B13-G13))/G13 -> 3.7651097 | J13: =(100*(C13-G13))/G13 -> 0 | K13: =(100*(D13-G13))/G13 -> 20.618632 | L13: =(100*(E13-G13))/G13 -> 0 | T13: =(100*('GA Arroyo'!AO13-E13))/E13 -> 5.8357375 | U13: =(100*('GA Arroyo'!AR13-E13))/E13 -> 0 | V13: =(100*('GA Arroyo'!AU13-E13))/E13 -> 6.6008107 | W13: =(100*('GA Arroyo'!AX13-E13))/E13 -> 5.8357375
B14: =MIN('GA Arroyo'!B14,'GA Arroyo'!E14,'GA Arroyo'!H14,'GA Arroyo'!K14) -> 9014.8 | C14: =MIN('GA Arroyo'!O14, 'GA Arroyo'!R14, 'GA Arroyo'!U14, 'GA Arroyo'!X14) -> 8986.4 | D14: =MIN('GA Arroyo'!AB14, 'GA Arroyo'!AE14, 'GA Arroyo'!AH14, 'GA Arroyo'!AK14) -> 8932.2 | E14: =MIN('GA Arroyo'!AO14, 'GA Arroyo'!AR14, 'GA Arroyo'!AU14, 'GA Arroyo'!AX14) -> 8846.9 | G14: =MIN(B14,C14,D14,E14) -> 8846.9 | I14: =(100*(B14-G14))/G14 -> 1.8978399 | J14: =(100*(C14-G14))/G14 -> 1.5768235 | K14: =(100*(D14-G14))/G14 -> 0.96417954 | L14: =(100*(E14-G14))/G14 -> 0 | T14: =(100*('GA Arroyo'!AO14-E14))/E14 -> 1.5768235 | U14: =(100*('GA Arroyo'!AR14-E14))/E14 -> 0 | V14: =(100*('GA Arroyo'!AU14-E14))/E14 -> 0 | W14: =(100*('GA Arroyo'!AX14-E14))/E14 -> 26.555064
B15: =MIN('GA Arroyo'!B15,'GA Arroyo'!E15,'GA Arroyo'!H15,'GA Arroyo'!K15) -> 9704.7 | C15: =MIN('GA Arroyo'!O15, 'GA Arroyo'!R15, 'GA Arroyo'!U15, 'GA Arroyo'!X15) -> 9704.7 | D15: =MIN('GA Arroyo'!AB15, 'GA Arroyo'!AE15, 'GA Arroyo'!AH15, 'GA Arroyo'!AK15) -> 9704.7 | E15: =MIN('GA Arroyo'!AO15, 'GA Arroyo'!AR15, 'GA Arroyo'!AU15, 'GA Arroyo'!AX15) -> 9727.2 | G15: =MIN(B15,C15,D15,E15) -> 9704.7 | I15: =(100*(B15-G15))/G15 -> 0 | J15: =(100*(C15-G15))/G15 -> 0 | K15: =(100*(D15-G15))/G15 -> 0 | L15: =(100*(E15-G15))/G15 -> 0.23184642 | T15: =(100*('GA Arroyo'!AO15-E15))/E15 -> 6.8066864 | U15: =(100*('GA Arroyo'!AR15-E15))/E15 -> 0 | V15: =(100*('GA Arroyo'!AU15-E15))/E15 -> 8.5461387 | W15: =(100*('GA Arroyo'!AX15-E15))/E15 -> 0
B16: =MIN('GA Arroyo'!B16,'GA Arroyo'!E16,'GA Arroyo'!H16,'GA Arroyo'!K16) -> 8289.5 | C16: =MIN('GA Arroyo'!O16, 'GA Arroyo'!R16, 'GA Arroyo'!U16, 'GA Arroyo'!X16) -> 8289.5 | D16: =MIN('GA Arroyo'!AB16, 'GA Arroyo'!AE16, 'GA Arroyo'!AH16, 'GA Arroyo'!AK16) -> 8289.5 | E16: =MIN('GA Arroyo'!AO16, 'GA Arroyo'!AR16, 'GA Arroyo'!AU16, 'GA Arroyo'!AX16) -> 8289.5 | G16: =MIN(B16,C16,D16,E16) -> 8289.5 | I16: =(100*(B16-G16))/G16 -> 0 | J16: =(100*(C16-G16))/G16 -> 0 | K16: =(100*(D16-G16))/G16 -> 0 | L16: =(100*(E16-G16))/G16 -> 0 | T16: =(100*('GA Arroyo'!AO16-E16))/E16 -> 38.777972 | U16: =(100*('GA Arroyo'!AR16-E16))/E16 -> 0 | V16: =(100*('GA Arroyo'!AU16-E16))/E16 -> 0 | W16: =(100*('GA Arroyo'!AX16-E16))/E16 -> 36.950359
B17: =MIN('GA Arroyo'!B17,'GA Arroyo'!E17,'GA Arroyo'!H17,'GA Arroyo'!K17) -> 12173.5 | C17: =MIN('GA Arroyo'!O17, 'GA Arroyo'!R17, 'GA Arroyo'!U17, 'GA Arroyo'!X17) -> 9904.6 | D17: =MIN('GA Arroyo'!AB17, 'GA Arroyo'!AE17, 'GA Arroyo'!AH17, 'GA Arroyo'!AK17) -> 9904.6 | E17: =MIN('GA Arroyo'!AO17, 'GA Arroyo'!AR17, 'GA Arroyo'!AU17, 'GA Arroyo'!AX17) -> 9887.6 | G17: =MIN(B17,C17,D17,E17) -> 9887.6 | I17: =(100*(B17-G17))/G17 -> 23.118856 | J17: =(100*(C17-G17))/G17 -> 0.17193252 | K17: =(100*(D17-G17))/G17 -> 0.17193252 | L17: =(100*(E17-G17))/G17 -> 0 | T17: =(100*('GA Arroyo'!AO17-E17))/E17 -> 13.005178 | U17: =(100*('GA Arroyo'!AR17-E17))/E17 -> 0 | V17: =(100*('GA Arroyo'!AU17-E17))/E17 -> 26.793155 | W17: =(100*('GA Arroyo'!AX17-E17))/E17 -> 13.005178
B18: =MIN('GA Arroyo'!B18,'GA Arroyo'!E18,'GA Arroyo'!H18,'GA Arroyo'!K18) -> 7658.5 | C18: =MIN('GA Arroyo'!O18, 'GA Arroyo'!R18, 'GA Arroyo'!U18, 'GA Arroyo'!X18) -> 7658.5 | D18: =MIN('GA Arroyo'!AB18, 'GA Arroyo'!AE18, 'GA Arroyo'!AH18, 'GA Arroyo'!AK18) -> 8402.6 | E18: =MIN('GA Arroyo'!AO18, 'GA Arroyo'!AR18, 'GA Arroyo'!AU18, 'GA Arroyo'!AX18) -> 7658.5 | G18: =MIN(B18,C18,D18,E18) -> 7658.5 | I18: =(100*(B18-G18))/G18 -> 0 | J18: =(100*(C18-G18))/G18 -> 0 | K18: =(100*(D18-G18))/G18 -> 9.7160018 | L18: =(100*(E18-G18))/G18 -> 0 | T18: =(100*('GA Arroyo'!AO18-E18))/E18 -> 6.0063981 | U18: =(100*('GA Arroyo'!AR18-E18))/E18 -> 0 | V18: =(100*('GA Arroyo'!AU18-E18))/E18 -> 0.81216948 | W18: =(100*('GA Arroyo'!AX18-E18))/E18 -> 0.21805837
B19: =MIN('GA Arroyo'!B19,'GA Arroyo'!E19,'GA Arroyo'!H19,'GA Arroyo'!K19) -> 7825.4 | C19: =MIN('GA Arroyo'!O19, 'GA Arroyo'!R19, 'GA Arroyo'!U19, 'GA Arroyo'!X19) -> 7825.4 | D19: =MIN('GA Arroyo'!AB19, 'GA Arroyo'!AE19, 'GA Arroyo'!AH19, 'GA Arroyo'!AK19) -> 8384.2 | E19: =MIN('GA Arroyo'!AO19, 'GA Arroyo'!AR19, 'GA Arroyo'!AU19, 'GA Arroyo'!AX19) -> 7825.4 | G19: =MIN(B19,C19,D19,E19) -> 7825.4 | I19: =(100*(B19-G19))/G19 -> 0 | J19: =(100*(C19-G19))/G19 -> 0 | K19: =(100*(D19-G19))/G19 -> 7.140849 | L19: =(100*(E19-G19))/G19 -> 0 | T19: =(100*('GA Arroyo'!AO19-E19))/E19 -> 8.8608889 | U19: =(100*('GA Arroyo'!AR19-E19))/E19 -> 8.8608889 | V19: =(100*('GA Arroyo'!AU19-E19))/E19 -> 0 | W19: =(100*('GA Arroyo'!AX19-E19))/E19 -> 0
